Workbook

Sheet Protein Stat Tables
A1: Comparison | I1: Sample ID | J1: Inv_ID | K1: Technical Replicates | L1: Reason for Removal
A2: Month | B2: Resistance Level | C2: Month | D2: Resistance Level | E2: Mean Difference | F2: p | I2: 511417 | J2: A | K2: 6
A3: June | B3: Not Resistant | C3: June | D3: Medium | E3: -0.08957897 | F3: 0.9410354 | I3: 51848 | J3: B | K3: 6
C4: June | D4: Resistant | E4: -0.24945536 | F4: 0.0927686 | I4: 511156 | J4: C | K4: 6
C5: August | D5: Not Resistant | E5: -0.75613753 | F5: 0 | I5: 511031 | J5: D | K5: 6
C6: August | D6: Medium | E6: -0.68183887 | F6: 0 | I6: 51334 | J6: E | K6: 6
C7: August | D7: Resistant | E7: -0.64364838 | F7: 0 | I7: 51717 | J7: F | K7: 6
B8: Medium | C8: June | D8: Resistant | E8: -0.15987639 | F8: 0.5558543 | I8: 51639 | J8: G | K8: 6
C9: August | D9: Not Resistant | E9: -0.66655856 | F9: 0 | I9: 51833 | J9: H | K9: 6
C10: August | D10: Medium | E10: -0.5922599 | F10: 0 | I10: 511325 | J10: I | K10: 6
C11: August | D11: Resistant | E11: -0.55406941 | F11: 2e-07 | I11: 511346 | J11: J | K11: 6
B12: Resistant | C12: August | D12: Not Resistant | E12: -0.50668217 | F12: 3e-07 | I12: 511221 | J12: K | K12: 6
C13: August | D13: Medium | E13: -0.43238351 | F13: 2.34e-05 | I13: 512217 | J13: L | K13: 6
C14: August | D14: Resistant | E14: -0.39419302 | F14: 0.0001179 | I14: 51746 | J14: M | K14: 6
A15: August | B15: Not Resistant | C15: August | D15: Medium | E15: 0.07429866 | F15: 0.915677 | I15: 511811 | J15: N | K15: 6
C16: August | D16: Resistant | E16: 0.11248915 | F16: 0.6399384 | I16: 51525 | J16: O | K16: 6
B17: Medium | C17: August | D17: Resistant | E17: 0.03819049 | F17: 0.9956817 | I17: 51185 | J17: P | K17: 6
A18: Tukey HSD for interaction term | I18: 511052 | J18: Q | K18: 6
I19: 51826 | J19: R | K19: 6
I20: 512014 | J20: S | K20: 6
I21: 97918 | J21: T | K21: 6
I22: 97231 | J22: U | K22: 6
I23: 971414 | J23: V | K23: 6
I24: 971349 | J24: W | K24: 6
I25: 97650 | J25: X | K25: 6
I26: 97335 | J26: Y | K26: 6
I27: 97730 | J27: Z | K27: 6
I28: 972017 | J28: AA | K28: 6
I29: 971145 | J29: AB | K29: 6
I30: 97734 | J30: AC | K30: 6
... I32: 97623 | J32: AE | K32: 6
I33: E97163 | J33: AG | K33: 6
I34: 97168 | J34: AH | K34: 6
I35: 971022 | J35: AI | K35: 6
I36: 97339 | J36: AJ | K36: 6
I37: 971316 | J37: AK | K37: 6
I38: E97143 | J38: AL | K38: 6
I39: E9712 | J39: AM | K39: 6
I40: 97206 | J40: AN | K40: 6
I41: 121434 | J41: AO | K41: 6
...

Sheet Sample Inventory
A1: Sample ID | B1: Month | C1: Present? | D1: Plug or Core? | E1: Tray # | F1: New Tray | G1: Comments
A2: 511417 | B2: August | C2: y | D2: P | E2: 1 | G2: a
A3: 51848 | B3: August | C3: y | D3: P | E3: 1 | G3: b
A4: 511156 | B4: August | C4: y | D4: P | E4: 1 | G4: c
A5: 511031 | B5: August | C5: y | D5: P | E5: 1 | G5: d
A6: 51334 | B6: August | C6: y | D6: P | E6: 1 | G6: e
A7: 51717 | B7: August | C7: y | D7: P | E7: 1 | G7: f
A8: 51639 | B8: August | C8: y | D8: P | E8: 1 | G8: g
A9: 51833 | B9: August | C9: y | D9: P | E9: 1 | G9: h
A10: 511325 | B10: August | C10: y | D10: P | E10: 1 | G10: i
A11: 511221 | B11: August | C11: y | D11: P | E11: 1 | G11: k
A12: 512217 | B12: August | C12: y | D12: P | E12: 1 | G12: l
A13: 51746 | B13: August | C13: y | D13: P | E13: 1 | G13: m
... A18: 512014 | B18: August | C18: y | D18: P | E18: 1 | G18: s
A19: 97918 | B19: August | C19: y | D19: P | E19: 1 | F19: 2 | G19: t
A20: 97231 | B20: August | C20: y | D20: P | E20: 1 | F20: 2 | G20: u
A21: 971414 | B21: August | C21: y | D21: P | E21: 1 | F21: 2 | G21: v
A22: 971349 | B22: August | C22: y | D22: P | E22: 1 | F22: 2 | G22: w
A23: 97650 | B23: August | C23: y | D23: P | E23: 1 | F23: 2 | G23: x
A24: 97335 | B24: August | C24: y | D24: P | E24: 1 | F24: 2 | G24: y
A25: 972017 | B25: August | C25: y | D25: P | E25: 2 | F25: 2 | G25: aa
A26: 971145 | B26: August | C26: y | D26: P | E26: 2 | F26: 2 | G26: ab
A27: 97734 | B27: August | C27: y | D27: P | E27: 2 | F27: 2 | G27: ac
A28: 97620 | B28: August | C28: y | D28: P | E28: 2 | F28: 2 | G28: ad
A29: 97623 | B29: August | C29: y | D29: P | E29: 2 | F29: 2 | G29: ae
A30: E97163 | B30: August | C30: y | D30: P | E30: 2 | F30: 2 | G30: ag
A31: 97168 | B31: August | C31: y | D31: P | E31: 2 | F31: 2 | G31: ah
A32: 971022 | B32: August | C32: y | D32: P | E32: 2 | F32: 2 | G32: ai
A33: 97339 | B33: August | C33: y | D33: P | E33: 2 | F33: 2 | G33: aj
A34: 971316 | B34: August | C34: y | D34: P | E34: 2 | F34: 2 | G34: ak
A35: E97143 | B35: August | C35: y | D35: P | E35: 2 | F35: 2 | G35: al
A36: E9712 | B36: August | C36: y | D36: P | E36: 2 | F36: 2 | G36: am
A37: 97206 | B37: August | C37: y | D37: P | E37: 2 | F37: 2 | G37: an
A38: 121434 | B38: August | C38: y | D38: P | E38: 2 | F38: 1 | G38: ao
A39: 121539 | B39: August | C39: y | D39: P | E39: 2 | F39: 1 | G39: ap
A40: 121743 | B40: August | C40: y | D40: P | E40: 2 | F40: 1 | G40: aq
A41: 1211312 | B41: August | C41: y | D41: P | E41: 2 | F41: 1 | G41: ar
A42: 121179 | B42: August | C42: y | D42: P | E42: 2 | F42: 1 | G42: as
A43: 121631 | B43: August | C43: y | D43: P | E43: 2 | F43: 1 | G43: at
A44: 1211019 | B44: August | C44: y | D44: P | E44: 2 | F44: 1 | G44: au
...

Sheet All PR_Conc
A1: Sample ID | B1: Inv_ID | C1: Month | D1: Res_Lev | E1: PR_Conc | F1: Comments
A2: 511417 | B2: A | C2: August | D2: Medium | E2: =AVERAGE(AM!X3,AM!X23,AM!X43,AM!X63,AM!X82,AM!X101) -> 1.3322501
A3: 51848 | B3: B | C3: August | D3: Medium | E3: =AVERAGE(AM!X4,AM!X24,AM!X44,AM!X64,AM!X83,AM!X102) -> 1.146814
A4: 511156 | B4: C | C4: August | D4: Medium | E4: =AVERAGE(AM!X5,AM!X25,AM!X45,AM!X65,AM!X84,AM!X103) -> 1.0536246
A5: 511031 | B5: D | C5: August | D5: Medium | E5: =AVERAGE(AM!X6,AM!X26,AM!X46) -> 0.54111739
A6: 51334 | B6: E | C6: August | D6: Medium | E6: =AVERAGE(AM!X7,AM!X27,AM!X47,AM!X66,AM!X85,AM!X104) -> 1.062631
A7: 51717 | B7: F | C7: August | D7: Medium | E7: =AVERAGE(AM!X8,AM!X28,AM!X48,AM!X67,AM!X86,AM!X105) -> 0.84902422
A8: 51639 | B8: G | C8: August | D8: Medium | E8: =AVERAGE(AM!X9,AM!X29,AM!X49,AM!X68,AM!X87,AM!X106) -> 1.6483894
A9: 51833 | B9: H | C9: August | D9: Medium | E9: =AVERAGE(AM!X10,AM!X30,AM!X50,AM!X69,AM!X88,AM!X107) -> 1.1954453
A10: 511325 | B10: I | C10: August | D10: Medium | E10: =AVERAGE(AM!X11,AM!X31,AM!X51,AM!X70,AM!X89,AM!X108) -> 1.2377941
A11: 511346 | B11: J | C11: August | D11: Medium | E11: =AVERAGE(AM!X12,AM!X32,AM!X52,AM!X71,AM!X90,AM!X109) -> 1.9399411
A12: 511221 | B12: K | C12: August | D12: Medium | E12: =AVERAGE(AM!X13,AM!X33,AM!X53,AM!X72,AM!X91,AM!X110) -> 1.1036307
A13: 512217 | B13: L | C13: August | D13: Medium | E13: =AVERAGE(AM!X14,AM!X34,AM!X54,AM!X73,AM!X92,AM!X111) -> 0.98681775
A14: 51746 | B14: M | C14: August | D14: Medium | E14: =AVERAGE(AM!X15,AM!X35,AM!X55,AM!X74,AM!X93,AM!X112) -> 0.77390282
A15: 511811 | B15: N | C15: August | D15: Medium | E15: =AVERAGE(AM!X16,AM!X36,AM!X56,AM!X75,AM!X94,AM!X113) -> 1.6320998
A16: 51525 | B16: O | C16: August | D16: Medium | E16: =AVERAGE(AM!X17,AM!X37,AM!X57,AM!X76,AM!X95,AM!X114) -> 1.092121
A17: 51185 | B17: P | C17: August | D17: Medium | E17: =AVERAGE(AM!X18,AM!X38,AM!X58,AM!X77,AM!X96,AM!X115) -> 1.6322715
... A20: 512014 | B20: S | C20: August | D20: Medium | E20: =AVERAGE(AM!X21,AM!X41,AM!X61,AM!X80,AM!X99,AM!X118) -> 1.1300852
A21: 97918 | B21: T | C21: August | D21: Resistant | E21: =AVERAGE(AR!Y3,AR!Y24,AR!Y45,AR!Y66,AR!Y87,AR!Y108) -> 1.2450332
A22: 97231 | B22: U | C22: August | D22: Resistant | E22: =AVERAGE(AR!Y4,AR!Y25,AR!Y46,AR!Y67,AR!Y88,AR!Y109) -> 1.3401105
A23: 971414 | B23: V | C23: August | D23: Resistant | E23: =AVERAGE(AR!Y5,AR!Y26,AR!Y47,AR!Y68,AR!Y89,AR!Y110) -> 0.9753415
A24: 971349 | B24: W | C24: August | D24: Resistant | E24: =AVERAGE(AR!Y6,AR!Y27,AR!Y48,AR!Y69,AR!Y90,AR!Y111) -> 0.9030939
A25: 97650 | B25: X | C25: August | D25: Resistant | E25: =AVERAGE(AR!Y7,AR!Y28,AR!Y49,AR!Y70,AR!Y91,AR!Y112) -> 1.5890522
A26: 97335 | B26: Y | C26: August | D26: Resistant | E26: =AVERAGE(AR!Y8,AR!Y29,AR!Y50,AR!Y71,AR!Y92,AR!Y113) -> 1.1874772
A27: 97730 | B27: Z | C27: August | D27: Resistant | E27: =AVERAGE(AR!Y9,AR!Y30,AR!Y51,AR!Y72,AR!Y93,AR!Y114) -> 1.1773162
A28: 972017 | B28: AA | C28: August | D28: Resistant | E28: =AVERAGE(AR!Y10,AR!Y31,AR!Y52,AR!Y73,AR!Y94,AR!Y115) -> 1.1939779
A29: 971145 | B29: AB | C29: August | D29: Resistant | E29: =AVERAGE(AR!Y11,AR!Y32,AR!Y53,AR!Y74,AR!Y95,AR!Y116) -> 1.5176989
A30: 97734 | B30: AC | C30: August | D30: Resistant | E30: =AVERAGE(AR!Y12,AR!Y33,AR!Y54,AR!Y75,AR!Y96,AR!Y117) -> 1.0036233
A31: 97620 | B31: AD | C31: August | D31: Resistant | E31: =AVERAGE(AR!Y13,AR!Y34,AR!Y55,AR!Y76,AR!Y97,AR!Y118) -> 1.0955378
A32: 97623 | B32: AE | C32: August | D32: Resistant | E32: =AVERAGE(AR!Y14,AR!Y35,AR!Y56,AR!Y77,AR!Y98,AR!Y119) -> 0.96023175
A33: E97163 | B33: AG | C33: August | D33: Resistant | E33: =AVERAGE(AR!Y15,AR!Y36,AR!Y57,AR!Y78,AR!Y99,AR!Y120) -> 1.1160101
A34: 97168 | B34: AH | C34: August | D34: Resistant | E34: =AVERAGE(AR!Y16,AR!Y37,AR!Y58,AR!Y79,AR!Y100,AR!Y121) -> 0.7853599
A35: 971022 | B35: AI | C35: August | D35: Resistant | E35: =AVERAGE(AR!Y17,AR!Y38,AR!Y59,AR!Y80,AR!Y101,AR!Y122) -> 1.2470317
A36: 97339 | B36: AJ | C36: August | D36: Resistant | E36: =AVERAGE(AR!Y18,AR!Y39,AR!Y60,AR!Y81,AR!Y102,AR!Y123) -> 1.3985107
A37: 971316 | B37: AK | C37: August | D37: Resistant | E37: =AVERAGE(AR!Y19,AR!Y40,AR!Y61,AR!Y82,AR!Y103,AR!Y124) -> 0.9764692
A38: E97143 | B38: AL | C38: August | D38: Resistant | E38: =AVERAGE(AR!Y20,AR!Y41,AR!Y62,AR!Y83,AR!Y104,AR!Y125) -> 0.92800562
A39: E9712 | B39: AM | C39: August | D39: Resistant | E39: =AVERAGE(AR!Y21,AR!Y42,AR!Y63,AR!Y84,AR!Y105,AR!Y126) -> 1.3274314
A40: 97206 | B40: AN | C40: August | D40: Resistant | E40: =AVERAGE(AR!Y22,AR!Y43,AR!Y64,AR!Y85,AR!Y106,AR!Y127) -> 1.001428
A41: 121434 | B41: AO | C41: August | D41: Not Resistant | E41: =AVERAGE(ANR!Y111,ANR!Y90,ANR!Y69,ANR!Y47,ANR!Y25,ANR!Y3) -> 0.8064494
A42: 121539 | B42: AP | C42: August | D42: Not Resistant | E42: =AVERAGE(ANR!Y112,ANR!Y91,ANR!Y70,ANR!Y48,ANR!Y26,ANR!Y4) -> 1.4545292
...

Sheet AM
A1: 1 | O1: STANDARD CURVES | T1: SAMPLES
B2: 1 | C2: 2 | D2: 3 | E2: 4 | F2: 5 | G2: 6 | H2: 7 | I2: 8 | J2: 9 | K2: 10 | L2: 11 | M2: 12 | N2: 1 | P2: AVG Absorbance | Q2: Corrected AVG | S2: 1 | T2: Sample ID | U2: Absorbance | V2: Corrected Absorbance | W2: Concentration (mg/mL) | X2: Concentration (mg/g DW)
A3: A | B3: 0.391 | C3: 0.364 | E3: 0.724 | F3: 0.701 | G3: 0.611 | H3: 0.537 | I3: 0.716 | J3: 0.613 | K3: 0.651 | L3: 0.681 | M3: 0.772 | O3: 0 | P3: =AVERAGE(B3:C3) -> 0.3775 | Q3: =P3-P$3 -> 0 | T3: A | U3: 0.724 | V3: =U3-P$3 -> 0.3465 | W3: =(V3+0.0125)/1.9946 -> 0.17998596 | X3: =W3*7 -> 1.2599017
A4: B | B4: 0.437 | C4: 0.481 | O4: 0.05 | P4: =AVERAGE(B4:C4) -> 0.459 | Q4: =P4-P$3 -> 0.0815 | T4: B | U4: 0.701 | V4: =U4-P$3 -> 0.3235 | W4: =(V4+0.0125)/1.9946 -> 0.16845483 | X4: =W4*7 -> 1.1791838
A5: C | E5: 0.989 | F5: 0.659 | G5: 0.59 | H5: 0.562 | I5: 0.784 | J5: 0.647 | K5: 0.776 | L5: 0.582 | M5: 0.781 | O5: 0.1 | P5: =AVERAGE(B6:C6) -> 0.609 | Q5: =P5-P$3 -> 0.2315 | T5: C | U5: 0.611 | V5: =U5-P$3 -> 0.2335 | W5: =(V5+0.0125)/1.9946 -> 0.123333 | X5: =W5*7 -> 0.86333099
A6: D | B6: 0.572 | C6: 0.646 | O6: 0.25 | P6: =AVERAGE(B8:C8) -> 0.7775 | Q6: =P6-P$3 -> 0.4 | T6: D | U6: 0.537 | V6: =U6-P$3 -> 0.1595 | W6: =(V6+0.0125)/1.9946 -> 0.086232829 | X6: =W6*7 -> 0.6036298
A7: E | E7: 0.586 | O7: 0.5 | P7: =AVERAGE(B10:C10) -> 1.397 | Q7: =P7-P$3 -> 1.0195 | T7: E | U7: 0.716 | V7: =U7-P$3 -> 0.3385 | W7: =(V7+0.0125)/1.9946 -> 0.17597513 | X7: =W7*7 -> 1.2318259
A8: F | B8: 0.787 | C8: 0.768 | N8: 2 | T8: F | U8: 0.613 | V8: =U8-P$3 -> 0.2355 | W8: =(V8+0.0125)/1.9946 -> 0.12433571 | X8: =W8*7 -> 0.87034994
A9: G | O9: 0 | P9: =AVERAGE(B13:C13) -> 0.382 | Q9: =P9-P$9 -> 0 | T9: G | U9: 0.651 | V9: =U9-P$3 -> 0.2735 | W9: =(V9+0.0125)/1.9946 -> 0.14338715 | X9: =W9*7 -> 1.00371
A10: H | B10: 1.402 | C10: 1.392 | O10: 0.05 | P10: =AVERAGE(B14:C14) -> 0.4875 | Q10: =P10-P$9 -> 0.1055 | T10: H | U10: 0.681 | V10: =U10-P$3 -> 0.3035 | W10: =(V10+0.0125)/1.9946 -> 0.15842775 | X10: =W10*7 -> 1.1089943
A11: 2 | O11: 0.1 | P11: =AVERAGE(B16:C16) -> 0.62 | Q11: =P11-P$9 -> 0.238 | T11: I | U11: 0.772 | V11: =U11-P$3 -> 0.3945 | W11: =(V11+0.0125)/1.9946 -> 0.20405094 | X11: =W11*7 -> 1.4283566
B12: 1 | C12: 2 | D12: 3 | E12: 4 | F12: 5 | G12: 6 | H12: 7 | I12: 8 | J12: 9 | K12: 10 | L12: 11 | M12: 12 | O12: 0.25 | P12: =AVERAGE(B18:C18) -> 0.766 | Q12: =P12-P$9 -> 0.384 | T12: J | U12: 0.989 | V12: =U12-P$3 -> 0.6115 | W12: =(V12+0.0125)/1.9946 -> 0.31284468 | X12: =W12*7 -> 2.1899128
A13: A | B13: 0.381 | C13: 0.383 | E13: 0.799 | F13: 0.655 | G13: 0.61 | H13: 0.494 | I13: 0.686 | J13: 0.532 | K13: 0.842 | L13: 0.602 | M13: 0.753 | O13: 0.5 | P13: =AVERAGE(B20:C20) -> 1.363 | Q13: =P13-P$9 -> 0.981 | T13: K | U13: 0.659 | V13: =U13-P$3 -> 0.2815 | W13: =(V13+0.0125)/1.9946 -> 0.14739797 | X13: =W13*7 -> 1.0317858
A14: B | B14: 0.488 | C14: 0.487 | N14: 3 | T14: L | U14: 0.59 | V14: =U14-P$3 -> 0.2125 | W14: =(V14+0.0125)/1.9946 -> 0.11280457 | X14: =W14*7 -> 0.78963201
A15: C | E15: 1 | F15: 0.678 | G15: 0.603 | H15: 0.546 | I15: 1.011 | J15: 0.779 | K15: 1.001 | L15: 0.604 | M15: 0.724 | O15: 0 | P15: =AVERAGE(B23:C23) -> 0.4015 | Q15: =P15-P$15 -> 0 | T15: M | U15: 0.562 | V15: =U15-P$3 -> 0.1845 | W15: =(V15+0.0125)/1.9946 -> 0.09876667 | X15: =W15*7 -> 0.69136669
A16: D | B16: 0.611 | C16: 0.629 | O16: 0.05 | P16: =AVERAGE(B24:C24) -> 0.482 | Q16: =P16-P$15 -> 0.0805 | T16: N | U16: 0.784 | V16: =U16-P$3 -> 0.4065 | W16: =(V16+0.0125)/1.9946 -> 0.21006718 | X16: =W16*7 -> 1.4704703
A17: E | E17: 0.627 | O17: 0.1 | P17: =AVERAGE(B26:C26) -> 0.5915 | Q17: =P17-P$15 -> 0.19 | T17: O | U17: 0.647 | V17: =U17-P$3 -> 0.2695 | W17: =(V17+0.0125)/1.9946 -> 0.14138173 | X17: =W17*7 -> 0.98967211
A18: F | B18: 0.738 | C18: 0.794 | O18: 0.25 | P18: =AVERAGE(B28:C28) -> 0.8025 | Q18: =P18-P$15 -> 0.401 | T18: P | U18: 0.776 | V18: =U18-P$3 -> 0.3985 | W18: =(V18+0.0125)/1.9946 -> 0.20605635 | X18: =W18*7 -> 1.4423945
A19: G | O19: 0.5 | P19: =AVERAGE(B30:C30) -> 1.446 | Q19: =P19-P$15 -> 1.0445 | T19: Q | U19: 0.582 | V19: =U19-P$3 -> 0.2045 | W19: =(V19+0.0125)/1.9946 -> 0.10879374 | X19: =W19*7 -> 0.7615562
A20: H | B20: 1.337 | C20: 1.389 | N20: 4 | T20: R | U20: 0.781 | V20: =U20-P$3 -> 0.4035 | W20: =(V20+0.0125)/1.9946 -> 0.20856312 | X20: =W20*7 -> 1.4599418
A21: 3 | O21: 0 | P21: =AVERAGE(B33:C33) -> 0.3595 | Q21: =P21-P$21 -> 0 | T21: S | U21: 0.586 | V21: =U21-P$3 -> 0.2085 | W21: =(V21+0.0125)/1.9946 -> 0.11079916 | X21: =W21*7 -> 0.7755941
B22: 1 | C22: 2 | D22: 3 | E22: 4 | F22: 5 | G22: 6 | H22: 7 | I22: 8 | J22: 9 | K22: 10 | L22: 11 | M22: 12 | O22: 0.05 | P22: =AVERAGE(B34:C34) -> 0.53 | Q22: =P22-P$21 -> 0.1705 | S22: 2 | T22: Sample ID | U22: Absorbance | V22: Corrected Absorbance | W22: Concentration (mg/mL) | X22: Concentration (mg/g DW)
A23: A | B23: 0.388 | C23: 0.415 | E23: 0.791 | F23: 0.746 | G23: 0.61 | H23: 0.553 | I23: 0.761 | J23: 0.63 | K23: 0.789 | L23: 0.678 | M23: 0.703 | O23: 0.1 | P23: =AVERAGE(B36:C36) -> 0.6605 | Q23: =P23-P$21 -> 0.301 | T23: A | U23: 0.799 | V23: =U23-P$9 -> 0.417 | W23: =(V23-0.0015)/1.8898 -> 0.21986454 | X23: =W23*7 -> 1.5390518
A24: B | B24: 0.478 | C24: 0.486 | O24: 0.25 | P24: =AVERAGE(B38:C38) -> 0.9135 | Q24: =P24-P$21 -> 0.554 | T24: B | U24: 0.655 | V24: =U24-P$9 -> 0.273 | W24: =(V24-0.0015)/1.8898 -> 0.143666 | X24: =W24*7 -> 1.005662
A25: C | E25: 1.094 | F25: 0.632 | G25: 0.573 | H25: 0.568 | I25: 0.766 | J25: 0.809 | K25: 0.696 | L25: 0.615 | M25: 0.676 | O25: 0.5 | P25: =AVERAGE(B40:C40) -> 1.245 | Q25: =P25-P$21 -> 0.8855 | T25: C | U25: 0.61 | V25: =U25-P$9 -> 0.228 | W25: =(V25-0.0015)/1.8898 -> 0.11985395 | X25: =W25*7 -> 0.83897767
A26: D | B26: 0.594 | C26: 0.589 | N26: 5 | T26: D | U26: 0.494 | V26: =U26-P$9 -> 0.112 | W26: =(V26-0.0015)/1.8898 -> 0.058471796 | X26: =W26*7 -> 0.40930257
A27: E | E27: 0.603 | O27: 0 | P27: =AVERAGE(B43:C43) -> 0.347 | Q27: =P27-P$27 -> 0 | T27: E | U27: 0.686 | V27: =U27-P$9 -> 0.304 | W27: =(V27-0.0015)/1.8898 -> 0.16006985 | X27: =W27*7 -> 1.1204889
A28: F | B28: 0.825 | C28: 0.78 | O28: 0.05 | P28: =AVERAGE(B44:C44) -> 0.504 | Q28: =P28-P$27 -> 0.157 | T28: F | U28: 0.532 | V28: =U28-P$9 -> 0.15 | W28: =(V28-0.0015)/1.8898 -> 0.078579744 | X28: =W28*7 -> 0.55005821
A29: G | O29: 0.1 | P29: =AVERAGE(B46:C46) -> 0.6375 | Q29: =P29-P$27 -> 0.2905 | T29: G | U29: 0.842 | V29: =U29-P$9 -> 0.46 | W29: =(V29-0.0015)/1.8898 -> 0.24261827 | X29: =W29*7 -> 1.6983279
A30: H | B30: 1.388 | C30: 1.504 | O30: 0.25 | P30: =AVERAGE(B48:C48) -> 0.9195 | Q30: =P30-P$27 -> 0.5725 | T30: H | U30: 0.602 | V30: =U30-P$9 -> 0.22 | W30: =(V30-0.0015)/1.8898 -> 0.1156207 | X30: =W30*7 -> 0.8093449
A31: 4 | O31: 0.5 | P31: =AVERAGE(B50:C50) -> 1.2685 | Q31: =P31-P$27 -> 0.9215 | T31: I | U31: 0.753 | V31: =U31-P$9 -> 0.371 | W31: =(V31-0.0015)/1.8898 -> 0.19552334 | X31: =W31*7 -> 1.3686634
B32: 1 | C32: 2 | D32: 3 | E32: 4 | F32: 5 | G32: 6 | H32: 7 | I32: 8 | J32: 9 | K32: 10 | L32: 11 | M32: 12 | N32: 6 | T32: J | U32: 1 | V32: =U32-P$9 -> 0.618 | W32: =(V32-0.0015)/1.8898 -> 0.326225 | X32: =W32*7 -> 2.283575
A33: A | B33: 0.364 | C33: 0.355 | E33: 0.723 | F33: 0.707 | G33: 0.739 | H33: 0.649 | I33: 0.669 | J33: 0.898 | K33: 0.77 | L33: 0.711 | M33: 0.78 | O33: 0 | P33: =AVERAGE(B53:C53) -> 0.3525 | Q33: =P33-P$33 -> 0 | T33: K | U33: 0.678 | V33: =U33-P$9 -> 0.296 | W33: =(V33-0.0015)/1.8898 -> 0.1558366 | X33: =W33*7 -> 1.0908562
A34: B | B34: 0.524 | C34: 0.536 | O34: 0.05 | P34: =AVERAGE(B54:C54) -> 0.5195 | Q34: =P34-P$33 -> 0.167 | T34: L | U34: 0.603 | V34: =U34-P$9 -> 0.221 | W34: =(V34-0.0015)/1.8898 -> 0.11614986 | X34: =W34*7 -> 0.813049
A35: C | E35: 0.71 | F35: 0.745 | G35: 0.676 | H35: 0.812 | I35: 0.646 | J35: 0.817 | K35: 0.76 | L35: 0.693 | M35: 0.784 | O35: 0.1 | P35: =AVERAGE(B56:C56) -> 0.635 | Q35: =P35-P$33 -> 0.2825 | T35: M | U35: 0.546 | V35: =U35-P$9 -> 0.164 | W35: =(V35-0.0015)/1.8898 -> 0.085987935 | X35: =W35*7 -> 0.60191555
A36: D | B36: 0.66 | C36: 0.661 | O36: 0.25 | P36: =AVERAGE(B58:C58) -> 0.9185 | Q36: =P36-P$33 -> 0.566 | T36: N | U36: 1.011 | V36: =U36-P$9 -> 0.629 | W36: =(V36-0.0015)/1.8898 -> 0.33204572 | X36: =W36*7 -> 2.32432
A37: E | O37: 0.5 | P37: =AVERAGE(B60:C60) -> 1.2685 | Q37: =P37-P$33 -> 0.916 | T37: O | U37: 0.779 | V37: =U37-P$9 -> 0.397 | W37: =(V37-0.0015)/1.8898 -> 0.20928141 | X37: =W37*7 -> 1.4649698
A38: F | B38: 0.896 | C38: 0.931 | T38: P | U38: 1.001 | V38: =U38-P$9 -> 0.619 | W38: =(V38-0.0015)/1.8898 -> 0.32675415 | X38: =W38*7 -> 2.2872791
A39: G | T39: Q | U39: 0.604 | V39: =U39-P$9 -> 0.222 | W39: =(V39-0.0015)/1.8898 -> 0.11667901 | X39: =W39*7 -> 0.8167531
A40: H | B40: 1.273 | C40: 1.217 | T40: R | U40: 0.724 | V40: =U40-P$9 -> 0.342 | W40: =(V40-0.0015)/1.8898 -> 0.1801778 | X40: =W40*7 -> 1.2612446
...

Sheet AR
A1: 1 | P1: STANDARD CURVES | U1: SAMPLES
B2: 1 | C2: 2 | D2: 3 | E2: 4 | F2: 5 | G2: 6 | H2: 7 | I2: 8 | J2: 9 | K2: 10 | L2: 11 | M2: 12 | O2: 1 | Q2: AVG Absorbance | R2: Corrected AVG | T2: 1 | U2: Sample ID | V2: Absorbance | W2: Corrected Absorbance | X2: Concentration (mg/mL) | Y2: Concentration (mg/g DW)
A3: A | B3: 0.377 | C3: 0.337 | E3: 0.677 | F3: 0.672 | G3: 0.606 | H3: 0.509 | I3: 0.858 | J3: 0.524 | K3: 0.704 | L3: 0.554 | M3: 0.65 | P3: 0 | Q3: =AVERAGE(B3:C3) -> 0.357 | R3: =Q3-Q$3 -> 0 | U3: T | V3: 0.677 | W3: =V3-Q$3 -> 0.32 | X3: =(W3+0.0066)/2.3929 -> 0.13648711 | Y3: =X3*7 -> 0.95540975
A4: B | B4: 0.459 | C4: 0.487 | P4: 0.05 | Q4: =AVERAGE(B4:C4) -> 0.473 | R4: =Q4-Q$3 -> 0.116 | U4: U | V4: 0.672 | W4: =V4-Q$3 -> 0.315 | X4: =(W4+0.0066)/2.3929 -> 0.13439759 | Y4: =X4*7 -> 0.94078315
A5: C | E5: 0.478 | F5: 0.565 | G5: 0.549 | H5: 0.59 | I5: 0.489 | J5: 0.531 | K5: 0.652 | L5: 0.587 | M5: 0.529 | P5: 0.1 | Q5: =AVERAGE(B6:C6) -> 0.635 | R5: =Q5-Q$3 -> 0.278 | U5: V | V5: 0.606 | W5: =V5-Q$3 -> 0.249 | X5: =(W5+0.0066)/2.3929 -> 0.106816 | Y5: =X5*7 -> 0.74771198
A6: D | B6: 0.592 | C6: 0.678 | P6: 0.25 | Q6: =AVERAGE(B8:C8) -> 0.8575 | R6: =Q6-Q$3 -> 0.5005 | U6: W | V6: 0.509 | W6: =V6-Q$3 -> 0.152 | X6: =(W6+0.0066)/2.3929 -> 0.06627941 | Y6: =X6*7 -> 0.46395587
A7: E | E7: 0.586 | F7: 0.531 | P7: 0.5 | Q7: =AVERAGE(B10:C10) -> 1.583 | R7: =Q7-Q$3 -> 1.226 | U7: X | V7: 0.858 | W7: =V7-Q$3 -> 0.501 | X7: =(W7+0.0066)/2.3929 -> 0.21212754 | Y7: =X7*7 -> 1.4848928
A8: F | B8: 0.825 | C8: 0.89 | O8: 2 | U8: Y | V8: 0.524 | W8: =V8-Q$3 -> 0.167 | X8: =(W8+0.0066)/2.3929 -> 0.072547954 | Y8: =X8*7 -> 0.50783568
A9: G | P9: 0 | Q9: =AVERAGE(B13:C13) -> 0.3895 | R9: =Q9-Q$9 -> 0 | U9: Z | V9: 0.704 | W9: =V9-Q$3 -> 0.347 | X9: =(W9+0.0066)/2.3929 -> 0.14777049 | Y9: =X9*7 -> 1.0343934
A10: H | B10: 1.642 | C10: 1.524 | P10: 0.05 | Q10: =AVERAGE(B14:C14) -> 0.4645 | R10: =Q10-Q$9 -> 0.075 | U10: AA | V10: 0.554 | W10: =V10-Q$3 -> 0.197 | X10: =(W10+0.0066)/2.3929 -> 0.085085043 | Y10: =X10*7 -> 0.5955953
A11: 2 | P11: 0.1 | Q11: =AVERAGE(B16:C16) -> 0.5345 | R11: =Q11-Q$9 -> 0.145 | U11: AB | V11: 0.65 | W11: =V11-Q$3 -> 0.293 | X11: =(W11+0.0066)/2.3929 -> 0.12520373 | Y11: =X11*7 -> 0.87642609
B12: 1 | C12: 2 | D12: 3 | E12: 4 | F12: 5 | G12: 6 | H12: 7 | I12: 8 | J12: 9 | K12: 10 | L12: 11 | M12: 12 | P12: 0.25 | Q12: =AVERAGE(B18:C18) -> 0.8765 | R12: =Q12-Q$9 -> 0.487 | U12: AC | V12: 0.478 | W12: =V12-Q$3 -> 0.121 | X12: =(W12+0.0066)/2.3929 -> 0.053324418 | Y12: =X12*7 -> 0.37327093
A13: A | B13: 0.391 | C13: 0.388 | E13: 0.618 | F13: 0.548 | G13: 0.576 | H13: 0.487 | I13: 0.612 | J13: 0.538 | K13: 0.622 | L13: 0.693 | M13: 0.758 | P13: 0.5 | Q13: =AVERAGE(B20:C20) -> 1.548 | R13: =Q13-Q$9 -> 1.1585 | U13: AD | V13: 0.565 | W13: =V13-Q$3 -> 0.208 | X13: =(W13+0.0066)/2.3929 -> 0.089681976 | Y13: =X13*7 -> 0.62777383
A14: B | B14: 0.471 | C14: 0.458 | O14: 3 | U14: AE | V14: 0.549 | W14: =V14-Q$3 -> 0.192 | X14: =(W14+0.0066)/2.3929 -> 0.082995528 | Y14: =X14*7 -> 0.5809687
A15: C | E15: 0.504 | F15: 0.536 | G15: 0.555 | H15: 0.628 | I15: 0.473 | J15: 0.573 | K15: 0.615 | L15: 0.613 | M15: 0.501 | P15: 0 | Q15: =AVERAGE(B23:C23) -> 0.3835 | R15: =Q15-Q$15 -> 0 | U15: AG | V15: 0.59 | W15: =V15-Q$3 -> 0.233 | X15: =(W15+0.0066)/2.3929 -> 0.10012955 | Y15: =X15*7 -> 0.70090685
A16: D | B16: 0.556 | C16: 0.513 | P16: 0.05 | Q16: =AVERAGE(B24:C24) -> 0.4665 | R16: =Q16-Q$15 -> 0.083 | U16: AH | V16: 0.489 | W16: =V16-Q$3 -> 0.132 | X16: =(W16+0.0066)/2.3929 -> 0.057921351 | Y16: =X16*7 -> 0.40544945
A17: E | E17: 0.596 | F17: 0.587 | P17: 0.1 | Q17: =AVERAGE(B26:C26) -> 0.581 | R17: =Q17-Q$15 -> 0.1975 | U17: AI | V17: 0.531 | W17: =V17-Q$3 -> 0.174 | X17: =(W17+0.0066)/2.3929 -> 0.075473275 | Y17: =X17*7 -> 0.52831293
A18: F | B18: 0.888 | C18: 0.865 | P18: 0.25 | Q18: =AVERAGE(B28:C28) -> 0.894 | R18: =Q18-Q$15 -> 0.5105 | U18: AJ | V18: 0.652 | W18: =V18-Q$3 -> 0.295 | X18: =(W18+0.0066)/2.3929 -> 0.12603953 | Y18: =X18*7 -> 0.88227674
A19: G | P19: 0.5 | Q19: =AVERAGE(B30:C30) -> 1.4355 | R19: =Q19-Q$15 -> 1.052 | U19: AK | V19: 0.587 | W19: =V19-Q$3 -> 0.23 | X19: =(W19+0.0066)/2.3929 -> 0.098875841 | Y19: =X19*7 -> 0.69213089
A20: H | B20: 1.505 | C20: 1.591 | O20: 4 | U20: AL | V20: 0.529 | W20: =V20-Q$3 -> 0.172 | X20: =(W20+0.0066)/2.3929 -> 0.074637469 | Y20: =X20*7 -> 0.52246228
A21: 3 | P21: 0 | Q21: =AVERAGE(B33:C33) -> 0.3465 | R21: =Q21-Q$21 -> 0 | U21: AM | V21: 0.586 | W21: =V21-Q$3 -> 0.229 | X21: =(W21+0.0066)/2.3929 -> 0.098457938 | Y21: =X21*7 -> 0.68920557
B22: 1 | C22: 2 | D22: 3 | E22: 4 | F22: 5 | G22: 6 | H22: 7 | I22: 8 | J22: 9 | K22: 10 | L22: 11 | M22: 12 | P22: 0.05 | Q22: =AVERAGE(B34:C34) -> 0.4715 | R22: =Q22-Q$21 -> 0.125 | U22: AN | V22: 0.531 | W22: =V22-Q$3 -> 0.174 | X22: =(W22+0.0066)/2.3929 -> 0.075473275 | Y22: =X22*7 -> 0.52831293
A23: A | B23: 0.382 | C23: 0.385 | E23: 0.603 | F23: 0.499 | G23: 0.557 | H23: 0.524 | I23: 0.645 | J23: 0.541 | K23: 0.624 | L23: 0.573 | M23: 0.648 | P23: 0.1 | Q23: =AVERAGE(B36:C36) -> 0.5965 | R23: =Q23-Q$21 -> 0.25 | T23: 2 | U23: Sample ID | V23: Absorbance | W23: Corrected Absorbance | X23: Concentration (mg/mL) | Y23: Concentration (mg/g DW)
A24: B | B24: 0.479 | C24: 0.454 | P24: 0.25 | Q24: =AVERAGE(B38:C38) -> 0.7735 | R24: =Q24-Q$21 -> 0.427 | U24: T | V24: 0.618 | W24: =V24-Q$9 -> 0.2285 | X24: =(W24+0.0504)/2.3525 -> 0.11855473 | Y24: =X24*7 -> 0.8298831
A25: C | E25: 0.517 | F25: 0.537 | G25: 0.508 | H25: 0.549 | I25: 0.491 | J25: 0.571 | K25: 0.661 | L25: 0.598 | M25: 0.557 | P25: 0.5 | Q25: =AVERAGE(B40:C40) -> 1.07 | R25: =Q25-Q$21 -> 0.7235 | U25: U | V25: 0.548 | W25: =V25-Q$9 -> 0.1585 | X25: =(W25+0.0504)/2.3525 -> 0.08879915 | Y25: =X25*7 -> 0.62159405
A26: D | B26: 0.522 | C26: 0.64 | O26: 5 | U26: V | V26: 0.576 | W26: =V26-Q$9 -> 0.1865 | X26: =(W26+0.0504)/2.3525 -> 0.10070138 | Y26: =X26*7 -> 0.70490967
A27: E | E27: 0.57 | F27: 0.652 | P27: 0 | Q27: =AVERAGE(B43:C43) -> 0.3335 | R27: =Q27-Q$27 -> 0 | U27: W | V27: 0.487 | W27: =V27-Q$9 -> 0.0975 | X27: =(W27+0.0504)/2.3525 -> 0.062869288 | Y27: =X27*7 -> 0.44008502
A28: F | B28: 0.911 | C28: 0.877 | P28: 0.05 | Q28: =AVERAGE(B44:C44) -> 0.4715 | R28: =Q28-Q$27 -> 0.138 | U28: X | V28: 0.612 | W28: =V28-Q$9 -> 0.2225 | X28: =(W28+0.0504)/2.3525 -> 0.11600425 | Y28: =X28*7 -> 0.81202976
A29: G | P29: 0.1 | Q29: =AVERAGE(B46:C46) -> 0.591 | R29: =Q29-Q$27 -> 0.2575 | U29: Y | V29: 0.538 | W29: =V29-Q$9 -> 0.1485 | X29: =(W29+0.0504)/2.3525 -> 0.084548353 | Y29: =X29*7 -> 0.59183847
A30: H | B30: 1.296 | C30: 1.575 | P30: 0.25 | Q30: =AVERAGE(B48:C48) -> 0.7365 | R30: =Q30-Q$27 -> 0.403 | U30: Z | V30: 0.622 | W30: =V30-Q$9 -> 0.2325 | X30: =(W30+0.0504)/2.3525 -> 0.12025505 | Y30: =X30*7 -> 0.84178533
A31: 4 | P31: 0.5 | Q31: =AVERAGE(B50:C50) -> 1.0375 | R31: =Q31-Q$27 -> 0.704 | U31: AA | V31: 0.693 | W31: =V31-Q$9 -> 0.3035 | X31: =(W31+0.0504)/2.3525 -> 0.15043571 | Y31: =X31*7 -> 1.0530499
B32: 1 | C32: 2 | D32: 3 | E32: 4 | F32: 5 | G32: 6 | H32: 7 | I32: 8 | J32: 9 | K32: 10 | L32: 11 | M32: 12 | O32: 6 | U32: AB | V32: 0.758 | W32: =V32-Q$9 -> 0.3685 | X32: =(W32+0.0504)/2.3525 -> 0.17806589 | Y32: =X32*7 -> 1.2464612
A33: A | B33: 0.342 | C33: 0.351 | E33: 0.688 | F33: 0.813 | G33: 0.637 | H33: 0.646 | I33: 0.794 | J33: 0.702 | K33: 0.74 | L33: 0.663 | M33: 0.798 | P33: 0 | Q33: =AVERAGE(B53:C53) -> 0.3315 | R33: =Q33-Q$33 -> 0 | U33: AC | V33: 0.504 | W33: =V33-Q$9 -> 0.1145 | X33: =(W33+0.0504)/2.3525 -> 0.070095643 | Y33: =X33*7 -> 0.4906695
A34: B | B34: 0.464 | C34: 0.479 | P34: 0.05 | Q34: =AVERAGE(B54:C54) -> 0.475 | R34: =Q34-Q$33 -> 0.1435 | U34: AD | V34: 0.536 | W34: =V34-Q$9 -> 0.1465 | X34: =(W34+0.0504)/2.3525 -> 0.083698193 | Y34: =X34*7 -> 0.58588735
A35: C | E35: 0.664 | F35: 0.726 | G35: 0.682 | H35: 0.696 | I35: 0.613 | J35: 0.732 | K35: 0.753 | L35: 0.619 | M35: 0.678 | P35: 0.1 | Q35: =AVERAGE(B56:C56) -> 0.587 | R35: =Q35-Q$33 -> 0.2555 | U35: AE | V35: 0.555 | W35: =V35-Q$9 -> 0.1655 | X35: =(W35+0.0504)/2.3525 -> 0.091774708 | Y35: =X35*7 -> 0.64242295
A36: D | B36: 0.601 | C36: 0.592 | P36: 0.25 | Q36: =AVERAGE(B58:C58) -> 0.737 | R36: =Q36-Q$33 -> 0.4055 | U36: AG | V36: 0.628 | W36: =V36-Q$9 -> 0.2385 | X36: =(W36+0.0504)/2.3525 -> 0.12280553 | Y36: =X36*7 -> 0.85963868
A37: E | E37: 0.77 | F37: 0.626 | P37: 0.5 | Q37: =AVERAGE(B60:C60) -> 1.049 | R37: =Q37-Q$33 -> 0.7175 | U37: AH | V37: 0.473 | W37: =V37-Q$9 -> 0.0835 | X37: =(W37+0.0504)/2.3525 -> 0.056918172 | Y37: =X37*7 -> 0.39842721
A38: F | B38: 0.76 | C38: 0.787 | U38: AI | V38: 0.573 | W38: =V38-Q$9 -> 0.1835 | X38: =(W38+0.0504)/2.3525 -> 0.099426142 | Y38: =X38*7 -> 0.695983
A39: G | U39: AJ | V39: 0.615 | W39: =V39-Q$9 -> 0.2255 | X39: =(W39+0.0504)/2.3525 -> 0.11727949 | Y39: =X39*7 -> 0.82095643
A40: H | B40: 1.081 | C40: 1.059 | U40: AK | V40: 0.613 | W40: =V40-Q$9 -> 0.2235 | X40: =(W40+0.0504)/2.3525 -> 0.11642933 | Y40: =X40*7 -> 0.81500531
...

Sheet ANR
A1: 1 | P1: STANDARD CURVES | U1: SAMPLES
B2: 1 | C2: 2 | D2: 3 | E2: 4 | F2: 5 | G2: 6 | H2: 7 | I2: 8 | J2: 9 | K2: 10 | L2: 11 | M2: 12 | O2: 1 | Q2: AVG Absorbance | R2: Corrected AVG | T2: 1 | U2: Sample ID | V2: Absorbance | W2: Corrected Absorbance | X2: Concentration (mg/mL) | Y2: Concentration (mg/g DW)
A3: A | B3: 0.451 | C3: 0.391 | E3: 0.611 | F3: 0.677 | G3: 0.738 | H3: 0.639 | I3: 0.538 | J3: 0.74 | K3: 0.621 | L3: 0.72 | M3: 0.801 | P3: 0 | Q3: =AVERAGE(B3:C3) -> 0.421 | R3: =Q3-Q$3 -> 0 | U3: AO | V3: 0.611 | W3: =V3-Q$3 -> 0.19 | X3: =(W3-0.0294)/1.7052 -> 0.094182501 | Y3: =X3*7 -> 0.6592775
A4: B | B4: 0.559 | C4: 0.518 | P4: 0.05 | Q4: =AVERAGE(B4:C4) -> 0.5385 | R4: =Q4-Q$3 -> 0.1175 | U4: AP | V4: 0.677 | W4: =V4-Q$3 -> 0.256 | X4: =(W4-0.0294)/1.7052 -> 0.13288764 | Y4: =X4*7 -> 0.93021346
A5: C | E5: 0.673 | F5: 0.762 | G5: 0.778 | H5: 0.679 | I5: 0.736 | J5: 0.787 | K5: 0.715 | L5: 0.701 | M5: 0.533 | P5: 0.1 | Q5: =AVERAGE(B6:C6) -> 0.631 | R5: =Q5-Q$3 -> 0.21 | U5: AQ | V5: 0.738 | W5: =V5-Q$3 -> 0.317 | X5: =(W5-0.0294)/1.7052 -> 0.16866057 | Y5: =X5*7 -> 1.180624
A6: D | B6: 0.617 | C6: 0.645 | P6: 0.25 | Q6: =AVERAGE(B8:C8) -> 0.914 | R6: =Q6-Q$3 -> 0.493 | U6: AR | V6: 0.639 | W6: =V6-Q$3 -> 0.218 | X6: =(W6-0.0294)/1.7052 -> 0.11060286 | Y6: =X6*7 -> 0.77422003
A7: E | E7: 0.638 | F7: 0.976 | G7: 0.82 | P7: 0.5 | Q7: =AVERAGE(B10:C10) -> 1.282 | R7: =Q7-Q$3 -> 0.861 | U7: AS | V7: 0.538 | W7: =V7-Q$3 -> 0.117 | X7: =(W7-0.0294)/1.7052 -> 0.051372273 | Y7: =X7*7 -> 0.35960591
A8: F | B8: 0.908 | C8: 0.92 | O8: 2 | U8: AT | V8: 0.74 | W8: =V8-Q$3 -> 0.319 | X8: =(W8-0.0294)/1.7052 -> 0.16983345 | Y8: =X8*7 -> 1.1888342
A9: G | P9: 0 | Q9: =AVERAGE(B13:C13) -> 0.3765 | R9: =Q9-Q$9 -> 0 | U9: AU | V9: 0.621 | W9: =V9-Q$3 -> 0.2 | X9: =(W9-0.0294)/1.7052 -> 0.10004692 | Y9: =X9*7 -> 0.70032841
A10: H | B10: 1.217 | C10: 1.347 | P10: 0.05 | Q10: =AVERAGE(B14:C14) -> 0.5515 | R10: =Q10-Q$9 -> 0.175 | U10: AV | V10: 0.72 | W10: =V10-Q$3 -> 0.299 | X10: =(W10-0.0294)/1.7052 -> 0.15810462 | Y10: =X10*7 -> 1.1067323
A11: 2 | P11: 0.1 | Q11: =AVERAGE(B16:C16) -> 0.545 | R11: =Q11-Q$9 -> 0.1685 | U11: AW | V11: 0.801 | W11: =V11-Q$3 -> 0.38 | X11: =(W11-0.0294)/1.7052 -> 0.20560638 | Y11: =X11*7 -> 1.4392447
B12: 1 | C12: 2 | D12: 3 | E12: 4 | F12: 5 | G12: 6 | H12: 7 | I12: 8 | J12: 9 | K12: 10 | L12: 11 | M12: 12 | P12: 0.25 | Q12: =AVERAGE(B18:C18) -> 0.8795 | R12: =Q12-Q$9 -> 0.503 | U12: AX | V12: 0.673 | W12: =V12-Q$3 -> 0.252 | X12: =(W12-0.0294)/1.7052 -> 0.13054187 | Y12: =X12*7 -> 0.9137931
A13: A | B13: 0.348 | C13: 0.405 | E13: 0.59 | F13: 0.676 | G13: 0.679 | H13: 0.688 | I13: 0.591 | J13: 0.668 | K13: 0.579 | L13: 0.709 | M13: 0.716 | P13: 0.5 | Q13: =AVERAGE(B20:C20) -> 1.4185 | R13: =Q13-Q$9 -> 1.042 | U13: AY | V13: 0.762 | W13: =V13-Q$3 -> 0.341 | X13: =(W13-0.0294)/1.7052 -> 0.18273516 | Y13: =X13*7 -> 1.2791461
A14: B | B14: 0.552 | C14: 0.551 | O14: 3 | U14: AZ | V14: 0.778 | W14: =V14-Q$3 -> 0.357 | X14: =(W14-0.0294)/1.7052 -> 0.19211823 | Y14: =X14*7 -> 1.3448276
A15: C | E15: 0.646 | F15: 0.646 | G15: 0.699 | H15: 0.667 | I15: 0.727 | J15: 0.534 | K15: 0.676 | L15: 0.75 | M15: 0.564 | P15: 0 | Q15: =AVERAGE(B23:C23) -> 0.374 | R15: =Q15-Q$15 -> 0 | U15: BA | V15: 0.679 | W15: =V15-Q$3 -> 0.258 | X15: =(W15-0.0294)/1.7052 -> 0.13406052 | Y15: =X15*7 -> 0.93842365
A16: D | B16: 0.633 | C16: 0.457 | P16: 0.05 | Q16: =AVERAGE(B24:C24) -> 0.4875 | R16: =Q16-Q$15 -> 0.1135 | U16: BB | V16: 0.736 | W16: =V16-Q$3 -> 0.315 | X16: =(W16-0.0294)/1.7052 -> 0.16748768 | Y16: =X16*7 -> 1.1724138
A17: E | E17: 0.771 | F17: 0.823 | G17: 0.837 | P17: 0.1 | Q17: =AVERAGE(B26:C26) -> 0.626 | R17: =Q17-Q$15 -> 0.252 | U17: BC | V17: 0.787 | W17: =V17-Q$3 -> 0.366 | X17: =(W17-0.0294)/1.7052 -> 0.1973962 | Y17: =X17*7 -> 1.3817734
A18: F | B18: 0.886 | C18: 0.873 | P18: 0.25 | Q18: =AVERAGE(B28:C28) -> 0.9315 | R18: =Q18-Q$15 -> 0.5575 | U18: BD | V18: 0.715 | W18: =V18-Q$3 -> 0.294 | X18: =(W18-0.0294)/1.7052 -> 0.15517241 | Y18: =X18*7 -> 1.0862069
A19: G | P19: 0.5 | Q19: =AVERAGE(B30:C30) -> 1.3645 | R19: =Q19-Q$15 -> 0.9905 | U19: BE | V19: 0.701 | W19: =V19-Q$3 -> 0.28 | X19: =(W19-0.0294)/1.7052 -> 0.14696223 | Y19: =X19*7 -> 1.0287356
A20: H | B20: 1.411 | C20: 1.426 | O20: 4 | U20: BG | V20: 0.533 | W20: =V20-Q$3 -> 0.112 | X20: =(W20-0.0294)/1.7052 -> 0.048440066 | Y20: =X20*7 -> 0.33908046
A21: 3 | P21: 0 | Q21: =AVERAGE(B33:C33) -> 0.3685 | R21: =Q21-Q$21 -> 0 | U21: BH | V21: 0.638 | W21: =V21-Q$3 -> 0.217 | X21: =(W21-0.0294)/1.7052 -> 0.11001642 | Y21: =X21*7 -> 0.77011494
B22: 1 | C22: 2 | D22: 3 | E22: 4 | F22: 5 | G22: 6 | H22: 7 | I22: 8 | J22: 9 | K22: 10 | L22: 11 | M22: 12 | P22: 0.05 | Q22: =AVERAGE(B34:C34) -> 0.506 | R22: =Q22-Q$21 -> 0.1375 | U22: BI | V22: 0.976 | W22: =V22-Q$3 -> 0.555 | X22: =(W22-0.0294)/1.7052 -> 0.30823364 | Y22: =X22*7 -> 2.1576355
A23: A | B23: 0.356 | C23: 0.392 | E23: 0.533 | F23: 0.668 | G23: 0.722 | H23: 0.692 | I23: 0.589 | J23: 0.604 | K23: 0.394 | L23: 0.699 | M23: 0.699 | P23: 0.1 | Q23: =AVERAGE(B36:C36) -> 0.628 | R23: =Q23-Q$21 -> 0.2595 | U23: BJ | V23: 0.82 | W23: =V23-Q$3 -> 0.399 | X23: =(W23-0.0294)/1.7052 -> 0.21674877 | Y23: =X23*7 -> 1.5172414
A24: B | B24: 0.522 | C24: 0.453 | P24: 0.25 | Q24: =AVERAGE(B38:C38) -> 0.9005 | R24: =Q24-Q$21 -> 0.532 | T24: 2 | U24: Sample ID | V24: Absorbance | W24: Corrected Absorbance | X24: Concentration (mg/mL) | Y24: Concentration (mg/g DW)
A25: C | E25: 0.643 | F25: 0.721 | G25: 0.741 | H25: 0.695 | I25: 0.725 | J25: 0.749 | K25: 0.544 | L25: 0.835 | M25: 0.607 | P25: 0.5 | Q25: =AVERAGE(B40:C40) -> 1.276 | R25: =Q25-Q$21 -> 0.9075 | U25: AO | V25: 0.59 | W25: =V25-Q$9 -> 0.2135 | X25: =(W25-0.0106)/2.0394 -> 0.099490046 | Y25: =X25*7 -> 0.69643032
A26: D | B26: 0.622 | C26: 0.63 | O26: 5 | U26: AP | V26: 0.676 | W26: =V26-Q$9 -> 0.2995 | X26: =(W26-0.0106)/2.0394 -> 0.14165931 | Y26: =X26*7 -> 0.99161518
A27: E | E27: 0.66 | F27: 0.846 | G27: 0.919 | P27: 0 | Q27: =AVERAGE(B43:C43) -> 0.3375 | R27: =Q27-Q$27 -> 0 | U27: AQ | V27: 0.679 | W27: =V27-Q$9 -> 0.3025 | X27: =(W27-0.0106)/2.0394 -> 0.14313033 | Y27: =X27*7 -> 1.0019123
A28: F | B28: 0.938 | C28: 0.925 | P28: 0.05 | Q28: =AVERAGE(B44:C44) -> 0.494 | R28: =Q28-Q$27 -> 0.1565 | U28: AR | V28: 0.688 | W28: =V28-Q$9 -> 0.3115 | X28: =(W28-0.0106)/2.0394 -> 0.1475434 | Y28: =X28*7 -> 1.0328038
A29: G | P29: 0.1 | Q29: =AVERAGE(B46:C46) -> 0.5995 | R29: =Q29-Q$27 -> 0.262 | U29: AS | V29: 0.591 | W29: =V29-Q$9 -> 0.2145 | X29: =(W29-0.0106)/2.0394 -> 0.099980386 | Y29: =X29*7 -> 0.6998627
A30: H | B30: 1.38 | C30: 1.349 | P30: 0.25 | Q30: =AVERAGE(B48:C48) -> 0.863 | R30: =Q30-Q$27 -> 0.5255 | U30: AT | V30: 0.668 | W30: =V30-Q$9 -> 0.2915 | X30: =(W30-0.0106)/2.0394 -> 0.13773659 | Y30: =X30*7 -> 0.96415612
A31: 4 | P31: 0.5 | Q31: =AVERAGE(B50:C50) -> 1.1935 | R31: =Q31-Q$27 -> 0.856 | U31: AU | V31: 0.579 | W31: =V31-Q$9 -> 0.2025 | X31: =(W31-0.0106)/2.0394 -> 0.094096303 | Y31: =X31*7 -> 0.65867412
B32: 1 | C32: 2 | D32: 3 | E32: 4 | F32: 5 | G32: 6 | H32: 7 | I32: 8 | J32: 9 | K32: 10 | L32: 11 | M32: 12 | O32: 6 | U32: AV | V32: 0.709 | W32: =V32-Q$9 -> 0.3325 | X32: =(W32-0.0106)/2.0394 -> 0.15784054 | Y32: =X32*7 -> 1.1048838
A33: A | B33: 0.366 | C33: 0.371 | P33: 0 | Q33: =AVERAGE(B53:C53) -> 0.361 | R33: =Q33-Q$33 -> 0 | U33: AW | V33: 0.716 | W33: =V33-Q$9 -> 0.3395 | X33: =(W33-0.0106)/2.0394 -> 0.16127292 | Y33: =X33*7 -> 1.1289105
A34: B | B34: 0.502 | C34: 0.51 | E34: 0.707 | F34: 0.889 | G34: 0.72 | H34: 0.8 | I34: 0.831 | J34: 0.864 | K34: 0.732 | L34: 0.867 | P34: 0.05 | Q34: =AVERAGE(B54:C54) -> 0.516 | R34: =Q34-Q$33 -> 0.155 | U34: AX | V34: 0.646 | W34: =V34-Q$9 -> 0.2695 | X34: =(W34-0.0106)/2.0394 -> 0.1269491 | Y34: =X34*7 -> 0.88864372
A35: C | E35: 0.746 | F35: 0.833 | G35: 0.715 | H35: 0.823 | I35: 0.808 | J35: 0.805 | K35: 0.676 | L35: 0.789 | P35: 0.1 | Q35: =AVERAGE(B56:C56) -> 0.6295 | R35: =Q35-Q$33 -> 0.2685 | U35: AY | V35: 0.646 | W35: =V35-Q$9 -> 0.2695 | X35: =(W35-0.0106)/2.0394 -> 0.1269491 | Y35: =X35*7 -> 0.88864372
A36: D | B36: 0.633 | C36: 0.623 | E36: 0.808 | F36: 0.891 | G36: 0.803 | H36: 0.684 | J36: 0.615 | K36: 0.651 | L36: 0.637 | P36: 0.25 | Q36: =AVERAGE(B58:C58) -> 0.898 | R36: =Q36-Q$33 -> 0.537 | U36: AZ | V36: 0.699 | W36: =V36-Q$9 -> 0.3225 | X36: =(W36-0.0106)/2.0394 -> 0.15293714 | Y36: =X36*7 -> 1.07056
A37: E | E37: 0.569 | F37: 0.61 | G37: 0.691 | H37: 0.704 | I37: 0.598 | J37: 0.584 | K37: 0.594 | L37: 0.604 | P37: 0.5 | Q37: =AVERAGE(B60:C60) -> 1.213 | R37: =Q37-Q$33 -> 0.852 | U37: BA | V37: 0.667 | W37: =V37-Q$9 -> 0.2905 | X37: =(W37-0.0106)/2.0394 -> 0.13724625 | Y37: =X37*7 -> 0.96072374
A38: F | B38: 0.902 | C38: 0.899 | E38: 0.638 | F38: 0.634 | U38: BB | V38: 0.727 | W38: =V38-Q$9 -> 0.3505 | X38: =(W38-0.0106)/2.0394 -> 0.16666667 | Y38: =X38*7 -> 1.1666667
A39: G | U39: BC | V39: 0.534 | W39: =V39-Q$9 -> 0.1575 | X39: =(W39-0.0106)/2.0394 -> 0.07203099 | Y39: =X39*7 -> 0.50421693
A40: H | B40: 1.258 | C40: 1.294 | U40: BD | V40: 0.676 | W40: =V40-Q$9 -> 0.2995 | X40: =(W40-0.0106)/2.0394 -> 0.14165931 | Y40: =X40*7 -> 0.99161518
...

Sheet JM
A1: 1 | P1: STANDARD CURVES | U1: SAMPLES
B2: 1 | C2: 2 | D2: 3 | E2: 4 | F2: 5 | G2: 6 | H2: 7 | I2: 8 | J2: 9 | K2: 10 | L2: 11 | M2: 12 | O2: 1 | Q2: AVG Absorbance | R2: Corrected AVG | T2: 1 | U2: Sample ID | V2: Absorbance | W2: Corrected Absorbance | X2: Concentration (mg/mL) | Y2: Concentration (mg/g DW)
A3: A | B3: 0.368 | C3: 0.342 | D3: 0.369 | E3: 0.59 | F3: 0.568 | G3: 0.837 | H3: 0.565 | I3: 0.715 | J3: 0.572 | K3: 0.59 | L3: 0.513 | M3: 0.554 | P3: 0 | Q3: =AVERAGE(I8:I10) -> 0.36466667 | R3: =Q3-Q$3 -> 0 | U3: BK | V3: 0.59 | W3: =V3-Q$3 -> 0.22533333 | X3: =(W3-0.0672)/2.0071 -> 0.078786973 | Y3: =X3*7 -> 0.55150881
A4: B | P4: 0.05 | Q4: =AVERAGE(J8:J10) -> 0.53233333 | R4: =Q4-Q$3 -> 0.16766667 | U4: BL | V4: 0.568 | W4: =V4-Q$3 -> 0.20333333 | X4: =(W4-0.0672)/2.0071 -> 0.067825885 | Y4: =X4*7 -> 0.47478119
A5: C | E5: 0.561 | F5: 0.592 | G5: 0.046 | P5: 0.1 | Q5: =AVERAGE(K8:K10) -> 0.71366667 | R5: =Q5-Q$3 -> 0.349 | U5: BM | V5: 0.837 | W5: =V5-Q$3 -> 0.47233333 | X5: =(W5-0.0672)/2.0071 -> 0.2018501 | Y5: =X5*7 -> 1.4129507
A6: D | P6: 0.25 | Q6: =AVERAGE(L8:L10) -> 0.938 | R6: =Q6-Q$3 -> 0.57333333 | U6: BN | V6: 0.565 | W6: =V6-Q$3 -> 0.20033333 | X6: =(W6-0.0672)/2.0071 -> 0.066331191 | Y6: =X6*7 -> 0.46431834
A7: E | P7: 0.5 | Q7: =AVERAGE(M8:M10) -> 1.417 | R7: =Q7-Q$3 -> 1.0523333 | U7: BO | V7: 0.715 | W7: =V7-Q$3 -> 0.35033333 | X7: =(W7-0.0672)/2.0071 -> 0.14106588 | Y7: =X7*7 -> 0.98746118
A8: F | I8: 0.36 | J8: 0.517 | K8: 0.718 | L8: 1.016 | M8: 1.41 | O8: 2 | U8: BP | V8: 0.572 | W8: =V8-Q$3 -> 0.20733333 | X8: =(W8-0.0672)/2.0071 -> 0.06981881 | Y8: =X8*7 -> 0.48873167
A9: G | I9: 0.37 | J9: 0.548 | K9: 0.722 | L9: 0.981 | M9: 1.428 | P9: 0 | Q9: =AVERAGE(B13:D13) -> 0.355 | R9: =Q9-Q$9 -> 0 | U9: BQ | V9: 0.59 | W9: =V9-Q$3 -> 0.22533333 | X9: =(W9-0.0672)/2.0071 -> 0.078786973 | Y9: =X9*7 -> 0.55150881
A10: H | I10: 0.364 | J10: 0.532 | K10: 0.701 | L10: 0.817 | M10: 1.413 | P10: 0.05 | Q10: =AVERAGE(J18:J20) -> 0.49733333 | R10: =Q10-Q$9 -> 0.14233333 | U10: BR | V10: 0.513 | W10: =V10-Q$3 -> 0.14833333 | X10: =(W10-0.0672)/2.0071 -> 0.040423164 | Y10: =X10*7 -> 0.28296215
A11: 2 | P11: 0.1 | Q11: =AVERAGE(K18:K20) -> 0.714 | R11: =Q11-Q$9 -> 0.359 | U11: BS | V11: 0.554 | W11: =V11-Q$3 -> 0.18933333 | X11: =(W11-0.0672)/2.0071 -> 0.060850647 | Y11: =X11*7 -> 0.42595453
B12: 1 | C12: 2 | D12: 3 | E12: 4 | F12: 5 | G12: 6 | H12: 7 | I12: 8 | J12: 9 | K12: 10 | L12: 11 | M12: 12 | P12: 0.25 | Q12: =AVERAGE(L18:L20) -> 1.0133333 | R12: =Q12-Q$9 -> 0.65833333 | U12: BT | V12: 0.561 | W12: =V12-Q$3 -> 0.19633333 | X12: =(W12-0.0672)/2.0071 -> 0.064338266 | Y12: =X12*7 -> 0.45036786
A13: A | B13: 0.367 | C13: 0.346 | D13: 0.352 | E13: 0.565 | F13: 0.561 | G13: 0.764 | H13: 0.565 | I13: 0.684 | J13: 0.563 | K13: 0.606 | L13: 0.503 | M13: 0.536 | P13: 0.5 | Q13: =AVERAGE(M18:M20) -> 1.381 | R13: =Q13-Q$9 -> 1.026 | U13: BU | V13: 0.592 | W13: =V13-Q$3 -> 0.22733333 | X13: =(W13-0.0672)/2.0071 -> 0.079783435 | Y13: =X13*7 -> 0.55848405
A14: B | O14: 3 | T14: 2 | U14: Sample ID | V14: Absorbance | W14: Corrected Absorbance | X14: Concentration (mg/mL) | Y14: Concentration (mg/g DW)
A15: C | E15: 0.551 | F15: 0.551 | G15: 0.045 | P15: 0 | Q15: =AVERAGE(B23:D23) -> 0.364 | R15: =Q15-Q$15 -> 0 | U15: BK | V15: 0.565 | W15: =V15-Q$9 -> 0.21 | X15: =(W15-0.0758)/2.0072 -> 0.066859306 | Y15: =X15*7 -> 0.46801515
A16: D | P16: 0.05 | Q16: =AVERAGE(J28:J30) -> 0.55666667 | R16: =Q16-Q$15 -> 0.19266667 | U16: BL | V16: 0.561 | W16: =V16-Q$9 -> 0.206 | X16: =(W16-0.0758)/2.0072 -> 0.064866481 | Y16: =X16*7 -> 0.45406536
A17: E | P17: 0.1 | Q17: =AVERAGE(K28:K30) -> 0.717 | R17: =Q17-Q$15 -> 0.353 | U17: BM | V17: 0.764 | W17: =V17-Q$9 -> 0.409 | X17: =(W17-0.0758)/2.0072 -> 0.16600239 | Y17: =X17*7 -> 1.1620167
A18: F | I18: 0.044 | J18: 0.552 | K18: 0.717 | L18: 1.01 | M18: 1.371 | P18: 0.25 | Q18: =AVERAGE(L28:L30) -> 0.98233333 | R18: =Q18-Q$15 -> 0.61833333 | U18: BN | V18: 0.565 | W18: =V18-Q$9 -> 0.21 | X18: =(W18-0.0758)/2.0072 -> 0.066859306 | Y18: =X18*7 -> 0.46801515
A19: G | I19: 0.044 | J19: 0.395 | K19: 0.718 | L19: 1.027 | M19: 1.395 | P19: 0.5 | Q19: =AVERAGE(M28:M30) -> 1.402 | R19: =Q19-Q$15 -> 1.038 | U19: BO | V19: 0.684 | W19: =V19-Q$9 -> 0.329 | X19: =(W19-0.0758)/2.0072 -> 0.12614587 | Y19: =X19*7 -> 0.88302112
A20: H | I20: 0.044 | J20: 0.545 | K20: 0.707 | L20: 1.003 | M20: 1.377 | O20: 4 | U20: BP | V20: 0.563 | W20: =V20-Q$9 -> 0.208 | X20: =(W20-0.0758)/2.0072 -> 0.065862894 | Y20: =X20*7 -> 0.46104026
A21: 3 | P21: 0 | Q21: =AVERAGE(B33:C33) -> 0.38 | R21: =Q21-Q$21 -> 0 | U21: BQ | V21: 0.606 | W21: =V21-Q$9 -> 0.251 | X21: =(W21-0.0758)/2.0072 -> 0.087285771 | Y21: =X21*7 -> 0.6110004
B22: 1 | C22: 2 | D22: 3 | E22: 4 | F22: 5 | G22: 6 | H22: 7 | I22: 8 | J22: 9 | K22: 10 | L22: 11 | M22: 12 | P22: 0.05 | Q22: =AVERAGE(B34:C34) -> 0.539 | R22: =Q22-Q$21 -> 0.159 | U22: BR | V22: 0.503 | W22: =V22-Q$9 -> 0.148 | X22: =(W22-0.0758)/2.0072 -> 0.035970506 | Y22: =X22*7 -> 0.25179354
A23: A | B23: 0.347 | C23: 0.371 | D23: 0.374 | E23: 0.564 | F23: 0.561 | G23: 0.874 | H23: 0.584 | I23: 0.73 | J23: 0.57 | K23: 0.546 | L23: 0.529 | M23: 0.575 | P23: 0.1 | Q23: =AVERAGE(B36:C36) -> 0.6405 | R23: =Q23-Q$21 -> 0.2605 | U23: BS | V23: 0.536 | W23: =V23-Q$9 -> 0.181 | X23: =(W23-0.0758)/2.0072 -> 0.052411319 | Y23: =X23*7 -> 0.36687923
A24: B | P24: 0.25 | Q24: =AVERAGE(B38:C38) -> 0.8665 | R24: =Q24-Q$21 -> 0.4865 | U24: BT | V24: 0.551 | W24: =V24-Q$9 -> 0.196 | X24: =(W24-0.0758)/2.0072 -> 0.059884416 | Y24: =X24*7 -> 0.41919091
A25: C | E25: 0.549 | F25: 0.27 | G25: 0.618 | P25: 0.5 | Q25: =AVERAGE(B40:C40) -> 1.3145 | R25: =Q25-Q$21 -> 0.9345 | U25: BU | V25: 0.551 | W25: =V25-Q$9 -> 0.196 | X25: =(W25-0.0758)/2.0072 -> 0.059884416 | Y25: =X25*7 -> 0.41919091
A26: D | O26: 5 | T26: 3 | U26: Sample ID | V26: Absorbance | W26: Corrected Absorbance | X26: Concentration (mg/mL) | Y26: Concentration (mg/g DW)
A27: E | P27: 0 | Q27: =AVERAGE(B43:C43) -> 0.38 | R27: =Q27-Q$27 -> 0 | U27: BK | V27: 0.564 | W27: =V27-Q$15 -> 0.2 | X27: =(W27-0.0846)/1.9764 -> 0.05838899 | Y27: =X27*7 -> 0.40872293
A28: F | I28: 0.045 | J28: 0.56 | K28: 0.719 | L28: 0.977 | M28: 1.401 | P28: 0.05 | Q28: =AVERAGE(B44:C44) -> 0.5615 | R28: =Q28-Q$27 -> 0.1815 | U28: BL | V28: 0.561 | W28: =V28-Q$15 -> 0.197 | X28: =(W28-0.0846)/1.9764 -> 0.056871079 | Y28: =X28*7 -> 0.39809755
A29: G | I29: 0.044 | J29: 0.551 | K29: 0.726 | L29: 1.039 | M29: 1.402 | P29: 0.1 | Q29: =AVERAGE(B46:C46) -> 0.6615 | R29: =Q29-Q$27 -> 0.2815 | U29: BM | V29: 0.874 | W29: =V29-Q$15 -> 0.51 | X29: =(W29-0.0846)/1.9764 -> 0.21523983 | Y29: =X29*7 -> 1.5066788
A30: H | I30: 0.045 | J30: 0.559 | K30: 0.706 | L30: 0.931 | M30: 1.403 | P30: 0.25 | Q30: =AVERAGE(B48:C48) -> 0.825 | R30: =Q30-Q$27 -> 0.445 | U30: BN | V30: 0.584 | W30: =V30-Q$15 -> 0.22 | X30: =(W30-0.0846)/1.9764 -> 0.068508399 | Y30: =X30*7 -> 0.47955879
A31: 4 | B31: (BS MISSING) | P31: 0.5 | Q31: =AVERAGE(B50:C50) -> 1.2615 | R31: =Q31-Q$27 -> 0.8815 | U31: BO | V31: 0.73 | W31: =V31-Q$15 -> 0.366 | X31: =(W31-0.0846)/1.9764 -> 0.14238009 | Y31: =X31*7 -> 0.9966606
B32: 1 | C32: 2 | D32: 3 | E32: 4 | F32: 5 | G32: 6 | H32: 7 | I32: 8 | J32: 9 | K32: 10 | L32: 11 | M32: 12 | O32: 6 | U32: BP | V32: 0.57 | W32: =V32-Q$15 -> 0.206 | X32: =(W32-0.0846)/1.9764 -> 0.061424813 | Y32: =X32*7 -> 0.42997369
A33: A | B33: 0.377 | C33: 0.383 | E33: 0.574 | F33: 0.544 | G33: 0.759 | H33: 0.477 | I33: 0.654 | J33: 0.554 | K33: 0.571 | L33: 0.546 | M33: 0.543 | P33: 0 | Q33: =AVERAGE(B53:C53) -> 0.408 | R33: =Q33-Q$33 -> 0 | U33: BQ | V33: 0.546 | W33: =V33-Q$15 -> 0.182 | X33: =(W33-0.0846)/1.9764 -> 0.049281522 | Y33: =X33*7 -> 0.34497065
A34: B | B34: 0.541 | C34: 0.537 | E34: 0.587 | P34: 0.05 | Q34: =AVERAGE(B54:C54) -> 0.583 | R34: =Q34-Q$33 -> 0.175 | U34: BR | V34: 0.529 | W34: =V34-Q$15 -> 0.165 | X34: =(W34-0.0846)/1.9764 -> 0.040680024 | Y34: =X34*7 -> 0.28476017
A35: C | B35: 0.044 | C35: 0.044 | P35: 0.1 | Q35: =AVERAGE(B56:C56) -> 0.664 | R35: =Q35-Q$33 -> 0.256 | U35: BS | V35: 0.575 | W35: =V35-Q$15 -> 0.211 | X35: =(W35-0.0846)/1.9764 -> 0.063954665 | Y35: =X35*7 -> 0.44768266
A36: D | B36: 0.649 | C36: 0.632 | P36: 0.25 | Q36: =AVERAGE(B58:C58) -> 0.7635 | R36: =Q36-Q$33 -> 0.3555 | U36: BT | V36: 0.549 | W36: =V36-Q$15 -> 0.185 | X36: =(W36-0.0846)/1.9764 -> 0.050799433 | Y36: =X36*7 -> 0.35559603
A37: E | B37: 0.045 | C37: 0.044 | P37: 0.5 | Q37: =AVERAGE(B60:C60) -> 1.341 | R37: =Q37-Q$33 -> 0.933 | U37: BU | V37: 0.618 | W37: =V37-Q$15 -> 0.254 | X37: =(W37-0.0846)/1.9764 -> 0.085711394 | Y37: =X37*7 -> 0.59997976
A38: F | B38: 0.863 | C38: 0.87 | T38: 3 | U38: Sample ID | V38: Absorbance | W38: Corrected Absorbance | X38: Concentration (mg/mL) | Y38: Concentration (mg/g DW)
A39: G | B39: 0.045 | C39: 0.044 | U39: BK | V39: 0.574 | W39: =V39-Q$21 -> 0.194 | X39: =(W39-0.0461)/1.7889 -> 0.082676505 | Y39: =X39*7 -> 0.57873554
A40: H | B40: 1.301 | C40: 1.328 | U40: BL | V40: 0.544 | W40: =V40-Q$21 -> 0.164 | X40: =(W40-0.0461)/1.7889 -> 0.065906423 | Y40: =X40*7 -> 0.46134496
...

Sheet JR
A1: 1 | P1: STANDARD CURVES | U1: SAMPLES
B2: 1 | C2: 2 | D2: 3 | E2: 4 | F2: 5 | G2: 6 | H2: 7 | I2: 8 | J2: 9 | K2: 10 | L2: 11 | M2: 12 | O2: 1 | Q2: AVG Absorbance | R2: Corrected AVG | T2: 1 | U2: Sample ID | V2: Absorbance | W2: Corrected Absorbance | X2: Concentration (mg/mL) | Y2: Concentration (mg/g DW)
A3: A | B3: 0.423 | C3: 0.387 | E3: 0.62 | F3: 0.606 | G3: 0.57 | H3: 0.56 | I3: 0.593 | J3: 0.686 | K3: 0.644 | L3: 0.578 | M3: 0.561 | P3: 0 | Q3: =AVERAGE(B3:C3) -> 0.405 | R3: =Q3-Q$3 -> 0 | U3: BV | V3: 0.62 | W3: =V3-Q$3 -> 0.215 | X3: =(W3-0.0463)/1.7857 -> 0.094472756 | Y3: =7*X3 -> 0.66130929
A4: B | B4: 0.571 | C4: 0.568 | P4: 0.05 | Q4: =AVERAGE(B4:C4) -> 0.5695 | R4: =Q4-Q$3 -> 0.1645 | U4: BW | V4: 0.606 | W4: =V4-Q$3 -> 0.201 | X4: =(W4-0.0463)/1.7857 -> 0.086632693 | Y4: =7*X4 -> 0.60642885
A5: C | E5: 0.581 | F5: 0.587 | G5: 0.639 | H5: 0.613 | P5: 0.1 | Q5: =AVERAGE(B6:C6) -> 0.664 | R5: =Q5-Q$3 -> 0.259 | U5: BX | V5: 0.57 | W5: =V5-Q$3 -> 0.165 | X5: =(W5-0.0463)/1.7857 -> 0.066472532 | Y5: =7*X5 -> 0.46530772
A6: D | B6: 0.669 | C6: 0.659 | F6: 0.044 | P6: 0.25 | Q6: =AVERAGE(B8:C8) -> 0.8835 | R6: =Q6-Q$3 -> 0.4785 | U6: BY | V6: 0.56 | W6: =V6-Q$3 -> 0.155 | X6: =(W6-0.0463)/1.7857 -> 0.060872487 | Y6: =7*X6 -> 0.42610741
A7: E | P7: 0.5 | Q7: =AVERAGE(B10:C10) -> 1.3415 | R7: =Q7-Q$3 -> 0.9365 | U7: BZ | V7: 0.593 | W7: =V7-Q$3 -> 0.188 | X7: =(W7-0.0463)/1.7857 -> 0.079352635 | Y7: =7*X7 -> 0.55546844
A8: F | B8: 0.892 | C8: 0.875 | O8: 2 | U8: CA | V8: 0.686 | W8: =V8-Q$3 -> 0.281 | X8: =(W8-0.0463)/1.7857 -> 0.13143305 | Y8: =7*X8 -> 0.92003136
A9: G | P9: 0 | Q9: =AVERAGE(B13:C13) -> 0.3805 | R9: =Q9-Q$9 -> 0 | U9: CB | V9: 0.644 | W9: =V9-Q$3 -> 0.239 | X9: =(W9-0.0463)/1.7857 -> 0.10791286 | Y9: =7*X9 -> 0.75539004
A10: H | B10: 1.353 | C10: 1.33 | P10: 0.05 | Q10: =AVERAGE(B14:C14) -> 0.526 | R10: =Q10-Q$9 -> 0.1455 | U10: CC | V10: 0.578 | W10: =V10-Q$3 -> 0.173 | X10: =(W10-0.0463)/1.7857 -> 0.070952568 | Y10: =7*X10 -> 0.49666797
A11: 2 | P11: 0.1 | Q11: =AVERAGE(B16:C16) -> 0.644 | R11: =Q11-Q$9 -> 0.2635 | U11: CD | V11: 0.561 | W11: =V11-Q$3 -> 0.156 | X11: =(W11-0.0463)/1.7857 -> 0.061432491 | Y11: =7*X11 -> 0.43002744
B12: 1 | C12: 2 | D12: 3 | E12: 4 | F12: 5 | G12: 6 | H12: 7 | I12: 8 | J12: 9 | K12: 10 | L12: 11 | M12: 12 | P12: 0.25 | Q12: =AVERAGE(B18:C18) -> 0.8405 | R12: =Q12-Q$9 -> 0.46 | U12: CE | V12: 0.581 | W12: =V12-Q$3 -> 0.176 | X12: =(W12-0.0463)/1.7857 -> 0.072632581 | Y12: =7*X12 -> 0.50842807
A13: A | B13: 0.379 | C13: 0.382 | E13: 0.575 | F13: 0.583 | G13: 0.582 | H13: 0.528 | I13: 0.579 | J13: 0.672 | K13: 0.634 | L13: 0.527 | M13: 0.551 | P13: 0.5 | Q13: =AVERAGE(B20:C20) -> 1.3035 | R13: =Q13-Q$9 -> 0.923 | U13: CF | V13: 0.587 | W13: =V13-Q$3 -> 0.182 | X13: =(W13-0.0463)/1.7857 -> 0.075992608 | Y13: =7*X13 -> 0.53194826
A14: B | B14: 0.526 | C14: 0.526 | O14: 3 | U14: CG | V14: 0.639 | W14: =V14-Q$3 -> 0.234 | X14: =(W14-0.0463)/1.7857 -> 0.10511284 | Y14: =7*X14 -> 0.73578989
A15: C | E15: 0.592 | F15: 0.824 | G15: 0.31 | H15: 0.598 | P15: 0 | Q15: =AVERAGE(B23:C23) -> 0.3755 | R15: =Q15-Q$15 -> 0 | U15: CH | V15: 0.613 | W15: =V15-Q$3 -> 0.208 | X15: =(W15-0.0463)/1.7857 -> 0.090552724 | Y15: =7*X15 -> 0.63386907
A16: D | B16: 0.65 | C16: 0.638 | G16: 0.575 | P16: 0.05 | Q16: =AVERAGE(B24:C24) -> 0.5255 | R16: =Q16-Q$15 -> 0.15 | T16: 2 | U16: Sample ID | V16: Absorbance | W16: Corrected Absorbance | X16: Concentration (mg/mL) | Y16: Concentration (mg/g DW)
A17: E | P17: 0.1 | Q17: =AVERAGE(B26:C26) -> 0.641 | R17: =Q17-Q$15 -> 0.2655 | U17: BV | V17: 0.575 | W17: =V17-Q$9 -> 0.1945 | X17: =(W17-0.0408)/1.7642 -> 0.087121642 | Y17: =7*X17 -> 0.60985149
A18: F | B18: 0.866 | C18: 0.815 | P18: 0.25 | Q18: =AVERAGE(B28:C28) -> 0.845 | R18: =Q18-Q$15 -> 0.4695 | U18: BW | V18: 0.583 | W18: =V18-Q$9 -> 0.2025 | X18: =(W18-0.0408)/1.7642 -> 0.091656275 | Y18: =7*X18 -> 0.64159392
A19: G | P19: 0.5 | Q19: =AVERAGE(B30:C30) -> 1.2635 | R19: =Q19-Q$15 -> 0.888 | U19: BX | V19: 0.582 | W19: =V19-Q$9 -> 0.2015 | X19: =(W19-0.0408)/1.7642 -> 0.091089446 | Y19: =7*X19 -> 0.63762612
A20: H | B20: 1.32 | C20: 1.287 | O20: 4 | U20: BY | V20: 0.528 | W20: =V20-Q$9 -> 0.1475 | X20: =(W20-0.0408)/1.7642 -> 0.060480671 | Y20: =7*X20 -> 0.4233647
A21: 3 | P21: 0 | Q21: =AVERAGE(B33:C33) -> 0.3685 | R21: =Q21-Q$21 -> 0 | U21: BZ | V21: 0.579 | W21: =V21-Q$9 -> 0.1985 | X21: =(W21-0.0408)/1.7642 -> 0.089388958 | Y21: =7*X21 -> 0.62572271
B22: 1 | C22: 2 | D22: 3 | E22: 4 | F22: 5 | G22: 6 | H22: 7 | I22: 8 | J22: 9 | K22: 10 | L22: 11 | M22: 12 | P22: 0.05 | Q22: =AVERAGE(B34:C34) -> 0.506 | R22: =Q22-Q$21 -> 0.1375 | U22: CA | V22: 0.672 | W22: =V22-Q$9 -> 0.2915 | X22: =(W22-0.0408)/1.7642 -> 0.14210407 | Y22: =7*X22 -> 0.99472849
A23: A | B23: 0.37 | C23: 0.381 | E23: 0.593 | F23: 0.514 | G23: 0.557 | H23: 0.516 | I23: 0.572 | J23: 0.608 | K23: 0.602 | L23: 0.527 | M23: 0.54 | P23: 0.1 | Q23: =AVERAGE(B36:C36) -> 0.628 | R23: =Q23-Q$21 -> 0.2595 | U23: CB | V23: 0.634 | W23: =V23-Q$9 -> 0.2535 | X23: =(W23-0.0408)/1.7642 -> 0.12056456 | Y23: =7*X23 -> 0.84395193
A24: B | B24: 0.523 | C24: 0.528 | P24: 0.25 | Q24: =AVERAGE(B38:C38) -> 0.9005 | R24: =Q24-Q$21 -> 0.532 | U24: CC | V24: 0.527 | W24: =V24-Q$9 -> 0.1465 | X24: =(W24-0.0408)/1.7642 -> 0.059913842 | Y24: =7*X24 -> 0.41939689
A25: C | E25: 0.549 | F25: 0.564 | G25: 0.599 | H25: 0.59 | P25: 0.5 | Q25: =AVERAGE(B40:C40) -> 1.276 | R25: =Q25-Q$21 -> 0.9075 | U25: CD | V25: 0.551 | W25: =V25-Q$9 -> 0.1705 | X25: =(W25-0.0408)/1.7642 -> 0.073517742 | Y25: =7*X25 -> 0.51462419
A26: D | B26: 0.656 | C26: 0.626 | G26: 0.045 | O26: 5 | U26: CE | V26: 0.592 | W26: =V26-Q$9 -> 0.2115 | X26: =(W26-0.0408)/1.7642 -> 0.096757737 | Y26: =7*X26 -> 0.67730416
A27: E | P27: 0 | Q27: =AVERAGE(B43:C43) -> 0.3375 | R27: =Q27-Q$27 -> 0 | U27: CF | V27: 0.824 | W27: =V27-Q$9 -> 0.4435 | X27: =(W27-0.0408)/1.7642 -> 0.2282621 | Y27: =7*X27 -> 1.5978347
A28: F | B28: 0.822 | C28: 0.868 | P28: 0.05 | Q28: =AVERAGE(B44:C44) -> 0.494 | R28: =Q28-Q$27 -> 0.1565 | U28: CG | V28: 0.575 | W28: =V28-Q$9 -> 0.1945 | X28: =(W28-0.0408)/1.7642 -> 0.087121642 | Y28: =7*X28 -> 0.60985149
A29: G | P29: 0.1 | Q29: =AVERAGE(B46:C46) -> 0.5995 | R29: =Q29-Q$27 -> 0.262 | U29: CH | V29: 0.598 | W29: =V29-Q$9 -> 0.2175 | X29: =(W29-0.0408)/1.7642 -> 0.10015871 | Y29: =7*X29 -> 0.70111099
A30: H | B30: 1.3 | C30: 1.227 | P30: 0.25 | Q30: =AVERAGE(B48:C48) -> 0.863 | R30: =Q30-Q$27 -> 0.5255 | T30: 3 | U30: Sample ID | V30: Absorbance | W30: Corrected Absorbance | X30: Concentration (mg/mL) | Y30: Concentration (mg/g DW)
P31: 0.5 | Q31: =AVERAGE(B50:C50) -> 1.1935 | R31: =Q31-Q$27 -> 0.856 | U31: BV | V31: 0.593 | W31: =V31-Q$15 -> 0.2175 | X31: =(W31-0.0495)/1.695 -> 0.099115044 | Y31: =7*X31 -> 0.69380531
B32: 1 | C32: 2 | D32: 3 | E32: 4 | F32: 5 | G32: 6 | H32: 7 | I32: 8 | J32: 9 | K32: 10 | L32: 11 | M32: 12 | O32: 6 | U32: BW | V32: 0.514 | W32: =V32-Q$15 -> 0.1385 | X32: =(W32-0.0495)/1.695 -> 0.052507375 | Y32: =7*X32 -> 0.36755162
A33: A | B33: 0.366 | C33: 0.371 | P33: 0 | Q33: =AVERAGE(B53:C53) -> 0.361 | R33: =Q33-Q$33 -> 0 | U33: BX | V33: 0.557 | W33: =V33-Q$15 -> 0.1815 | X33: =(W33-0.0495)/1.695 -> 0.077876106 | Y33: =7*X33 -> 0.54513274
A34: B | B34: 0.502 | C34: 0.51 | P34: 0.05 | Q34: =AVERAGE(B54:C54) -> 0.516 | R34: =Q34-Q$33 -> 0.155 | U34: BY | V34: 0.516 | W34: =V34-Q$15 -> 0.1405 | X34: =(W34-0.0495)/1.695 -> 0.053687316 | Y34: =7*X34 -> 0.37581121
A35: C | P35: 0.1 | Q35: =AVERAGE(B56:C56) -> 0.6295 | R35: =Q35-Q$33 -> 0.2685 | U35: BZ | V35: 0.572 | W35: =V35-Q$15 -> 0.1965 | X35: =(W35-0.0495)/1.695 -> 0.086725664 | Y35: =7*X35 -> 0.60707965
A36: D | B36: 0.633 | C36: 0.623 | J36: 0.615 | K36: 0.651 | L36: 0.637 | P36: 0.25 | Q36: =AVERAGE(B58:C58) -> 0.898 | R36: =Q36-Q$33 -> 0.537 | U36: CA | V36: 0.608 | W36: =V36-Q$15 -> 0.2325 | X36: =(W36-0.0495)/1.695 -> 0.1079646 | Y36: =7*X36 -> 0.75575221
A37: E | E37: 0.569 | F37: 0.61 | G37: 0.691 | H37: 0.704 | I37: 0.598 | J37: 0.584 | K37: 0.594 | L37: 0.604 | P37: 0.5 | Q37: =AVERAGE(B60:C60) -> 1.213 | R37: =Q37-Q$33 -> 0.852 | U37: CB | V37: 0.602 | W37: =V37-Q$15 -> 0.2265 | X37: =(W37-0.0495)/1.695 -> 0.10442478 | Y37: =7*X37 -> 0.73097345
A38: F | B38: 0.902 | C38: 0.899 | E38: 0.638 | F38: 0.634 | U38: CC | V38: 0.527 | W38: =V38-Q$15 -> 0.1515 | X38: =(W38-0.0495)/1.695 -> 0.060176991 | Y38: =7*X38 -> 0.42123894
A39: G | U39: CD | V39: 0.54 | W39: =V39-Q$15 -> 0.1645 | X39: =(W39-0.0495)/1.695 -> 0.067846608 | Y39: =7*X39 -> 0.47492625
A40: H | B40: 1.258 | C40: 1.294 | U40: CE | V40: 0.549 | W40: =V40-Q$15 -> 0.1735 | X40: =(W40-0.0495)/1.695 -> 0.073156342 | Y40: =7*X40 -> 0.5120944
...

Sheet JNR
A1: 1 | P1: STANDARD CURVES | U1: SAMPLES
B2: 1 | C2: 2 | D2: 3 | E2: 4 | F2: 5 | G2: 6 | H2: 7 | I2: 8 | J2: 9 | K2: 10 | L2: 11 | M2: 12 | O2: 1 | Q2: AVG Absorbance | R2: Corrected AVG | T2: 1 | U2: Sample ID | V2: Absorbance | W2: Corrected Absorbance | X2: Concentration (mg/mL) | Y2: Concentration (mg/g DW)
A3: A | B3: 0.376 | C3: 0.359 | E3: 0.524 | F3: 0.532 | G3: 0.534 | H3: 0.565 | I3: 0.528 | J3: 0.556 | K3: 0.591 | L3: 0.589 | M3: 0.637 | P3: 0 | Q3: =AVERAGE(B3:C3) -> 0.3675 | R3: =Q3-Q$3 -> 0 | U3: CI | V3: 0.524 | W3: =V3-Q$3 -> 0.1565 | X3: =(W3-0.0426)/1.9007 -> 0.059925291 | Y3: =X3*7 -> 0.41947703
A4: B | P4: 0.05 | Q4: =AVERAGE(E9:E10) -> 0.434 | R4: =Q4-Q$3 -> 0.0665 | U4: CJ | V4: 0.532 | W4: =V4-Q$3 -> 0.1645 | X4: =(W4-0.0426)/1.9007 -> 0.064134266 | Y4: =X4*7 -> 0.44893986
A5: C | E5: 0.56 | F5: 0.588 | G5: 0.651 | H5: 0.546 | I5: 0.573 | K5: 0.667 | L5: 0.758 | M5: 0.672 | P5: 0.1 | Q5: =AVERAGE(F9:F10) -> 0.711 | R5: =Q5-Q$3 -> 0.3435 | U5: CK | V5: 0.534 | W5: =V5-Q$3 -> 0.1665 | X5: =(W5-0.0426)/1.9007 -> 0.06518651 | Y5: =X5*7 -> 0.45630557
A6: D | P6: 0.25 | Q6: =AVERAGE(G9:G10) -> 0.921 | R6: =Q6-Q$3 -> 0.5535 | U6: CL | V6: 0.565 | W6: =V6-Q$3 -> 0.1975 | X6: =(W6-0.0426)/1.9007 -> 0.081496291 | Y6: =X6*7 -> 0.57047404
A7: E | P7: 0.5 | Q7: =AVERAGE(H9:H10) -> 1.3275 | R7: =Q7-Q$3 -> 0.96 | U7: CM | V7: 0.528 | W7: =V7-Q$3 -> 0.1605 | X7: =(W7-0.0426)/1.9007 -> 0.062029779 | Y7: =X7*7 -> 0.43420845
A8: F | O8: 3 | U8: CN | V8: 0.556 | W8: =V8-Q$3 -> 0.1885 | X8: =(W8-0.0426)/1.9007 -> 0.076761193 | Y8: =X8*7 -> 0.53732835
A9: G | E9: 0.501 | F9: 0.721 | G9: 0.934 | H9: 1.356 | P9: 0 | Q9: =AVERAGE(B13:C13) -> 0.3615 | R9: =Q9-Q$9 -> 0 | U9: CO | V9: 0.591 | W9: =V9-Q$3 -> 0.2235 | X9: =(W9-0.0426)/1.9007 -> 0.095175462 | Y9: =X9*7 -> 0.66622823
A10: H | E10: 0.367 | F10: 0.701 | G10: 0.908 | H10: 1.299 | P10: 0.05 | Q10: =AVERAGE(E19:E20) -> 0.5925 | R10: =Q10-Q$9 -> 0.231 | U10: CP | V10: 0.589 | W10: =V10-Q$3 -> 0.2215 | X10: =(W10-0.0426)/1.9007 -> 0.094123218 | Y10: =X10*7 -> 0.65886252
A11: 3 | P11: 0.1 | Q11: =AVERAGE(F19:F20) -> 0.719 | R11: =Q11-Q$9 -> 0.3575 | U11: CQ | V11: 0.637 | W11: =V11-Q$3 -> 0.2695 | X11: =(W11-0.0426)/1.9007 -> 0.11937707 | Y11: =X11*7 -> 0.8356395
B12: 1 | C12: 2 | D12: 3 | E12: 4 | F12: 5 | G12: 6 | H12: 7 | I12: 8 | J12: 9 | K12: 10 | L12: 11 | M12: 12 | P12: 0.25 | Q12: =AVERAGE(G19:G20) -> 0.949 | R12: =Q12-Q$9 -> 0.5875 | U12: CR | V12: 0.56 | W12: =V12-Q$3 -> 0.1925 | X12: =(W12-0.0426)/1.9007 -> 0.078865681 | Y12: =X12*7 -> 0.55205977
A13: A | B13: 0.364 | C13: 0.359 | E13: 0.526 | F13: 0.523 | G13: 0.503 | H13: 0.551 | I13: 0.487 | J13: 0.514 | K13: 0.608 | L13: 0.559 | M13: 0.637 | P13: 0.5 | Q13: =AVERAGE(H19:H20) -> 1.296 | R13: =Q13-Q$9 -> 0.9345 | U13: CS | V13: 0.588 | W13: =V13-Q$3 -> 0.2205 | X13: =(W13-0.0426)/1.9007 -> 0.093597096 | Y13: =X13*7 -> 0.65517967
A14: B | O14: 4 | U14: CT | V14: 0.651 | W14: =V14-Q$3 -> 0.2835 | X14: =(W14-0.0426)/1.9007 -> 0.12674278 | Y14: =X14*7 -> 0.88719945
A15: C | E15: 0.554 | F15: 0.584 | G15: 0.639 | H15: 0.545 | I15: 0.555 | K15: 0.643 | L15: 0.783 | M15: 0.69 | P15: 0 | Q15: =AVERAGE(B23:C23) -> 0.38 | R15: =Q15-Q$15 -> 0 | T15: 3 | U15: Sample ID | V15: Absorbance | W15: Corrected Absorbance | X15: Concentration (mg/mL) | Y15: Concentration (mg/g DW)
A16: D | P16: 0.05 | Q16: =AVERAGE(B24:C24) -> 0.539 | R16: =Q16-Q$15 -> 0.159 | U16: CI | V16: 0.526 | W16: =V16-Q$9 -> 0.1645 | X16: =(W16-0.1112)/1.7272 -> 0.030859194 | Y16: =X16*7 -> 0.21601436
A17: E | P17: 0.1 | Q17: =AVERAGE(B26:C26) -> 0.6405 | R17: =Q17-Q$15 -> 0.2605 | U17: CJ | V17: 0.523 | W17: =V17-Q$9 -> 0.1615 | X17: =(W17-0.1112)/1.7272 -> 0.029122279 | Y17: =X17*7 -> 0.20385595
A18: F | P18: 0.25 | Q18: =AVERAGE(B28:C28) -> 0.8665 | R18: =Q18-Q$15 -> 0.4865 | U18: CK | V18: 0.503 | W18: =V18-Q$9 -> 0.1415 | X18: =(W18-0.1112)/1.7272 -> 0.017542844 | Y18: =X18*7 -> 0.12279991
A19: G | E19: 0.599 | F19: 0.713 | G19: 0.931 | H19: 1.294 | P19: 0.5 | Q19: =AVERAGE(B30:C30) -> 1.3145 | R19: =Q19-Q$15 -> 0.9345 | U19: CL | V19: 0.551 | W19: =V19-Q$9 -> 0.1895 | X19: =(W19-0.1112)/1.7272 -> 0.045333488 | Y19: =X19*7 -> 0.31733441
A20: H | E20: 0.586 | F20: 0.725 | G20: 0.967 | H20: 1.298 | O20: 5 | U20: CM | V20: 0.487 | W20: =V20-Q$9 -> 0.1255 | X20: =(W20-0.1112)/1.7272 -> 0.008279296 | Y20: =X20*7 -> 0.057955072
A21: 4 | B21: (ALL ANNOTATIONS HERE APPLY TO 5 AND 6) | P21: 0 | Q21: =AVERAGE(B33:C33) -> 0.38 | R21: =Q21-Q$21 -> 0 | U21: CN | V21: 0.514 | W21: =V21-Q$9 -> 0.1525 | X21: =(W21-0.1112)/1.7272 -> 0.023911533 | Y21: =X21*7 -> 0.16738073
B22: 1 | C22: 2 | D22: 3 | E22: 4 | F22: 5 | G22: 6 | H22: 7 | I22: 8 | J22: 9 | K22: 10 | L22: 11 | M22: 12 | P22: 0.05 | Q22: =AVERAGE(B34:C34) -> 0.5615 | R22: =Q22-Q$21 -> 0.1815 | U22: CO | V22: 0.608 | W22: =V22-Q$9 -> 0.2465 | X22: =(W22-0.1112)/1.7272 -> 0.078334877 | Y22: =X22*7 -> 0.54834414
