Workbook

Sheet Aggregated Wavelength Data
A2: Row Labels | B2: Count of Wavelength (nm) | C2: Associated Chemical (Curran, 1989)
A3: 2160.0002 | B3: 11 | C3: Protein, nitrogen (N-H bend, 2nd overtone/C-H stretch/C-O stretch/C=O stretch/C-N stretch)
A4: Interpretation | B4: 4
A5: Prediction | B5: 2
A6: VarImp | B6: 5
A7: 2141.108 | B7: 11 | C7: Protein (N-H stretch)
A8: Interpretation | B8: 4
A9: Prediction | B9: 2
A10: VarImp | B10: 5
A11: 2166.3718 | B11: 10 | C11: Protein, nitrogen (N-H bend, 2nd overtone/C-H stretch/C-O stretch/C=O stretch/C-N stretch)
A12: Interpretation | B12: 4
A13: Prediction | B13: 2
A14: VarImp | B14: 4
A15: 2153.6658 | B15: 10 | C15: Protein, nitrogen (N-H bend, 2nd overtone/C-H stretch/C-O stretch/C=O stretch/C-N stretch)
A16: Interpretation | B16: 4
A17: Prediction | B17: 1
A18: VarImp | B18: 5
A19: 2134.8839 | B19: 9 | C19: Protein (N-H stretch)
A20: Interpretation | B20: 3
A21: Prediction | B21: 2
A22: VarImp | B22: 4
A23: 2361.4149 | B23: 9 | C23: Cellulose, protein, nitrogen (CH2 bend, 2nd overtone, C-H deformation, 2nd overtone)
A24: Interpretation | B24: 3
A25: Prediction | B25: 3
A26: VarImp | B26: 3
A27: 2172.7812 | B27: 8 | C27: Protein, nitrogen (N-H bend, 2nd overtone/C-H stretch/C-O stretch/C=O stretch/C-N stretch)
A28: Interpretation | B28: 3
A29: Prediction | B29: 2
A30: VarImp | B30: 3
A31: 2400.0001 | B31: 8
A32: Interpretation | B32: 3
A33: Prediction | B33: 2
A34: VarImp | B34: 3
A35: 2369.0323 | B35: 8 | C35: Cellulose, protein, nitrogen (CH2 bend, 2nd overtone, C-H deformation, 2nd overtone)
A36: Interpretation | B36: 3
A37: Prediction | B37: 2
A38: VarImp | B38: 3
A39: 2147.3686 | B39: 8 | C39: Protein (N-H stretch)
A40: Interpretation | B40: 4
A41: VarImp | B41: 4
...

Sheet Monthly Analyses SVM
A1: June 2024 Wavelengths of Importance | D1: August 2024 Wavelengths of Importance
A2: Wavelength (nm) | B2: Average Importance (x97) | C2: Count of Wavelength (nm) | D2: Wavelength (nm) | E2: Average Importance (x97) | F2: Count of Wavelength (nm)
A3: 2400.0001 | B3: 68 | C3: 3 | D3: 2179.2286 | E3: 76.43 | F3: 2
A4: 2160.0002 | B4: 82.726667 | C4: 3 | D4: 2153.6658 | E4: 73.435 | F4: 2
A5: 2141.108 | B5: 76.39 | C5: 3 | D5: 2141.108 | E5: 67.635 | F5: 2
A6: 2153.6658 | B6: 85.353333 | C6: 3 | D6: 1632.0003 | E6: 61.595 | F6: 2
A7: 2376.6991 | B7: 70.97 | C7: 2 | D7: 2166.3718 | E7: 83.875 | F7: 2
A8: 2415.7895 | B8: 69.305 | C8: 2 | D8: 1661.5388 | E8: 65.22 | F8: 2
A9: 2128.6958 | B9: 70.705 | C9: 2 | D9: 2353.8462 | E9: 90.165 | F9: 2
A10: 1661.5388 | B10: 72.09 | C10: 2 | D10: 1669.0912 | E10: 74.835 | F10: 2
A11: 2295.0001 | B11: 72.905 | C11: 2 | D11: 2147.3686 | E11: 68.035 | F11: 2
A12: 2147.3686 | B12: 73.9 | C12: 2 | D12: 1696.0742 | E12: 88.41 | F12: 2
A13: 2384.4156 | B13: 78.605 | C13: 2 | D13: 2160.0002 | E13: 84.27 | F13: 2
A14: 2423.7624 | B14: 51.815 | C14: 2 | D14: 1700.0003 | E14: 74.03 | F14: 2
... A61: 2068.7326 | B61: 27.35 | C61: 1 | D61: 2384.4156 | E61: 57.03 | F61: 1
A62: Grand Total | B62: 67.925875 | C62: 80 | D62: 1958.4002 | E62: 77.47 | F62: 1
D63: 1409.5972 | E63: 79.74 | F63: 1
D64: 1963.6366 | E64: 83.6 | F64: 1
D65: Grand Total | E65: 64.056375 | F65: 80

Sheet Class Analyses SVM
A1: 3-Class Wavelengths of Importance | D1: 2-Class Wavelengths of Importance
A2: Wavelength (nm) | B2: Average Importance (x97) | C2: Frequency | D2: Wavelength (nm) | E2: Average Importance (x97) | F2: Frequency
A3: 2384.4156 | B3: 70.44 | C3: 2 | D3: 2153.6658 | E3: 85.8 | F3: 3
A4: 2309.4341 | B4: 38.16 | C4: 2 | D4: 2141.108 | E4: 69.426667 | F4: 3
A5: 2295.0001 | B5: 54.315 | C5: 2 | D5: 2160.0002 | E5: 87.37 | F5: 3
A6: 1661.5388 | B6: 67.5 | C6: 2 | D6: 2400.0001 | E6: 77.055 | F6: 2
A7: 2369.0323 | B7: 74.82 | C7: 2 | D7: 2147.3686 | E7: 74.045 | F7: 2
A8: 1822.3328 | B8: 42.375 | C8: 2 | D8: 1471.7438 | E8: 70.45 | F8: 2
A9: 2166.3718 | B9: 62.74 | C9: 2 | D9: 1468.8003 | E9: 65.14 | F9: 2
A10: 2134.8839 | B10: 82.885 | C10: 2 | D10: 1661.5388 | E10: 69.81 | F10: 2
A11: 2302.1945 | B11: 21.575 | C11: 2 | D11: 2166.3718 | E11: 81.67 | F11: 2
A12: 2141.108 | B12: 78.08 | C12: 2 | D12: 1669.0912 | E12: 71.31 | F12: 2
A13: 2361.4149 | B13: 83.425 | C13: 2 | D13: 2172.7812 | E13: 80.995 | F13: 2
A14: 2147.3686 | B14: 67.89 | C14: 2 | D14: 2122.5435 | E14: 70.715 | F14: 2
... A64: 2068.7326 | B64: 27.35 | C64: 1 | D64: 1428.7941 | E64: 68.14 | F64: 1
A65: 1360.0003 | B65: 91.04 | C65: 1 | D65: Grand Total | E65: 72.749125 | F65: 80
A66: 2122.5435 | B66: 65.84 | C66: 1
A67: Grand Total | B67: 59.233125 | C67: 80

Sheet 2 Class Aggregate Wavelengths
A1: Method | B1: Run | C1: Tissue | D1: Class | E1: Wavelength | F1: Column Number | H1: Row Labels | I1: Count of Wavelength
A2: Interpretation | B2: P_0624R22C | C2: {=_xlfn.IFS(ISNUMBER(FIND("N",B2)),"Needles",ISNUMBER(FIND("P",B2)),"Phloem")} -> Phloem | D2: 2 | E2: 2134.8839 | F2: 60 | H2: 2160.0002 | I2: 7
A3: Interpretation | B3: P_0624R22C | C3: {=_xlfn.IFS(ISNUMBER(FIND("N",B3)),"Needles",ISNUMBER(FIND("P",B3)),"Phloem")} -> Phloem | D3: 2 | E3: 2153.6658 | F3: 57 | H3: Needles | I3: 3
A4: Interpretation | B4: P_0624R22C | C4: {=_xlfn.IFS(ISNUMBER(FIND("N",B4)),"Needles",ISNUMBER(FIND("P",B4)),"Phloem")} -> Phloem | D4: 2 | E4: 2128.6958 | F4: 61 | H4: Phloem | I4: 4
A5: Interpretation | B5: P_0624R22C | C5: {=_xlfn.IFS(ISNUMBER(FIND("N",B5)),"Needles",ISNUMBER(FIND("P",B5)),"Phloem")} -> Phloem | D5: 2 | E5: 2141.108 | F5: 59 | H5: 2153.6658 | I5: 6
A6: Interpretation | B6: P_0624R22C | C6: {=_xlfn.IFS(ISNUMBER(FIND("N",B6)),"Needles",ISNUMBER(FIND("P",B6)),"Phloem")} -> Phloem | D6: 2 | E6: 2160.0002 | F6: 56 | H6: Needles | I6: 2
A7: Interpretation | B7: P_0624R22C | C7: {=_xlfn.IFS(ISNUMBER(FIND("N",B7)),"Needles",ISNUMBER(FIND("P",B7)),"Phloem")} -> Phloem | D7: 2 | E7: 2147.3686 | F7: 58 | H7: Phloem | I7: 4
A8: Interpretation | B8: P_0624R22C | C8: {=_xlfn.IFS(ISNUMBER(FIND("N",B8)),"Needles",ISNUMBER(FIND("P",B8)),"Phloem")} -> Phloem | D8: 2 | E8: 2122.5435 | F8: 62 | H8: 2400.0001 | I8: 6
A9: Interpretation | B9: P_0624R22C | C9: {=_xlfn.IFS(ISNUMBER(FIND("N",B9)),"Needles",ISNUMBER(FIND("P",B9)),"Phloem")} -> Phloem | D9: 2 | E9: 2166.3718 | F9: 55 | H9: Needles | I9: 3
A10: Interpretation | B10: P_0624R22C | C10: {=_xlfn.IFS(ISNUMBER(FIND("N",B10)),"Needles",ISNUMBER(FIND("P",B10)),"Phloem")} -> Phloem | D10: 2 | E10: 2407.8689 | F10: 21 | H10: Phloem | I10: 3
A11: Interpretation | B11: P_0624R22C | C11: {=_xlfn.IFS(ISNUMBER(FIND("N",B11)),"Needles",ISNUMBER(FIND("P",B11)),"Phloem")} -> Phloem | D11: 2 | E11: 2116.4267 | F11: 63 | H11: 2141.108 | I11: 6
A12: Interpretation | B12: P_0624R22C | C12: {=_xlfn.IFS(ISNUMBER(FIND("N",B12)),"Needles",ISNUMBER(FIND("P",B12)),"Phloem")} -> Phloem | D12: 2 | E12: 2415.7895 | F12: 20 | H12: Needles | I12: 2
A13: Interpretation | B13: P_0624R22C | C13: {=_xlfn.IFS(ISNUMBER(FIND("N",B13)),"Needles",ISNUMBER(FIND("P",B13)),"Phloem")} -> Phloem | D13: 2 | E13: 2400.0001 | F13: 22 | H13: Phloem | I13: 4
A14: Interpretation | B14: P_0624R22C | C14: {=_xlfn.IFS(ISNUMBER(FIND("N",B14)),"Needles",ISNUMBER(FIND("P",B14)),"Phloem")} -> Phloem | D14: 2 | E14: 1420.5032 | F14: 233 | H14: 2172.7812 | I14: 5
A15: Interpretation | B15: P_0624R22C | C15: {=_xlfn.IFS(ISNUMBER(FIND("N",B15)),"Needles",ISNUMBER(FIND("P",B15)),"Phloem")} -> Phloem | D15: 2 | E15: 2205.4055 | F15: 49 | H15: Needles | I15: 2
A16: Interpretation | B16: P_0624R22C | C16: {=_xlfn.IFS(ISNUMBER(FIND("N",B16)),"Needles",ISNUMBER(FIND("P",B16)),"Phloem")} -> Phloem | D16: 2 | E16: 2028.7295 | F16: 78 | H16: Phloem | I16: 3
A17: Interpretation | B17: P_0624R22C | C17: {=_xlfn.IFS(ISNUMBER(FIND("N",B17)),"Needles",ISNUMBER(FIND("P",B17)),"Phloem")} -> Phloem | D17: 2 | E17: 1462.9485 | F17: 218 | H17: 2166.3718 | I17: 5
A18: Interpretation | B18: P_0624R22C | C18: {=_xlfn.IFS(ISNUMBER(FIND("N",B18)),"Needles",ISNUMBER(FIND("P",B18)),"Phloem")} -> Phloem | D18: 2 | E18: 1719.9066 | F18: 143 | H18: Needles | I18: 2
A19: Interpretation | B19: P_0824R22C | C19: {=_xlfn.IFS(ISNUMBER(FIND("N",B19)),"Needles",ISNUMBER(FIND("P",B19)),"Phloem")} -> Phloem | D19: 2 | E19: 2172.7812 | F19: 54 | H19: Phloem | I19: 3
A20: Prediction | B20: P_0624R22C | C20: {=_xlfn.IFS(ISNUMBER(FIND("N",B20)),"Needles",ISNUMBER(FIND("P",B20)),"Phloem")} -> Phloem | D20: {=_xlfn.IFS(ISNUMBER(FIND("R13C",B20)),3,ISNUMBER(FIND("R22C",B20)),2)} -> 2 | E20: =VLOOKUP(F20,ColRef!$A$2:$B$258,2,FALSE) -> 2134.8839 | F20: 60 | H20: 2134.8839 | I20: 4
A21: Prediction | B21: P_0624R22C | C21: {=_xlfn.IFS(ISNUMBER(FIND("N",B21)),"Needles",ISNUMBER(FIND("P",B21)),"Phloem")} -> Phloem | D21: {=_xlfn.IFS(ISNUMBER(FIND("R13C",B21)),3,ISNUMBER(FIND("R22C",B21)),2)} -> 2 | E21: =VLOOKUP(F21,ColRef!$A$2:$B$258,2,FALSE) -> 2153.6658 | F21: 57 | H21: Phloem | I21: 4
A22: Prediction | B22: P_0624R22C | C22: {=_xlfn.IFS(ISNUMBER(FIND("N",B22)),"Needles",ISNUMBER(FIND("P",B22)),"Phloem")} -> Phloem | D22: {=_xlfn.IFS(ISNUMBER(FIND("R13C",B22)),3,ISNUMBER(FIND("R22C",B22)),2)} -> 2 | E22: =VLOOKUP(F22,ColRef!$A$2:$B$258,2,FALSE) -> 2141.108 | F22: 59 | H22: 2407.8689 | I22: 4
A23: Prediction | B23: P_0624R22C | C23: {=_xlfn.IFS(ISNUMBER(FIND("N",B23)),"Needles",ISNUMBER(FIND("P",B23)),"Phloem")} -> Phloem | D23: {=_xlfn.IFS(ISNUMBER(FIND("R13C",B23)),3,ISNUMBER(FIND("R22C",B23)),2)} -> 2 | E23: =VLOOKUP(F23,ColRef!$A$2:$B$258,2,FALSE) -> 2160.0002 | F23: 56 | H23: Needles | I23: 2
A24: Prediction | B24: P_0624R22C | C24: {=_xlfn.IFS(ISNUMBER(FIND("N",B24)),"Needles",ISNUMBER(FIND("P",B24)),"Phloem")} -> Phloem | D24: {=_xlfn.IFS(ISNUMBER(FIND("R13C",B24)),3,ISNUMBER(FIND("R22C",B24)),2)} -> 2 | E24: =VLOOKUP(F24,ColRef!$A$2:$B$258,2,FALSE) -> 2166.3718 | F24: 55 | H24: Phloem | I24: 2
A25: Prediction | B25: P_0624R22C | C25: {=_xlfn.IFS(ISNUMBER(FIND("N",B25)),"Needles",ISNUMBER(FIND("P",B25)),"Phloem")} -> Phloem | D25: {=_xlfn.IFS(ISNUMBER(FIND("R13C",B25)),3,ISNUMBER(FIND("R22C",B25)),2)} -> 2 | E25: =VLOOKUP(F25,ColRef!$A$2:$B$258,2,FALSE) -> 2400.0001 | F25: 22 | H25: 1471.7438 | I25: 4
A26: Prediction | B26: P_0624R22C | C26: {=_xlfn.IFS(ISNUMBER(FIND("N",B26)),"Needles",ISNUMBER(FIND("P",B26)),"Phloem")} -> Phloem | D26: {=_xlfn.IFS(ISNUMBER(FIND("R13C",B26)),3,ISNUMBER(FIND("R22C",B26)),2)} -> 2 | E26: =VLOOKUP(F26,ColRef!$A$2:$B$258,2,FALSE) -> 1420.5032 | F26: 233 | H26: Needles | I26: 4
A27: Prediction | B27: P_0624R22C | C27: {=_xlfn.IFS(ISNUMBER(FIND("N",B27)),"Needles",ISNUMBER(FIND("P",B27)),"Phloem")} -> Phloem | D27: {=_xlfn.IFS(ISNUMBER(FIND("R13C",B27)),3,ISNUMBER(FIND("R22C",B27)),2)} -> 2 | E27: =VLOOKUP(F27,ColRef!$A$2:$B$258,2,FALSE) -> 1462.9485 | F27: 218 | H27: 1661.5388 | I27: 4
A28: Prediction | B28: P_0824R22C | C28: {=_xlfn.IFS(ISNUMBER(FIND("N",B28)),"Needles",ISNUMBER(FIND("P",B28)),"Phloem")} -> Phloem | D28: {=_xlfn.IFS(ISNUMBER(FIND("R13C",B28)),3,ISNUMBER(FIND("R22C",B28)),2)} -> 2 | E28: =VLOOKUP(F28,ColRef!$A$2:$B$258,2,FALSE) -> 2172.7812 | F28: 54 | H28: Needles | I28: 3
A29: VarImp | B29: P_0624R22C | C29: {=_xlfn.IFS(ISNUMBER(FIND("N",B29)),"Needles",ISNUMBER(FIND("P",B29)),"Phloem")} -> Phloem | D29: 2 | E29: 2160.0002 | F29: 56 | H29: Phloem | I29: 1
A30: VarImp | B30: P_0624R22C | C30: {=_xlfn.IFS(ISNUMBER(FIND("N",B30)),"Needles",ISNUMBER(FIND("P",B30)),"Phloem")} -> Phloem | D30: 2 | E30: 2147.3686 | F30: 58 | H30: 2147.3686 | I30: 4
A31: VarImp | B31: P_0624R22C | C31: {=_xlfn.IFS(ISNUMBER(FIND("N",B31)),"Needles",ISNUMBER(FIND("P",B31)),"Phloem")} -> Phloem | D31: 2 | E31: 2153.6658 | F31: 57 | H31: Needles | I31: 1
A32: VarImp | B32: P_0624R22C | C32: {=_xlfn.IFS(ISNUMBER(FIND("N",B32)),"Needles",ISNUMBER(FIND("P",B32)),"Phloem")} -> Phloem | D32: 2 | E32: 2141.108 | F32: 59 | H32: Phloem | I32: 3
A33: VarImp | B33: P_0624R22C | C33: {=_xlfn.IFS(ISNUMBER(FIND("N",B33)),"Needles",ISNUMBER(FIND("P",B33)),"Phloem")} -> Phloem | D33: 2 | E33: 2128.6958 | F33: 61 | H33: 2001.0901 | I33: 4
A34: VarImp | B34: P_0624R22C | C34: {=_xlfn.IFS(ISNUMBER(FIND("N",B34)),"Needles",ISNUMBER(FIND("P",B34)),"Phloem")} -> Phloem | D34: 2 | E34: 2122.5435 | F34: 62 | H34: Needles | I34: 4
A35: VarImp | B35: P_0624R22C | C35: {=_xlfn.IFS(ISNUMBER(FIND("N",B35)),"Needles",ISNUMBER(FIND("P",B35)),"Phloem")} -> Phloem | D35: 2 | E35: 2134.8839 | F35: 60 | H35: 2353.8462 | I35: 3
A36: VarImp | B36: P_0624R22C | C36: {=_xlfn.IFS(ISNUMBER(FIND("N",B36)),"Needles",ISNUMBER(FIND("P",B36)),"Phloem")} -> Phloem | D36: 2 | E36: 2023.1407 | F36: 79 | H36: Needles | I36: 3
A37: VarImp | B37: P_0624R22C | C37: {=_xlfn.IFS(ISNUMBER(FIND("N",B37)),"Needles",ISNUMBER(FIND("P",B37)),"Phloem")} -> Phloem | D37: 2 | E37: 1462.9485 | F37: 218 | H37: 1468.8003 | I37: 3
A38: VarImp | B38: P_0624R22C | C38: {=_xlfn.IFS(ISNUMBER(FIND("N",B38)),"Needles",ISNUMBER(FIND("P",B38)),"Phloem")} -> Phloem | D38: 2 | E38: 2384.4156 | F38: 24 | H38: Needles | I38: 3
A39: VarImp | B39: P_0624R22C | C39: {=_xlfn.IFS(ISNUMBER(FIND("N",B39)),"Needles",ISNUMBER(FIND("P",B39)),"Phloem")} -> Phloem | D39: 2 | E39: 2415.7895 | F39: 20 | H39: 1462.9485 | I39: 3
A40: VarImp | B40: P_0624R22C | C40: {=_xlfn.IFS(ISNUMBER(FIND("N",B40)),"Needles",ISNUMBER(FIND("P",B40)),"Phloem")} -> Phloem | D40: 2 | E40: 2116.4267 | F40: 63 | H40: Phloem | I40: 3
...

Sheet 2 Class Phloem Aggregate
A1: Method | B1: Run | C1: Tissue | D1: Class | E1: Wavelength | F1: Column Number | H1: Wavelength (nm) | I1: Frequency | J1: Corresponding Chemical (curran 1989)
A2: Interpretation | B2: P_0624R22C | C2: {=_xlfn.IFS(ISNUMBER(FIND("N",B2)),"Needles",ISNUMBER(FIND("P",B2)),"Phloem")} -> Phloem | D2: 2 | E2: 2134.8839 | F2: 60 | H2: 2141.108 | I2: 4 | J2: 2.13-2.18 - Protein - Protein,nitrogen
A3: Interpretation | B3: P_0624R22C | C3: {=_xlfn.IFS(ISNUMBER(FIND("N",B3)),"Needles",ISNUMBER(FIND("P",B3)),"Phloem")} -> Phloem | D3: 2 | E3: 2153.6658 | F3: 57 | H3: 2153.6658 | I3: 4 | J3: 2.13-2.18 - Protein - Protein,nitrogen
A4: Interpretation | B4: P_0624R22C | C4: {=_xlfn.IFS(ISNUMBER(FIND("N",B4)),"Needles",ISNUMBER(FIND("P",B4)),"Phloem")} -> Phloem | D4: 2 | E4: 2128.6958 | F4: 61 | H4: 2160.0002 | I4: 4 | J4: 2.13-2.18 - Protein - Protein,nitrogen
A5: Interpretation | B5: P_0624R22C | C5: {=_xlfn.IFS(ISNUMBER(FIND("N",B5)),"Needles",ISNUMBER(FIND("P",B5)),"Phloem")} -> Phloem | D5: 2 | E5: 2141.108 | F5: 59 | H5: 2134.8839 | I5: 4 | J5: 2.13-2.18 - Protein - Protein,nitrogen
A6: Interpretation | B6: P_0624R22C | C6: {=_xlfn.IFS(ISNUMBER(FIND("N",B6)),"Needles",ISNUMBER(FIND("P",B6)),"Phloem")} -> Phloem | D6: 2 | E6: 2160.0002 | F6: 56 | H6: 2166.3718 | I6: 3 | J6: 2.13-2.18 - Protein - Protein,nitrogen
A7: Interpretation | B7: P_0624R22C | C7: {=_xlfn.IFS(ISNUMBER(FIND("N",B7)),"Needles",ISNUMBER(FIND("P",B7)),"Phloem")} -> Phloem | D7: 2 | E7: 2147.3686 | F7: 58 | H7: 1462.9485 | I7: 3 | J7: 1.45-1.49 - starch, sugar, lignin, water - cellulose, sugar
A8: Interpretation | B8: P_0624R22C | C8: {=_xlfn.IFS(ISNUMBER(FIND("N",B8)),"Needles",ISNUMBER(FIND("P",B8)),"Phloem")} -> Phloem | D8: 2 | E8: 2122.5435 | F8: 62 | H8: 2147.3686 | I8: 3 | J8: 2.13-2.18 - Protein - Protein,nitrogen
A9: Interpretation | B9: P_0624R22C | C9: {=_xlfn.IFS(ISNUMBER(FIND("N",B9)),"Needles",ISNUMBER(FIND("P",B9)),"Phloem")} -> Phloem | D9: 2 | E9: 2166.3718 | F9: 55 | H9: 2400.0001 | I9: 3 | J9: > 2.35 - cellulose, protein, nitrogen
A10: Interpretation | B10: P_0624R22C | C10: {=_xlfn.IFS(ISNUMBER(FIND("N",B10)),"Needles",ISNUMBER(FIND("P",B10)),"Phloem")} -> Phloem | D10: 2 | E10: 2407.8689 | F10: 21 | H10: 2172.7812 | I10: 3 | J10: 2.13-2.18 - Protein - Protein,nitrogen
A11: Interpretation | B11: P_0624R22C | C11: {=_xlfn.IFS(ISNUMBER(FIND("N",B11)),"Needles",ISNUMBER(FIND("P",B11)),"Phloem")} -> Phloem | D11: 2 | E11: 2116.4267 | F11: 63 | H11: 2122.5435 | I11: 3 | J11: 2.10-2.13- Starch, cellulose - Protein
A12: Interpretation | B12: P_0624R22C | C12: {=_xlfn.IFS(ISNUMBER(FIND("N",B12)),"Needles",ISNUMBER(FIND("P",B12)),"Phloem")} -> Phloem | D12: 2 | E12: 2415.7895 | F12: 20 | H12: 2407.8689 | I12: 2 | J12: > 2.35 - cellulose, protein, nitrogen
A13: Interpretation | B13: P_0624R22C | C13: {=_xlfn.IFS(ISNUMBER(FIND("N",B13)),"Needles",ISNUMBER(FIND("P",B13)),"Phloem")} -> Phloem | D13: 2 | E13: 2400.0001 | F13: 22 | H13: 1420.5032 | I13: 2 | J13: 1.42 - 1.49 - lignin - starch, sugar, lignin, water
... A19: Interpretation | B19: P_0824R22C | C19: {=_xlfn.IFS(ISNUMBER(FIND("N",B19)),"Needles",ISNUMBER(FIND("P",B19)),"Phloem")} -> Phloem | D19: 2 | E19: 2172.7812 | F19: 54 | H19: 1808.8673 | I19: 1 | J19: 1.78-1.82 - cellulose,sugar,starch-cellulose
A20: Prediction | B20: P_0624R22C | C20: {=_xlfn.IFS(ISNUMBER(FIND("N",B20)),"Needles",ISNUMBER(FIND("P",B20)),"Phloem")} -> Phloem | D20: {=_xlfn.IFS(ISNUMBER(FIND("R13C",B20)),3,ISNUMBER(FIND("R22C",B20)),2)} -> 2 | E20: =VLOOKUP(F20,ColRef!$A$2:$B$258,2,FALSE) -> 2134.8839 | F20: 60 | H20: 1428.7941 | I20: 1 | J20: 1.42-1.45 - lignin - starch,sugar,lignin,water
A21: Prediction | B21: P_0624R22C | C21: {=_xlfn.IFS(ISNUMBER(FIND("N",B21)),"Needles",ISNUMBER(FIND("P",B21)),"Phloem")} -> Phloem | D21: {=_xlfn.IFS(ISNUMBER(FIND("R13C",B21)),3,ISNUMBER(FIND("R22C",B21)),2)} -> 2 | E21: =VLOOKUP(F21,ColRef!$A$2:$B$258,2,FALSE) -> 2153.6658 | F21: 57 | H21: 2179.2286 | I21: 1 | J21: 2.13-2.18 - Protein - Protein,nitrogen
A22: Prediction | B22: P_0624R22C | C22: {=_xlfn.IFS(ISNUMBER(FIND("N",B22)),"Needles",ISNUMBER(FIND("P",B22)),"Phloem")} -> Phloem | D22: {=_xlfn.IFS(ISNUMBER(FIND("R13C",B22)),3,ISNUMBER(FIND("R22C",B22)),2)} -> 2 | E22: =VLOOKUP(F22,ColRef!$A$2:$B$258,2,FALSE) -> 2141.108 | F22: 59 | H22: 1672.8932 | I22: 1 | J22: 1.58-1.69 - starch,sugar-lignin,starch,protein,nitrogen
A23: Prediction | B23: P_0624R22C | C23: {=_xlfn.IFS(ISNUMBER(FIND("N",B23)),"Needles",ISNUMBER(FIND("P",B23)),"Phloem")} -> Phloem | D23: {=_xlfn.IFS(ISNUMBER(FIND("R13C",B23)),3,ISNUMBER(FIND("R22C",B23)),2)} -> 2 | E23: =VLOOKUP(F23,ColRef!$A$2:$B$258,2,FALSE) -> 2160.0002 | F23: 56 | H23: 2448 | I23: 1 | J23: > 2.35 - cellulose, protein, nitrogen
A24: Prediction | B24: P_0624R22C | C24: {=_xlfn.IFS(ISNUMBER(FIND("N",B24)),"Needles",ISNUMBER(FIND("P",B24)),"Phloem")} -> Phloem | D24: {=_xlfn.IFS(ISNUMBER(FIND("R13C",B24)),3,ISNUMBER(FIND("R22C",B24)),2)} -> 2 | E24: =VLOOKUP(F24,ColRef!$A$2:$B$258,2,FALSE) -> 2166.3718 | F24: 55 | H24: 1465.8686 | I24: 1 | J24: 1.45-1.49 - starch,sugar,lignin,water-cellulose,sugar
A25: Prediction | B25: P_0624R22C | C25: {=_xlfn.IFS(ISNUMBER(FIND("N",B25)),"Needles",ISNUMBER(FIND("P",B25)),"Phloem")} -> Phloem | D25: {=_xlfn.IFS(ISNUMBER(FIND("R13C",B25)),3,ISNUMBER(FIND("R22C",B25)),2)} -> 2 | E25: =VLOOKUP(F25,ColRef!$A$2:$B$258,2,FALSE) -> 2400.0001 | F25: 22 | H25: 2384.4156 | I25: 1 | J25: > 2.35 - cellulose, protein, nitrogen
A26: Prediction | B26: P_0624R22C | C26: {=_xlfn.IFS(ISNUMBER(FIND("N",B26)),"Needles",ISNUMBER(FIND("P",B26)),"Phloem")} -> Phloem | D26: {=_xlfn.IFS(ISNUMBER(FIND("R13C",B26)),3,ISNUMBER(FIND("R22C",B26)),2)} -> 2 | E26: =VLOOKUP(F26,ColRef!$A$2:$B$258,2,FALSE) -> 1420.5032 | F26: 233 | H26: 1813.3336 | I26: 1 | J26: 1.78-1.82 - cellulose,sugar,starch-cellulose
A27: Prediction | B27: P_0624R22C | C27: {=_xlfn.IFS(ISNUMBER(FIND("N",B27)),"Needles",ISNUMBER(FIND("P",B27)),"Phloem")} -> Phloem | D27: {=_xlfn.IFS(ISNUMBER(FIND("R13C",B27)),3,ISNUMBER(FIND("R22C",B27)),2)} -> 2 | E27: =VLOOKUP(F27,ColRef!$A$2:$B$258,2,FALSE) -> 1462.9485 | F27: 218 | H27: 2376.6991 | I27: 1 | J27: > 2.35 - cellulose, protein, nitrogen
A28: Prediction | B28: P_0824R22C | C28: {=_xlfn.IFS(ISNUMBER(FIND("N",B28)),"Needles",ISNUMBER(FIND("P",B28)),"Phloem")} -> Phloem | D28: {=_xlfn.IFS(ISNUMBER(FIND("R13C",B28)),3,ISNUMBER(FIND("R22C",B28)),2)} -> 2 | E28: =VLOOKUP(F28,ColRef!$A$2:$B$258,2,FALSE) -> 2172.7812 | F28: 54 | H28: 1719.9066 | I28: 1 | J28: 1.69-1.78-lignin,starch,protein,nitrogen-cellulose,sugar,starch
A29: VarImp | B29: P_0624R22C | C29: {=_xlfn.IFS(ISNUMBER(FIND("N",B29)),"Needles",ISNUMBER(FIND("P",B29)),"Phloem")} -> Phloem | D29: 2 | E29: 2160.0002 | F29: 56 | H29: 2431.7881 | I29: 1 | J29: > 2.35 - cellulose, protein, nitrogen
A30: VarImp | B30: P_0624R22C | C30: {=_xlfn.IFS(ISNUMBER(FIND("N",B30)),"Needles",ISNUMBER(FIND("P",B30)),"Phloem")} -> Phloem | D30: 2 | E30: 2147.3686 | F30: 58 | H30: 1665.3064 | I30: 1 | J30: 1.58-1.69 - starch,sugar-lignin,starch,protein,nitrogen
A31: VarImp | B31: P_0624R22C | C31: {=_xlfn.IFS(ISNUMBER(FIND("N",B31)),"Needles",ISNUMBER(FIND("P",B31)),"Phloem")} -> Phloem | D31: 2 | E31: 2153.6658 | F31: 57 | H31: 2423.7624 | I31: 1 | J31: > 2.35 - cellulose, protein, nitrogen
A32: VarImp | B32: P_0624R22C | C32: {=_xlfn.IFS(ISNUMBER(FIND("N",B32)),"Needles",ISNUMBER(FIND("P",B32)),"Phloem")} -> Phloem | D32: 2 | E32: 2141.108 | F32: 59 | H32: 1642.9533 | I32: 1 | J32: 1.58-1.69 - starch,sugar-lignin,starch,protein,nitrogen
A33: VarImp | B33: P_0624R22C | C33: {=_xlfn.IFS(ISNUMBER(FIND("N",B33)),"Needles",ISNUMBER(FIND("P",B33)),"Phloem")} -> Phloem | D33: 2 | E33: 2128.6958 | F33: 61 | H33: 2185.7144 | I33: 1 | J33: 2.18-2.24-protein,nitrogen-protein
A34: VarImp | B34: P_0624R22C | C34: {=_xlfn.IFS(ISNUMBER(FIND("N",B34)),"Needles",ISNUMBER(FIND("P",B34)),"Phloem")} -> Phloem | D34: 2 | E34: 2122.5435 | F34: 62 | H34: 2192.239 | I34: 1 | J34: 2.18-2.24-protein,nitrogen-protein
A35: VarImp | B35: P_0624R22C | C35: {=_xlfn.IFS(ISNUMBER(FIND("N",B35)),"Needles",ISNUMBER(FIND("P",B35)),"Phloem")} -> Phloem | D35: 2 | E35: 2134.8839 | F35: 60 | H35: 1822.3328 | I35: 1 | J35: 1.82-1.90-cellulose-starch
A36: VarImp | B36: P_0624R22C | C36: {=_xlfn.IFS(ISNUMBER(FIND("N",B36)),"Needles",ISNUMBER(FIND("P",B36)),"Phloem")} -> Phloem | D36: 2 | E36: 2023.1407 | F36: 79 | H36: 2205.4055 | I36: 1 | J36: 2.18-2.24-protein,nitrogen-protein
A37: VarImp | B37: P_0624R22C | C37: {=_xlfn.IFS(ISNUMBER(FIND("N",B37)),"Needles",ISNUMBER(FIND("P",B37)),"Phloem")} -> Phloem | D37: 2 | E37: 1462.9485 | F37: 218 | H37: 1817.822 | I37: 1 | J37: 1.78-1.82 - cellulose,sugar,starch-cellulose
A38: VarImp | B38: P_0624R22C | C38: {=_xlfn.IFS(ISNUMBER(FIND("N",B38)),"Needles",ISNUMBER(FIND("P",B38)),"Phloem")} -> Phloem | D38: 2 | E38: 2384.4156 | F38: 24 | H38: 2023.1407 | I38: 1 | J38: 2.00- 2.06 - starch - protein, nitrogen
A39: VarImp | B39: P_0624R22C | C39: {=_xlfn.IFS(ISNUMBER(FIND("N",B39)),"Needles",ISNUMBER(FIND("P",B39)),"Phloem")} -> Phloem | D39: 2 | E39: 2415.7895 | F39: 20 | H39: Grand Total | I39: 67
A40: VarImp | B40: P_0624R22C | C40: {=_xlfn.IFS(ISNUMBER(FIND("N",B40)),"Needles",ISNUMBER(FIND("P",B40)),"Phloem")} -> Phloem | D40: 2 | E40: 2116.4267 | F40: 63
A41: VarImp | B41: P_0624R22C | C41: {=_xlfn.IFS(ISNUMBER(FIND("N",B41)),"Needles",ISNUMBER(FIND("P",B41)),"Phloem")} -> Phloem | D41: 2 | E41: 2400.0001 | F41: 22
A42: VarImp | B42: P_0624R22C | C42: {=_xlfn.IFS(ISNUMBER(FIND("N",B42)),"Needles",ISNUMBER(FIND("P",B42)),"Phloem")} -> Phloem | D42: 2 | E42: 2407.8689 | F42: 21
A43: VarImp | B43: P_0624R22C | C43: {=_xlfn.IFS(ISNUMBER(FIND("N",B43)),"Needles",ISNUMBER(FIND("P",B43)),"Phloem")} -> Phloem | D43: 2 | E43: 1428.7941 | F43: 230
A44: VarImp | B44: P_0624R22C | C44: {=_xlfn.IFS(ISNUMBER(FIND("N",B44)),"Needles",ISNUMBER(FIND("P",B44)),"Phloem")} -> Phloem | D44: 2 | E44: 2028.7295 | F44: 78
A45: VarImp | B45: P_0624R22C | C45: {=_xlfn.IFS(ISNUMBER(FIND("N",B45)),"Needles",ISNUMBER(FIND("P",B45)),"Phloem")} -> Phloem | D45: 2 | E45: 2431.7881 | F45: 18
...

Sheet Figure for Publication
A1: Wavelength (nm) | B1: Frequency | C1: Associated Vibration and Chemical (Curran, 1989)
A2: 2160.0002 | B2: 7 | C2: N-H Stretch (Protein)
A3: 2141.108 | B3: 6 | C3: N-H Stretch (Protein)
A4: 2153.6658 | B4: 6 | C4: N-H Stretch (Protein)
A5: 2400.0001 | B5: 6 | C5: CH2 bend, 2nd overtone, C-H deformation, 2nd overtone (Cellulose, protein, nitrogen)
A6: 2172.7812 | B6: 5 | C6: N-H Stretch (Protein)
A7: 2166.3718 | B7: 5 | C7: N-H Stretch (Protein)
A8: 2001.0901 | B8: 4 | C8: O-H deformation, C-O deformation (Starch)
A9: 2134.8839 | B9: 4 | C9: N-H Stretch (Protein)
A10: 1661.5388 | B10: 4 | C10: O-H stretch, first overtone (Starch, sugar)
A11: 2407.8689 | B11: 4 | C11: CH2 bend, 2nd overtone, C-H deformation, 2nd overtone (Cellulose, protein, nitrogen)
A15: Wavelength (nm) | B15: Frequency | C15: Associated Chemical(s) (Curran, 1989)
A16: 2141.108 | B16: 4 | C16: Protein, nitrogen
A17: 2153.6658 | B17: 4 | C17: Protein, nitrogen
A18: 2160.0002 | B18: 4 | C18: Protein, nitrogen
A19: 2134.8839 | B19: 4 | C19: Protein, nitrogen
A20: 2166.3718 | B20: 3 | C20: Protein, nitrogen
A21: 1462.9485 | B21: 3 | C21: Starch, sugar, lignin, water, cellulose
A22: 2147.3686 | B22: 3 | C22: Protein, nitrogen
A23: 2400.0001 | B23: 3 | C23: Cellulose, protein, nitrogen
A24: 2172.7812 | B24: 3 | C24: Protein, nitrogen
A25: 2122.5435 | B25: 3 | C25: Starch, cellulose, protein

Sheet VarImp
E1: Importance | U1: Run | V1: Date | W1: Classes | X1: Wavelength (nm) | Y1: x121 | Z1: x51 | AA1: x97 | AC1: Run | AD1: Date | AE1: Classes | AF1: Wavelengths | AG1: x121 | AH1: x51 | AI1: x97 | AK1: Run | AL1: Date | AM1: Classes | AN1: Wavelengths | AO1: x121 | AP1: x51 | AQ1: x97
A2: Run | B2: Month | C2: Class # | D2: Wavelength (nm) | E2: x121 | F2: x51 | G2: x97 | U2: N_0824R13C | V2: August | W2: 3 | X2: 2361.4149 | Y2: 19.4034 | Z2: 100 | AA2: 94.64 | AC2: N_0624R13C | AD2: June | AE2: 3 | AF2: 2324.0507 | AG2: 70.29 | AH2: 75.27 | AI2: 100 | AK2: N_0624R22C | AL2: June | AM2: 2 | AN2: 2153.6658 | AQ2: 100
A3: N_0624R13C | B3: June | C3: 3 | D3: 2324.0507 | E3: 70.29 | F3: 75.27 | G3: 100 | I3: =VLOOKUP(D3,WLReference!$A$2:$B$258,2,FALSE) -> 32 | U3: N_0824R13C | V3: August | W3: 3 | X3: 2369.0323 | Y3: 27.1094 | Z3: 90.78 | AA3: 68.86 | AC3: N_0624R13C | AD3: June | AE3: 3 | AF3: 1665.3064 | AG3: 96.22 | AH3: 22.1 | AI3: 69.72 | AK3: N_0624R22C | AL3: June | AM3: 2 | AN3: 1511.1114 | AQ3: 91.7
A4: N_0624R13C | B4: June | C4: 3 | D4: 1665.3064 | E4: 96.22 | F4: 22.1 | G4: 69.72 | I4: =VLOOKUP(D4,WLReference!$A$2:$B$258,2,FALSE) -> 157 | U4: N_0824R13C | V4: August | W4: 3 | X4: 2353.8462 | Y4: 0.8171 | Z4: 88.18 | AA4: 90.65 | AC4: N_0624R13C | AD4: June | AE4: 3 | AF4: 1360.0003 | AG4: 19.65 | AH4: 17.87 | AI4: 91.04 | AK4: N_0624R22C | AL4: June | AM4: 2 | AN4: 2400.0001 | AQ4: 84.95
A5: N_0624R13C | B5: June | C5: 3 | D5: 1360.0003 | E5: 19.65 | F5: 17.87 | G5: 91.04 | I5: =VLOOKUP(D5,WLReference!$A$2:$B$258,2,FALSE) -> 256 | U5: N_0824R13C | V5: August | W5: 3 | X5: 2376.6991 | Y5: 13.4548 | Z5: 85.87 | AA5: 65.27 | AC5: N_0624R13C | AD5: June | AE5: 3 | AF5: 1508.0085 | AG5: 89.02 | AH5: 82.05 | AI5: 46.37 | AK5: N_0624R22C | AL5: June | AM5: 2 | AN5: 2160.0002 | AQ5: 80.34
A6: N_0624R13C | B6: June | C6: 3 | D6: 1508.0085 | E6: 89.02 | F6: 82.05 | G6: 46.37 | I6: =VLOOKUP(D6,WLReference!$A$2:$B$258,2,FALSE) -> 203 | U6: N_0824R13C | V6: August | W6: 3 | X6: 1696.0742 | Y6: 36.5234 | Z6: 39.64 | AA6: 76.82 | AC6: N_0624R13C | AD6: June | AE6: 3 | AF6: 1661.5388 | AG6: 88.17 | AH6: 72.22 | AI6: 75.79 | AK6: N_0624R22C | AL6: June | AM6: 2 | AN6: 2407.8689 | AQ6: 76.87
A7: N_0624R13C | B7: June | C7: 3 | D7: 1661.5388 | E7: 88.17 | F7: 72.22 | G7: 75.79 | I7: =VLOOKUP(D7,WLReference!$A$2:$B$258,2,FALSE) -> 158 | U7: N_0824R13C | V7: August | W7: 3 | X7: 2384.4156 | Y7: 17.912 | Z7: 76.62 | AA7: 57.03 | AC7: N_0624R13C | AD7: June | AE7: 3 | AF7: 2266.6668 | AG7: 17.59 | AH7: 18 | AI7: 88.08 | AK7: N_0624R22C | AL7: June | AM7: 2 | AN7: 1471.7438 | AQ7: 76.61
A8: N_0624R13C | B8: June | C8: 3 | D8: 2266.6668 | E8: 17.59 | F8: 18 | G8: 88.08 | I8: =VLOOKUP(D8,WLReference!$A$2:$B$258,2,FALSE) -> 40 | K8: Row Labels | L8: Average of x97 | M8: Count of Wavelength (nm) | U8: N_0824R13C | V8: August | W8: 3 | X8: 2309.4341 | Y8: 60.6089 | Z8: 70.77 | AA8: 16.28 | AC8: N_0624R13C | AD8: June | AE8: 3 | AF8: 1610.5266 | AG8: 67.3 | AH8: 73.36 | AI8: 87.56 | AK8: N_0624R22C | AL8: June | AM8: 2 | AN8: 2456.1873 | AQ8: 72.16
A9: N_0624R13C | B9: June | C9: 3 | D9: 1610.5266 | E9: 67.3 | F9: 73.36 | G9: 87.56 | I9: =VLOOKUP(D9,WLReference!$A$2:$B$258,2,FALSE) -> 172 | K9: 2153.6658 | L9: 80.586 | M9: 5 | U9: N_0824R13C | V9: August | W9: 3 | X9: 1878.2611 | Y9: 27.1738 | Z9: 54.42 | AA9: 69.56 | AC9: N_0624R13C | AD9: June | AE9: 3 | AF9: 2302.1945 | AG9: 87.38 | AH9: 30.66 | AI9: 13.33 | AK9: N_0624R22C | AL9: June | AM9: 2 | AN9: 1533.1945 | AQ9: 72.08
A10: N_0624R13C | B10: June | C10: 3 | D10: 2302.1945 | E10: 87.38 | F10: 30.66 | G10: 13.33 | I10: =VLOOKUP(D10,WLReference!$A$2:$B$258,2,FALSE) -> 35 | K10: 2160.0002 | L10: 83.344 | M10: 5 | U10: N_0824R13C | V10: August | W10: 3 | X10: 2346.326 | Y10: 19.8324 | Z10: 41.23 | AA10: 69.54 | AC10: N_0624R13C | AD10: June | AE10: 3 | AF10: 2456.1873 | AG10: 87.28 | AH10: 61.27 | AI10: 46.37 | AK10: N_0624R22C | AL10: June | AM10: 2 | AN10: 2141.108 | AQ10: 70.18
A11: N_0624R13C | B11: June | C11: 3 | D11: 2456.1873 | E11: 87.28 | F11: 61.27 | G11: 46.37 | I11: =VLOOKUP(D11,WLReference!$A$2:$B$258,2,FALSE) -> 15 | K11: 2141.108 | L11: 72.888 | M11: 5 | U11: N_0824R13C | V11: August | W11: 3 | X11: 2295.0001 | Y11: 40.4524 | Z11: 69.46 | AA11: 26 | AC11: N_0624R13C | AD11: June | AE11: 3 | AF11: 2068.7326 | AG11: 87.22 | AH11: 12 | AI11: 27.35 | AK11: N_0624R22C | AL11: June | AM11: 2 | AN11: 1669.0912 | AQ11: 69.74
A12: N_0624R13C | B12: June | C12: 3 | D12: 2068.7326 | E12: 87.22 | F12: 12 | G12: 27.35 | I12: =VLOOKUP(D12,WLReference!$A$2:$B$258,2,FALSE) -> 71 | K12: 1661.5388 | L12: 68.655 | M12: 4 | U12: N_0824R13C | V12: August | W12: 3 | X12: 1700.0003 | Y12: 20.0653 | Z12: 52.81 | AA12: 68.57 | AC12: N_0624R13C | AD12: June | AE12: 3 | AF12: 2309.4341 | AG12: 85.6 | AH12: 23.58 | AI12: 60.04 | AK12: N_0624R22C | AL12: June | AM12: 2 | AN12: 1495.7233 | AQ12: 69.57
A13: N_0624R13C | B13: June | C13: 3 | D13: 2309.4341 | E13: 85.6 | F13: 23.58 | G13: 60.04 | I13: =VLOOKUP(D13,WLReference!$A$2:$B$258,2,FALSE) -> 34 | K13: 2134.8839 | L13: 74.6575 | M13: 4 | U13: N_0824R13C | V13: August | W13: 3 | X13: 1711.8884 | Y13: 35.5404 | Z13: 67.09 | AA13: 12.47 | AC13: N_0624R13C | AD13: June | AE13: 3 | AF13: 1892.7837 | AG13: 46.37 | AH13: 85.6 | AI13: 25.43 | AK13: N_0624R22C | AL13: June | AM13: 2 | AN13: 2172.7812 | AQ13: 69.4
A14: N_0624R13C | B14: June | C14: 3 | D14: 1892.7837 | E14: 46.37 | F14: 85.6 | G14: 25.43 | I14: =VLOOKUP(D14,WLReference!$A$2:$B$258,2,FALSE) -> 104 | K14: 2147.3686 | L14: 70.9675 | M14: 4 | U14: N_0824R13C | V14: August | W14: 3 | X14: 2302.1945 | Y14: 43.3599 | Z14: 66.96 | AA14: 29.82 | AC14: N_0624R13C | AD14: June | AE14: 3 | AF14: 1442.8294 | AG14: 10.9 | AH14: 84.84 | AI14: 25.02 | AK14: N_0624R22C | AL14: June | AM14: 2 | AN14: 1661.5388 | AQ14: 68.39
A15: N_0624R13C | B15: June | C15: 3 | D15: 1442.8294 | E15: 10.9 | F15: 84.84 | G15: 25.02 | I15: =VLOOKUP(D15,WLReference!$A$2:$B$258,2,FALSE) -> 225 | K15: 2166.3718 | L15: 72.205 | M15: 4 | U15: N_0824R13C | V15: August | W15: 3 | X15: 2316.7193 | Y15: 56.4102 | Z15: 66.42 | AA15: 24.67 | AC15: N_0624R13C | AD15: June | AE15: 3 | AF15: 1460.0401 | AG15: 84.6 | AH15: 46.37 | AI15: 38.95 | AK15: N_0624R22C | AL15: June | AM15: 2 | AN15: 2017.5826 | AQ15: 67.99
A16: N_0624R13C | B16: June | C16: 3 | D16: 1460.0401 | E16: 84.6 | F16: 46.37 | G16: 38.95 | I16: =VLOOKUP(D16,WLReference!$A$2:$B$258,2,FALSE) -> 219 | K16: 1669.0912 | L16: 73.136667 | M16: 3 | U16: N_0824R13C | V16: August | W16: 3 | X16: 1984.8651 | Y16: 65.8078 | Z16: 34.26 | AA16: 55.07 | AC16: N_0624R13C | AD16: June | AE16: 3 | AF16: 2497.9592 | AG16: 82.78 | AH16: 17.51 | AI16: 16.73 | AK16: N_0624R22C | AL16: June | AM16: 2 | AN16: 2001.0901 | AQ16: 67.86
A17: N_0624R13C | B17: June | C17: 3 | D17: 2497.9592 | E17: 82.78 | F17: 17.51 | G17: 16.73 | I17: =VLOOKUP(D17,WLReference!$A$2:$B$258,2,FALSE) -> 10 | K17: 2369.0323 | L17: 76.87 | M17: 3 | U17: N_0824R13C | V17: August | W17: 3 | X17: 2280.7455 | Y17: 29.0414 | Z17: 65.75 | AA17: 37.37 | AC17: N_0624R13C | AD17: June | AE17: 3 | AF17: 2295.0001 | AG17: 81.22 | AH17: 48.66 | AI17: 82.63 | AK17: N_0624R22C | AL17: June | AM17: 2 | AN17: 1800.0003 | AQ17: 67.17
A18: N_0624R13C | B18: June | C18: 3 | D18: 2295.0001 | E18: 81.22 | F18: 48.66 | G18: 82.63 | I18: =VLOOKUP(D18,WLReference!$A$2:$B$258,2,FALSE) -> 36 | K18: 2122.5435 | L18: 69.09 | M18: 3 | U18: N_0824R13C | V18: August | W18: 3 | X18: 2273.6843 | Y18: 24.7803 | Z18: 65.71 | AA18: 25.3 | AC18: N_0624R13C | AD18: June | AE18: 3 | AF18: 2472.7273 | AG18: 30.55 | AH18: 41.48 | AI18: 82.6 | AK18: N_0624R22C | AL18: June | AM18: 2 | AN18: 1912.5002 | AQ18: 65.75
A19: N_0624R13C | B19: June | C19: 3 | D19: 2472.7273 | E19: 30.55 | F19: 41.48 | G19: 82.6 | I19: =VLOOKUP(D19,WLReference!$A$2:$B$258,2,FALSE) -> 13 | K19: 2172.7812 | L19: 82.22 | M19: 3 | U19: N_0824R13C | V19: August | W19: 3 | X19: 2287.8506 | Y19: 57.6196 | Z19: 63.67 | AA19: 15.98 | AC19: N_0624R13C | AD19: June | AE19: 3 | AF19: 2400.0001 | AG19: 82.44 | AH19: 25.43 | AI19: 49.89 | AK19: N_0624R22C | AL19: June | AM19: 2 | AN19: 1468.8003 | AQ19: 63.45
A20: N_0624R13C | B20: June | C20: 3 | D20: 2400.0001 | E20: 82.44 | F20: 25.43 | G20: 49.89 | I20: =VLOOKUP(D20,WLReference!$A$2:$B$258,2,FALSE) -> 22 | K20: 2376.6991 | L20: 69.07 | M20: 3 | U20: N_0824R13C | V20: August | W20: 3 | X20: 1715.8881 | Y20: 48.9116 | Z20: 63.44 | AA20: 17.93 | AC20: N_0624R13C | AD20: June | AE20: 3 | AF20: 1822.3328 | AG20: 82.44 | AH20: 46.37 | AI20: 11 | AK20: N_0624R22C | AL20: June | AM20: 2 | AN20: 2166.3718 | AQ20: 63.34
A21: N_0624R13C | B21: June | C21: 3 | D21: 1822.3328 | E21: 82.44 | F21: 46.37 | G21: 11 | I21: =VLOOKUP(D21,WLReference!$A$2:$B$258,2,FALSE) -> 119 | K21: 2295.0001 | L21: 57.27 | M21: 3 | U21: N_0824R13C | V21: August | W21: 3 | X21: 2040.0002 | Y21: 15.8519 | Z21: 47.29 | AA21: 63.06 | AC21: N_0624R13C | AD21: June | AE21: 3 | AF21: 2198.8025 | AG21: 82.41 | AH21: 51.78 | AI21: 69.79 | AK21: N_0624R22C | AL21: June | AM21: 2 | AN21: 2295.0001 | AQ21: 63.18
A22: N_0624R13C | B22: June | C22: 3 | D22: 2198.8025 | E22: 82.41 | F22: 51.78 | G22: 69.79 | I22: =VLOOKUP(D22,WLReference!$A$2:$B$258,2,FALSE) -> 50 | K22: 2361.4149 | L22: 88.216667 | M22: 3 | U22: N_0824R22C | V22: August | W22: 2 | X22: 1696.0742 | AA22: 100 | AC22: P_0624R13C | AD22: June | AE22: 3 | AF22: 2134.8839 | AG22: 100 | AH22: 78.699 | AI22: 84.97 | AK22: P_0624R22C | AL22: June | AM22: 2 | AN22: 2160.0002 | AQ22: 100
A23: P_0624R13C | B23: June | C23: 3 | D23: 2134.8839 | E23: 100 | F23: 78.699 | G23: 84.97 | I23: =VLOOKUP(D23,WLReference!$A$2:$B$258,2,FALSE) -> 60 | K23: 1822.3328 | L23: 45.963333 | M23: 3 | U23: N_0824R22C | V23: August | W23: 2 | X23: 2361.4149 | AA23: 97.8 | AC23: P_0624R13C | AD23: June | AE23: 3 | AF23: 2128.6958 | AG23: 88.58 | AH23: 57.499 | AI23: 56.58 | AK23: P_0624R22C | AL23: June | AM23: 2 | AN23: 2147.3686 | AQ23: 96.51
A24: P_0624R13C | B24: June | C24: 3 | D24: 2128.6958 | E24: 88.58 | F24: 57.499 | G24: 56.58 | I24: =VLOOKUP(D24,WLReference!$A$2:$B$258,2,FALSE) -> 61 | K24: 2384.4156 | L24: 71.413333 | M24: 3 | U24: N_0824R22C | V24: August | W24: 2 | X24: 2001.0901 | AA24: 92.57 | AC24: P_0624R13C | AD24: June | AE24: 3 | AF24: 2153.6658 | AG24: 88.57 | AH24: 33.495 | AI24: 65.21 | AK24: P_0624R22C | AL24: June | AM24: 2 | AN24: 2153.6658 | AQ24: 90.85
A25: P_0624R13C | B25: June | C25: 3 | D25: 2153.6658 | E25: 88.57 | F25: 33.495 | G25: 65.21 | I25: =VLOOKUP(D25,WLReference!$A$2:$B$258,2,FALSE) -> 57 | K25: 2400.0001 | L25: 68 | M25: 3 | U25: N_0824R22C | V25: August | W25: 2 | X25: 1692.1662 | AA25: 92.07 | AC25: P_0624R13C | AD25: June | AE25: 3 | AF25: 2160.0002 | AG25: 87.76 | AH25: 34.842 | AI25: 67.84 | AK25: P_0624R22C | AL25: June | AM25: 2 | AN25: 2141.108 | AQ25: 89.63
A26: P_0624R13C | B26: June | C26: 3 | D26: 2160.0002 | E26: 87.76 | F26: 34.842 | G26: 67.84 | I26: =VLOOKUP(D26,WLReference!$A$2:$B$258,2,FALSE) -> 56 | K26: 2346.326 | L26: 72.905 | M26: 2 | U26: N_0824R22C | V26: August | W26: 2 | X26: 2353.8462 | AA26: 89.68 | AC26: P_0624R13C | AD26: June | AE26: 3 | AF26: 2384.4156 | AG26: 64.6 | AH26: 63.725 | AI26: 83.85 | AK26: P_0624R22C | AL26: June | AM26: 2 | AN26: 2128.6958 | AQ26: 84.83
A27: P_0624R13C | B27: June | C27: 3 | D27: 2384.4156 | E27: 64.6 | F27: 63.725 | G27: 83.85 | I27: =VLOOKUP(D27,WLReference!$A$2:$B$258,2,FALSE) -> 24 | K27: 2415.7895 | L27: 69.305 | M27: 2 | U27: N_0824R22C | V27: August | W27: 2 | X27: 1963.6366 | AA27: 83.6 | AC27: P_0624R13C | AD27: June | AE27: 3 | AF27: 2141.108 | AG27: 83.23 | AH27: 54.599 | AI27: 69.36 | AK27: P_0624R22C | AL27: June | AM27: 2 | AN27: 2122.5435 | AQ27: 83.6
A28: P_0624R13C | B28: June | C28: 3 | D28: 2141.108 | E28: 83.23 | F28: 54.599 | G28: 69.36 | I28: =VLOOKUP(D28,WLReference!$A$2:$B$258,2,FALSE) -> 59 | K28: 2309.4341 | L28: 38.16 | M28: 2 | U28: N_0824R22C | V28: August | W28: 2 | X28: 2369.0323 | AA28: 80.97 | AC28: P_0624R13C | AD28: June | AE28: 3 | AF28: 2369.0323 | AG28: 39.85 | AH28: 77.277 | AI28: 80.78 | AK28: P_0624R22C | AL28: June | AM28: 2 | AN28: 2134.8839 | AQ28: 80.9
A29: P_0624R13C | B29: June | C29: 3 | D29: 2369.0323 | E29: 39.85 | F29: 77.277 | G29: 80.78 | I29: =VLOOKUP(D29,WLReference!$A$2:$B$258,2,FALSE) -> 26 | K29: 2456.1873 | L29: 59.265 | M29: 2 | U29: N_0824R22C | V29: August | W29: 2 | X29: 1409.5972 | AA29: 79.74 | AC29: P_0624R13C | AD29: June | AE29: 3 | AF29: 1420.5032 | AG29: 75.76 | AH29: 56.61 | AI29: 40.7 | AK29: P_0624R22C | AL29: June | AM29: 2 | AN29: 2023.1407 | AQ29: 77.71
A30: P_0624R13C | B30: June | C30: 3 | D30: 1420.5032 | E30: 75.76 | F30: 56.61 | G30: 40.7 | I30: =VLOOKUP(D30,WLReference!$A$2:$B$258,2,FALSE) -> 233 | K30: 2353.8462 | L30: 90.165 | M30: 2 | U30: N_0824R22C | V30: August | W30: 2 | X30: 1700.0003 | AA30: 79.49 | AC30: P_0624R13C | AD30: June | AE30: 3 | AF30: 2376.6991 | AG30: 48.2 | AH30: 62.17 | AI30: 75.74 | AK30: P_0624R22C | AL30: June | AM30: 2 | AN30: 1462.9485 | AQ30: 77.58
A31: P_0624R13C | B31: June | C31: 3 | D31: 2376.6991 | E31: 48.2 | F31: 62.17 | G31: 75.74 | I31: =VLOOKUP(D31,WLReference!$A$2:$B$258,2,FALSE) -> 25 | K31: 1468.8003 | L31: 65.14 | M31: 2 | U31: N_0824R22C | V31: August | W31: 2 | X31: 2006.5576 | AA31: 77.93 | AC31: P_0624R13C | AD31: June | AE31: 3 | AF31: 2147.3686 | AG31: 74.43 | AH31: 37.432 | AI31: 51.29 | AK31: P_0624R22C | AL31: June | AM31: 2 | AN31: 2384.4156 | AQ31: 73.36
A32: P_0624R13C | B32: June | C32: 3 | D32: 2147.3686 | E32: 74.43 | F32: 37.432 | G32: 51.29 | I32: =VLOOKUP(D32,WLReference!$A$2:$B$258,2,FALSE) -> 58 | K32: 2179.2286 | L32: 76.43 | M32: 2 | U32: N_0824R22C | V32: August | W32: 2 | X32: 1958.4002 | AA32: 77.47 | AC32: P_0624R13C | AD32: June | AE32: 3 | AF32: 2051.3968 | AG32: 58.34 | AH32: 54.597 | AI32: 74.21 | AK32: P_0624R22C | AL32: June | AM32: 2 | AN32: 2415.7895 | AQ32: 72.01
A33: P_0624R13C | B33: June | C33: 3 | D33: 2051.3968 | E33: 58.34 | F33: 54.597 | G33: 74.21 | I33: =VLOOKUP(D33,WLReference!$A$2:$B$258,2,FALSE) -> 74 | K33: 2128.6958 | L33: 70.705 | M33: 2 | U33: N_0824R22C | V33: August | W33: 2 | X33: 2346.326 | AA33: 76.27 | AC33: P_0624R13C | AD33: June | AE33: 3 | AF33: 2392.1825 | AG33: 35.75 | AH33: 49.31 | AI33: 74.15 | AK33: P_0624R22C | AL33: June | AM33: 2 | AN33: 2116.4267 | AQ33: 71.72
... A41: P_0624R13C | B41: June | C41: 3 | D41: 1365.0561 | E41: 38.97 | F41: 66.337 | G41: 41.46 | I41: =VLOOKUP(D41,WLReference!$A$2:$B$258,2,FALSE) -> 254 | K41: 2302.1945 | L41: 21.575 | M41: 2 | U41: N_0824R22C | V41: August | W41: 2 | X41: 1412.308 | AA41: 64.11 | AC41: P_0624R13C | AD41: June | AE41: 3 | AF41: 2122.5435 | AG41: 65.41 | AH41: 52.388 | AI41: 65.84 | AK41: P_0624R22C | AL41: June | AM41: 2 | AN41: 2423.7624 | AQ41: 63.67
A42: P_0624R13C | B42: June | C42: 3 | D42: 2122.5435 | E42: 65.41 | F42: 52.388 | G42: 65.84 | I42: =VLOOKUP(D42,WLReference!$A$2:$B$258,2,FALSE) -> 62 | K42: 2051.3968 | L42: 78.37 | M42: 2 | U42: P_0824R13C | V42: August | W42: 3 | X42: 2172.7812 | Y42: 100 | Z42: 72.58 | AA42: 84.67 | AC42: N_0824R13C | AD42: August | AE42: 3 | AF42: 2361.4149 | AG42: 19.4034 | AH42: 100 | AI42: 94.64 | AK42: N_0824R22C | AL42: August | AM42: 2 | AN42: 1696.0742 | AQ42: 100
A43: N_0824R13C | B43: August | C43: 3 | D43: 2361.4149 | E43: 19.4034 | F43: 100 | G43: 94.64 | I43: =VLOOKUP(D43,WLReference!$A$2:$B$258,2,FALSE) -> 27 | K43: 2407.8689 | L43: 87.925 | M43: 2 | U43: P_0824R13C | V43: August | W43: 3 | X43: 2160.0002 | Y43: 90.88 | Z43: 57.15 | AA43: 86.77 | AC43: N_0824R13C | AD43: August | AE43: 3 | AF43: 2369.0323 | AG43: 27.1094 | AH43: 90.78 | AI43: 68.86 | AK43: N_0824R22C | AL43: August | AM43: 2 | AN43: 2361.4149 | AQ43: 97.8
A44: N_0824R13C | B44: August | C44: 3 | D44: 2369.0323 | E44: 27.1094 | F44: 90.78 | G44: 68.86 | I44: =VLOOKUP(D44,WLReference!$A$2:$B$258,2,FALSE) -> 26 | K44: 2006.5576 | L44: 72.445 | M44: 2 | U44: P_0824R13C | V44: August | W44: 3 | X44: 1922.5133 | Y44: 37.46 | Z44: 90.56 | AA44: 58.23 | AC44: N_0824R13C | AD44: August | AE44: 3 | AF44: 2353.8462 | AG44: 0.8171 | AH44: 88.18 | AI44: 90.65 | AK44: N_0824R22C | AL44: August | AM44: 2 | AN44: 2001.0901 | AQ44: 92.57
A45: N_0824R13C | B45: August | C45: 3 | D45: 2353.8462 | E45: 0.8171 | F45: 88.18 | G45: 90.65 | I45: =VLOOKUP(D45,WLReference!$A$2:$B$258,2,FALSE) -> 28 | K45: 2280.7455 | L45: 37.37 | M45: 1 | U45: P_0824R13C | V45: August | W45: 3 | X45: 2166.3718 | Y45: 90.04 | Z45: 52.41 | AA45: 67.75 | AC45: N_0824R13C | AD45: August | AE45: 3 | AF45: 2376.6991 | AG45: 13.4548 | AH45: 85.87 | AI45: 65.27 | AK45: N_0824R22C | AL45: August | AM45: 2 | AN45: 1692.1662 | AQ45: 92.07
A46: N_0824R13C | B46: August | C46: 3 | D46: 2376.6991 | E46: 13.4548 | F46: 85.87 | G46: 65.27 | I46: =VLOOKUP(D46,WLReference!$A$2:$B$258,2,FALSE) -> 25 | K46: 1628.3817 | L46: 24.23 | M46: 1 | U46: P_0824R13C | V46: August | W46: 3 | X46: 2141.108 | Y46: 70.65 | Z46: 25.09 | AA46: 86.8 | AC46: N_0824R13C | AD46: August | AE46: 3 | AF46: 1696.0742 | AG46: 36.5234 | AH46: 39.64 | AI46: 76.82 | AK46: N_0824R22C | AL46: August | AM46: 2 | AN46: 2353.8462 | AQ46: 89.68
A47: N_0824R13C | B47: August | C47: 3 | D47: 1696.0742 | E47: 36.5234 | F47: 39.64 | G47: 76.82 | I47: =VLOOKUP(D47,WLReference!$A$2:$B$258,2,FALSE) -> 149 | K47: 1958.4002 | L47: 77.47 | M47: 1 | U47: P_0824R13C | V47: August | W47: 3 | X47: 2153.6658 | Y47: 85.05 | Z47: 29.24 | AA47: 80.32 | AC47: N_0824R13C | AD47: August | AE47: 3 | AF47: 2384.4156 | AG47: 17.912 | AH47: 76.62 | AI47: 57.03 | AK47: N_0824R22C | AL47: August | AM47: 2 | AN47: 1963.6366 | AQ47: 83.6
...

Sheet Interpretation
A1: Run | B1: Class | C1: Wavelength | D1: Column Number
A2: N_0624R22C | B2: {=_xlfn.IFS(ISNUMBER(FIND("R13C",A2)),3,ISNUMBER(FIND("R22C",A2)),2)} -> 2 | C2: =VLOOKUP(D2,ColRef!A$1:B$258, 2, FALSE) -> 2160.0002 | D2: 56 | F2: Wavelength (nm) | G2: Count of Wavelength
A3: N_0624R22C | B3: {=_xlfn.IFS(ISNUMBER(FIND("R13C",A3)),3,ISNUMBER(FIND("R22C",A3)),2)} -> 2 | C3: =VLOOKUP(D3,ColRef!A$1:B$258, 2, FALSE) -> 1511.1114 | D3: 202 | F3: 2160.0002 | G3: 4
A4: N_0624R22C | B4: {=_xlfn.IFS(ISNUMBER(FIND("R13C",A4)),3,ISNUMBER(FIND("R22C",A4)),2)} -> 2 | C4: =VLOOKUP(D4,ColRef!A$1:B$258, 2, FALSE) -> 2153.6658 | D4: 57 | F4: 56 | G4: 4
A5: N_0624R22C | B5: {=_xlfn.IFS(ISNUMBER(FIND("R13C",A5)),3,ISNUMBER(FIND("R22C",A5)),2)} -> 2 | C5: =VLOOKUP(D5,ColRef!A$1:B$258, 2, FALSE) -> 2166.3718 | D5: 55 | F5: 2153.6658 | G5: 4
A6: N_0624R22C | B6: {=_xlfn.IFS(ISNUMBER(FIND("R13C",A6)),3,ISNUMBER(FIND("R22C",A6)),2)} -> 2 | C6: =VLOOKUP(D6,ColRef!A$1:B$258, 2, FALSE) -> 2400.0001 | D6: 22 | F6: 57 | G6: 4
A7: N_0624R22C | B7: {=_xlfn.IFS(ISNUMBER(FIND("R13C",A7)),3,ISNUMBER(FIND("R22C",A7)),2)} -> 2 | C7: =VLOOKUP(D7,ColRef!A$1:B$258, 2, FALSE) -> 1665.3064 | D7: 157 | F7: 2141.108 | G7: 4
A8: N_0624R22C | B8: {=_xlfn.IFS(ISNUMBER(FIND("R13C",A8)),3,ISNUMBER(FIND("R22C",A8)),2)} -> 2 | C8: =VLOOKUP(D8,ColRef!A$1:B$258, 2, FALSE) -> 2147.3686 | D8: 58 | F8: 59 | G8: 4
A9: N_0624R22C | B9: {=_xlfn.IFS(ISNUMBER(FIND("R13C",A9)),3,ISNUMBER(FIND("R22C",A9)),2)} -> 2 | C9: =VLOOKUP(D9,ColRef!A$1:B$258, 2, FALSE) -> 2034.3492 | D9: 77 | F9: 2147.3686 | G9: 4
A10: N_0624R22C | B10: {=_xlfn.IFS(ISNUMBER(FIND("R13C",A10)),3,ISNUMBER(FIND("R22C",A10)),2)} -> 2 | C10: =VLOOKUP(D10,ColRef!A$1:B$258, 2, FALSE) -> 2172.7812 | D10: 54 | F10: 58 | G10: 4
A11: N_0624R22C | B11: {=_xlfn.IFS(ISNUMBER(FIND("R13C",A11)),3,ISNUMBER(FIND("R22C",A11)),2)} -> 2 | C11: =VLOOKUP(D11,ColRef!A$1:B$258, 2, FALSE) -> 1661.5388 | D11: 158 | F11: 2166.3718 | G11: 4
A12: N_0624R22C | B12: {=_xlfn.IFS(ISNUMBER(FIND("R13C",A12)),3,ISNUMBER(FIND("R22C",A12)),2)} -> 2 | C12: =VLOOKUP(D12,ColRef!A$1:B$258, 2, FALSE) -> 2392.1825 | D12: 23 | F12: 55 | G12: 4
A13: N_0624R22C | B13: {=_xlfn.IFS(ISNUMBER(FIND("R13C",A13)),3,ISNUMBER(FIND("R22C",A13)),2)} -> 2 | C13: =VLOOKUP(D13,ColRef!A$1:B$258, 2, FALSE) -> 1514.2271 | D13: 201 | F13: 2134.8839 | G13: 3
A14: N_0624R22C | B14: {=_xlfn.IFS(ISNUMBER(FIND("R13C",A14)),3,ISNUMBER(FIND("R22C",A14)),2)} -> 2 | C14: =VLOOKUP(D14,ColRef!A$1:B$258, 2, FALSE) -> 2028.7295 | D14: 78 | F14: 60 | G14: 3
... A123: P_0824R13C | B123: {=_xlfn.IFS(ISNUMBER(FIND("R13C",A123)),3,ISNUMBER(FIND("R22C",A123)),2)} -> 3 | C123: =VLOOKUP(D123,ColRef!A$1:B$258, 2, FALSE) -> 1672.8932 | D123: 155 | F123: 1635.635 | G123: 1
F124: 165 | G124: 1
F125: 1420.5032 | G125: 1
F126: 233 | G126: 1
F127: 1907.5327 | G127: 1
F128: 101 | G128: 1
F129: 2205.4055 | G129: 1
F130: 49 | G130: 1
F131: 1868.7025 | G131: 1
F132: 109 | G132: 1
F133: 1462.9485 | G133: 1
F134: 218 | G134: 1
F135: 1917.4937 | G135: 1
... F160: 18 | G160: 1
F161: Grand Total | G161: 121

Sheet Prediction
A1: Run | B1: Class | C1: Wavelength | D1: Column Number | F1: Row Labels | G1: Count of Wavelength
A2: N_0624R13C | B2: {=_xlfn.IFS(ISNUMBER(FIND("R13C",A2)),3,ISNUMBER(FIND("R22C",A2)),2)} -> 3 | C2: =VLOOKUP(D2,ColRef!$A$2:$B$258,2,FALSE) -> 1672.8932 | D2: 155 | F2: 2361.4149 | G2: 3
A3: N_0624R13C | B3: {=_xlfn.IFS(ISNUMBER(FIND("R13C",A3)),3,ISNUMBER(FIND("R22C",A3)),2)} -> 3 | C3: =VLOOKUP(D3,ColRef!$A$2:$B$258,2,FALSE) -> 1669.0912 | D3: 156 | F3: 27 | G3: 3
A4: N_0624R13C | B4: {=_xlfn.IFS(ISNUMBER(FIND("R13C",A4)),3,ISNUMBER(FIND("R22C",A4)),2)} -> 3 | C4: =VLOOKUP(D4,ColRef!$A$2:$B$258,2,FALSE) -> 1549.3674 | D4: 190 | F4: 2141.108 | G4: 2
A5: P_0624R13C | B5: {=_xlfn.IFS(ISNUMBER(FIND("R13C",A5)),3,ISNUMBER(FIND("R22C",A5)),2)} -> 3 | C5: =VLOOKUP(D5,ColRef!$A$2:$B$258,2,FALSE) -> 2134.8839 | D5: 60 | F5: 59 | G5: 2
A6: P_0624R13C | B6: {=_xlfn.IFS(ISNUMBER(FIND("R13C",A6)),3,ISNUMBER(FIND("R22C",A6)),2)} -> 3 | C6: =VLOOKUP(D6,ColRef!$A$2:$B$258,2,FALSE) -> 2141.108 | D6: 59 | F6: 2172.7812 | G6: 2
A7: P_0624R13C | B7: {=_xlfn.IFS(ISNUMBER(FIND("R13C",A7)),3,ISNUMBER(FIND("R22C",A7)),2)} -> 3 | C7: =VLOOKUP(D7,ColRef!$A$2:$B$258,2,FALSE) -> 2384.4156 | D7: 24 | F7: 54 | G7: 2
A8: P_0624R13C | B8: {=_xlfn.IFS(ISNUMBER(FIND("R13C",A8)),3,ISNUMBER(FIND("R22C",A8)),2)} -> 3 | C8: =VLOOKUP(D8,ColRef!$A$2:$B$258,2,FALSE) -> 2034.3492 | D8: 77 | F8: 2160.0002 | G8: 2
A9: P_0624R13C | B9: {=_xlfn.IFS(ISNUMBER(FIND("R13C",A9)),3,ISNUMBER(FIND("R22C",A9)),2)} -> 3 | C9: =VLOOKUP(D9,ColRef!$A$2:$B$258,2,FALSE) -> 2369.0323 | D9: 26 | F9: 56 | G9: 2
A10: P_0624R13C | B10: {=_xlfn.IFS(ISNUMBER(FIND("R13C",A10)),3,ISNUMBER(FIND("R22C",A10)),2)} -> 3 | C10: =VLOOKUP(D10,ColRef!$A$2:$B$258,2,FALSE) -> 2361.4149 | D10: 27 | F10: 2369.0323 | G10: 2
A11: P_0624R13C | B11: {=_xlfn.IFS(ISNUMBER(FIND("R13C",A11)),3,ISNUMBER(FIND("R22C",A11)),2)} -> 3 | C11: =VLOOKUP(D11,ColRef!$A$2:$B$258,2,FALSE) -> 2166.3718 | D11: 55 | F11: 26 | G11: 2
A12: P_0624R13C | B12: {=_xlfn.IFS(ISNUMBER(FIND("R13C",A12)),3,ISNUMBER(FIND("R22C",A12)),2)} -> 3 | C12: =VLOOKUP(D12,ColRef!$A$2:$B$258,2,FALSE) -> 2045.6826 | D12: 75 | F12: 2400.0001 | G12: 2
A13: N_0824R13C | B13: {=_xlfn.IFS(ISNUMBER(FIND("R13C",A13)),3,ISNUMBER(FIND("R22C",A13)),2)} -> 3 | C13: =VLOOKUP(D13,ColRef!$A$2:$B$258,2,FALSE) -> 2361.4149 | D13: 27 | F13: 22 | G13: 2
... A39: P_0824R22C | B39: {=_xlfn.IFS(ISNUMBER(FIND("R13C",A39)),3,ISNUMBER(FIND("R22C",A39)),2)} -> 2 | C39: =VLOOKUP(D39,ColRef!$A$2:$B$258,2,FALSE) -> 2172.7812 | D39: 54 | F39: 158 | G39: 1
F40: 1462.9485 | G40: 1
F41: 218 | G41: 1
F42: 2045.6826 | G42: 1
F43: 75 | G43: 1
F44: 1696.0742 | G44: 1
F45: 149 | G45: 1
F46: 1672.8932 | G46: 1
F47: 155 | G47: 1
F48: 1963.6366 | G48: 1
F49: 90 | G49: 1
F50: 1669.0912 | G50: 1
F51: 156 | G51: 1
... F57: 57 | G57: 1
F58: Grand Total | G58: 38

Sheet PLSDA
A1: P_0824R22C - 2 component
A2: value.var freq
A3: X1669.091199 0.2669012591 0.804
A4: X1672.893228 0.2586524055 0.580
A5: X1665.306413 0.2356501368 0.792
A6: X1676.712617 0.2013589995 0.092
A7: X1434.375318 -0.1782285699 0.420
A8: X1765.384887 -0.1757326116 0.016
A9: X1431.579266 -0.1753715782 0.304
A10: X1661.538753 0.1744151528 0.480
A11: X1769.638825 -0.1721878455 0.052
A12: X1761.151352 -0.1647574558 NA
... A102: X2280.745452 0.0005095259 0.064

Sheet Bulk Wavelengths
A1: Run | B1: Wavelength (nm) | C1: Source
A2: N_0624R13C | B2: 2324.0507 | C2: VarImp
A3: N_0624R13C | B3: 1665.3064 | C3: VarImp
A4: N_0624R13C | B4: 1360.0003 | C4: VarImp
A5: N_0624R13C | B5: 1508.0085 | C5: VarImp
A6: N_0624R13C | B6: 1661.5388 | C6: VarImp
A7: N_0624R13C | B7: 2266.6668 | C7: VarImp
A8: N_0624R13C | B8: 1610.5266 | C8: VarImp
A9: N_0624R13C | B9: 2302.1945 | C9: VarImp
A10: N_0624R13C | B10: 2456.1873 | C10: VarImp
A11: N_0624R13C | B11: 2068.7326 | C11: VarImp
A12: N_0624R13C | B12: 2309.4341 | C12: VarImp
A13: N_0624R13C | B13: 1892.7837 | C13: VarImp
... A321: P_0824R22C | B321: 2172.7812 | C321: Prediction

Sheet WLReference
A2: 2550 | B2: 4 | C2: =VLOOKUP(B2,A2:B258,1,FALSE) -> #N/A
A3: 2541.1765 | B3: 5
A4: 2532.4138 | B4: 6
A5: 2523.7113 | B5: 7 | J5: 155 | K5: =VLOOKUP(J5,A2:B258,1,FALSE) -> #N/A
A6: 2515.0685 | B6: 8 | J6: 156
A7: 2506.4846 | B7: 9 | J7: 202
A8: 2497.9592 | B8: 10 | J8: 7
A9: 2489.4915 | B9: 11
A10: 2481.0811 | B10: 12
A11: 2472.7273 | B11: 13
A12: 2464.4296 | B12: 14
A13: 2456.1873 | B13: 15
A14: 2448 | B14: 16
A15: 2439.8671 | B15: 17
A16: 2431.7881 | B16: 18
A17: 2423.7624 | B17: 19
A18: 2415.7895 | B18: 20
A19: 2407.8689 | B19: 21
A20: 2400.0001 | B20: 22
... A258: 1350.0003 | B258: 260

Sheet ColRef
A2: 4 | B2: 2550
A3: 5 | B3: 2541.1765
A4: 6 | B4: 2532.4138
A5: 7 | B5: 2523.7113
A6: 8 | B6: 2515.0685
A7: 9 | B7: 2506.4846
A8: 10 | B8: 2497.9592
A9: 11 | B9: 2489.4915
A10: 12 | B10: 2481.0811
A11: 13 | B11: 2472.7273
A12: 14 | B12: 2464.4296
A13: 15 | B13: 2456.1873
... A258: 260 | B258: 1350.0003
