Workbook

Sheet Tables for Thesis
A1: Model | B1: Resistant % | C1: Medium % | D1: Not Resistant % | F1: Model | G1: Calibration % | H1: Cross-Validated % | I1: Evaluation %
A2: Three Class | B2: ='3C'!N6/SUM('3C'!L6:N6)*100 -> 44.444444 | C2: ='3C'!M5/SUM('3C'!L5:N5)*100 -> 5.5555556 | D2: ='3C'!L4/SUM('3C'!L4:N4)*100 -> 61.111111 | F2: Three Class | G2: 78.81 | H2: 70.46 | I2: ='3C'!L7 -> 37.037037
A3: Two Class | B3: ='2C'!N6/SUM('2C'!L6,'2C'!N6) * 100 -> 61.111111 | C3: n/a | D3: =100*'2C'!L4/SUM('2C'!L4,'2C'!N4) -> 61.111111 | F3: Two Class | G3: 86.13 | H3: 83.66 | I3: ='2C'!L7 -> 61.111111
A4: Hierarchical Model | B4: =HM!N6/SUM(HM!L6:M6) -> 0 | C4: =HM!M5/SUM(HM!L5:N5)*100 -> 61.111111 | D4: =HM!L4/SUM(HM!L4:N4)*100 -> 33.333333 | F4: Hierarchical Model | G4: - | H4: - | I4: =HM!L7 -> 31.481481
A5: A | B5: =A!M14/SUM(A!L14:M14) * 100 -> 66.666667 | C5: =A!M13/18 * 100 -> 61.111111 | D5: =A!L12/18 * 100 -> 38.888889 | F5: A | G5: 83.56 | H5: 82.55 | I5: =A!L6 -> 55.555556
A6: B | B6: =B!L4/18*100 -> 100 | C6: =B!M5/18 * 100 -> 0 | D6: n/a | F6: B | G6: 68.34 | H6: 65.32 | I6: =B!L6 -> 50
A7: C | B7: n/a | C7: ='C'!L4/18 *100 -> 55.555556 | D7: ='C'!M5/18 * 100 -> 38.888889 | F7: C | G7: 89.23 | H7: 81.03 | I7: ='C'!L6 -> 47.222222
A9: Model | B9: Original % | C9: Naive %
A10: Three Class | B10: ='3C'!B7 -> 33.333333 | C10: ='3C'!G7 -> 40.740741
A11: Two Class | B11: ='2C'!B7 -> 55.555556 | C11: ='2C'!G7 -> 66.666667
A12: Hierarchical Model | B12: =HM!B7 -> 37.037037 | C12: =HM!G7 -> 25.925926
A13: A | B13: =A!B6 -> 62.962963 | C13: =A!G6 -> 48.148148
A14: B | B14: =B!B6 -> 50 | C14: =B!G6 -> 50
A15: C | B15: ='C'!B6 -> 55.555556 | C15: ='C'!G6 -> 38.888889
B18: By Resistance Level | E18: By Dataset | H18: By Evaluation Subset
A19: Model | B19: High Resistance % | C19: Medium % | D19: No Resistance % | E19: Calibration % | F19: Cross-Validation % | G19: Evaluation % | H19: Original % | I19: Naive %
A20: Three Class | B20: 44.444444 | C20: 5.5555556 | D20: 61.111111 | E20: 78.81 | F20: 70.46 | G20: 37.037037 | H20: 33.333333 | I20: 40.740741
A21: Two Class | B21: 61.111111 | C21: - | D21: 61.111111 | E21: 86.13 | F21: 83.66 | G21: 61.111111 | H21: 55.555556 | I21: 66.666667
A22: Hierarchical Model | B22: 0 | C22: 61.111111 | D22: 33.333333 | E22: - | F22: - | G22: 31.481481 | H22: 37.037037 | I22: 25.925926
A23: A | B23: 66.666667 | C23: 61.111111 | D23: 38.888889 | E23: 83.56 | F23: 82.55 | G23: 55.555556 | H23: 62.962963 | I23: 48.148148
A24: B | B24: 100 | C24: 0 | D24: - | E24: 68.34 | F24: 65.32 | G24: 50 | H24: 50 | I24: 50
A25: C | B25: - | C25: 55.555556 | D25: 38.888889 | E25: 89.23 | F25: 81.03 | G25: 47.222222 | H25: 55.555556 | I25: 38.888889

Sheet Data Collected
A1: Sample | B1: True Class | C1: B/MID | D1: 3C | E1: 2C | F1: A | G1: C | H1: B | I1: BWA? | K1: Training Genotypes | O1: Sample | P1: True Class | Q1: HM
A2: 121-10-29 | B2: NR | C2: B | D2: NR | E2: NR | F2: NR | G2: NR | H2: M | I2: N | K2: 97 | L2: R | O2: 121-10-29 | P2: NR | Q2: NR
A3: 121-13-12 | B3: NR | D3: NR | E3: NR | F3: NR | G3: NR | H3: M | I3: N | K3: 121 | L3: NR | O3: 121-13-12 | P3: NR | Q3: NR
A4: 121-13-39 | B4: NR | C4: B | D4: R | E4: R | F4: MR | G4: M | H4: M | I4: N | K4: 51 | L4: M | O4: 121-13-39 | P4: NR | Q4: M
A5: 121-20-31 | B5: NR | C5: B | D5: R | E5: R | F5: MR | G5: M | H5: M | I5: N | O5: 121-20-31 | P5: NR | Q5: M
A6: 121-21-8 | K6: Testing Genotypes | O6: 121-21-8 | Q6: N
A7: 121-4-22 | B7: NR | D7: NR | E7: NR | F7: NR | G7: NR | H7: M | I7: N | K7: 32 | L7: R | O7: 121-4-22 | P7: NR | Q7: NR
A8: 121-4-34 | B8: NR | D8: R | E8: R | F8: MR | G8: M | H8: M | I8: N | K8: 24 | L8: NR | O8: 121-4-34 | P8: NR | Q8: M
A9: 121-11-44 | B9: NR | C9: B | D9: NR | E9: NR | F9: MR | G9: M | H9: M | I9: N | K9: 131 | L9: M | O9: 121-11-44 | P9: NR | Q9: M
A10: 121-10-19 | B10: NR | C10: B | D10: R | E10: R | F10: MR | G10: M | H10: M | I10: N | O10: 121-10-19 | P10: NR | Q10: M
A11: 121-8-34 | B11: NR | D11: R | E11: R | F11: MR | G11: NR | H11: M | I11: N | K11: Colored Cells indicate hierarchical model (HM) results | O11: 121-8-34 | P11: NR | Q11: M
A12: 131-11-19 | B12: M | C12: B | D12: R | E12: R | F12: MR | G12: M | H12: M | I12: N | O12: 131-11-19 | P12: M | Q12: M
A13: 131-10-35 | B13: M | C13: B | D13: NR | E13: NR | F13: NR | G13: NR | H13: M | I13: N | O13: 131-10-35 | P13: M | Q13: NR
A14: 131-14-39 | B14: M | C14: B | D14: NR | E14: NR | F14: NR | G14: NR | H14: M | I14: N | O14: 131-14-39 | P14: M | Q14: NR
A15: 131-18-32 | B15: M | C15: MID | D15: NR | E15: NR | F15: NR | G15: NR | H15: M | I15: N | O15: 131-18-32 | P15: M | Q15: NR
A16: 131-20-24 | B16: M | C16: B | D16: NR | E16: NR | F16: NR | G16: NR | H16: M | I16: N | O16: 131-20-24 | P16: M | Q16: NR
A17: 131-20-47 | B17: M | I17: N | O17: 131-20-47 | P17: M
A18: 131-2-3 | B18: M | D18: R | E18: R | F18: MR | G18: M | H18: M | I18: N | O18: 131-2-3 | P18: M | Q18: M
A19: 131-24-31 | B19: M | C19: MID | D19: R | E19: R | F19: MR | G19: M | H19: M | I19: N | O19: 131-24-31 | P19: M | Q19: M
A20: 131-3-24 | B20: M | D20: NR | E20: NR | F20: NR | G20: NR | H20: M | I20: N | O20: 131-3-24 | P20: M | Q20: NR
A21: 131-6-27 | B21: M | D21: R | E21: R | F21: MR | G21: M | H21: M | I21: N | O21: 131-6-27 | P21: M | Q21: M
A22: 24-13-18 | B22: NR | C22: B | D22: NR | E22: NR | F22: MR | G22: M | H22: M | I22: N | O22: 24-13-18 | P22: NR | Q22: M
A23: 24-14-26 | B23: NR | I23: N | O23: 24-14-26 | P23: NR | Q23: N
A24: 24-16-54 | B24: NR | C24: B | D24: NR | E24: NR | F24: NR | G24: NR | H24: M | I24: N | O24: 24-16-54 | P24: NR | Q24: NR
A25: 24-19-34 | B25: NR | C25: B | D25: NR | E25: NR | F25: NR | G25: M | H25: M | I25: N | O25: 24-19-34 | P25: NR | Q25: M
A26: 24-13-14 | B26: NR | C26: B | D26: M | E26: R | F26: MR | G26: M | H26: M | I26: N | O26: 24-13-14 | P26: NR | Q26: M
A27: 24-9-34 | B27: NR | C27: MID | D27: NR | E27: NR | F27: MR | G27: M | H27: M | I27: N | O27: 24-9-34 | P27: NR | Q27: M
A28: 24-10-38 | B28: NR | C28: B | D28: NR | E28: NR | F28: NR | G28: NR | H28: M | I28: N | O28: 24-10-38 | P28: NR | Q28: NR
A29: 24-6-46 | B29: NR | D29: NR | E29: NR | F29: MR | G29: M | H29: M | I29: N | O29: 24-6-46 | P29: NR | Q29: M
A30: 24-8-31 | B30: NR | C30: B | D30: NR | E30: NR | F30: NR | G30: NR | H30: M | I30: N | O30: 24-8-31 | P30: NR | Q30: NR
A31: 24-9-21 | B31: NR | C31: MID | D31: R | E31: R | F31: MR | G31: M | H31: M | I31: N | O31: 24-9-21 | P31: NR | Q31: M
A32: 32-12-30 | B32: R | C32: B | D32: R | E32: R | F32: MR | G32: M | H32: M | I32: N | O32: 32-12-30 | P32: R | Q32: M
A33: 32-13-36 | B33: R | I33: N | O33: 32-13-36 | P33: R
A34: 32-13-41 | B34: R | C34: B | D34: R | E34: R | F34: MR | G34: M | H34: M | I34: N | O34: 32-13-41 | P34: R | Q34: M
A35: 32-19-32 | B35: R | C35: B | D35: NR | E35: NR | F35: NR | G35: NR | H35: M | I35: N | O35: 32-19-32 | P35: R | Q35: NR
A36: 32-9-17 | B36: R | C36: MID | D36: R | E36: R | F36: MR | G36: NR | H36: M | I36: N | O36: 32-9-17 | P36: R | Q36: M
A37: 32-10-20 | B37: R | C37: B | D37: R | E37: R | F37: MR | G37: M | H37: M | I37: N | O37: 32-10-20 | P37: R | Q37: M
A38: 32-9-38 | B38: R | C38: MID | D38: NR | E38: NR | F38: NR | G38: NR | H38: M | I38: N | O38: 32-9-38 | P38: R | Q38: NR
A39: 32-4-40 | B39: R | D39: NR | E39: NR | F39: NR | G39: NR | H39: M | I39: N | O39: 32-4-40 | P39: R | Q39: NR
A40: 32-5-46 | B40: R | D40: NR | E40: R | F40: MR | G40: M | H40: M | I40: N | O40: 32-5-46 | P40: R | Q40: M
...

Sheet 3C
A1: Calibration | F1: Validation | K1: Total
B2: Predicted | G2: Predicted | L2: Predicted
A3: Correct | B3: NR | C3: M | D3: R | F3: Correct | G3: NR | H3: M | I3: R | K3: Correct | L3: NR | M3: M | N3: R
A4: NR | B4: =COUNTIF('Data Collected'!$D2:$D11,"NR") -> 4 | C4: =COUNTIF('Data Collected'!$D2:$D11,"M") -> 0 | D4: =COUNTIF('Data Collected'!$D2:$D11,"R") -> 5 | F4: NR | G4: =COUNTIF('Data Collected'!$D22:$D31,"NR") -> 7 | H4: =COUNTIF('Data Collected'!$D22:$D31,"M") -> 1 | I4: =COUNTIF('Data Collected'!$D22:$D31,"R") -> 1 | K4: NR | L4: =SUM(G4,B4) -> 11 | M4: =SUM(H4,C4) -> 1 | N4: =SUM(I4,D4) -> 6
A5: M | B5: =COUNTIF('Data Collected'!$D42:$D51, "NR") -> 3 | C5: =COUNTIF('Data Collected'!$D42:$D51, "M") -> 1 | D5: =COUNTIF('Data Collected'!$D42:$D51, "R") -> 5 | F5: M | G5: =COUNTIF('Data Collected'!$D12:$D21,"NR") -> 5 | H5: =COUNTIF('Data Collected'!$D12:$D21,"M") -> 0 | I5: =COUNTIF('Data Collected'!$D12:$D21,"R") -> 4 | K5: M | L5: =SUM(G5,B5) -> 8 | M5: =SUM(H5,C5) -> 1 | N5: =SUM(I5,D5) -> 9
A6: R | B6: =COUNTIF('Data Collected'!$D52:$D61, "NR") -> 4 | C6: =COUNTIF('Data Collected'!$D52:$D61, "M") -> 1 | D6: =COUNTIF('Data Collected'!$D52:$D61, "R") -> 4 | F6: R | G6: =COUNTIF('Data Collected'!$D32:$D41,"NR") -> 5 | H6: =COUNTIF('Data Collected'!$D32:$D41,"M") -> 0 | I6: =COUNTIF('Data Collected'!$D32:$D41,"R") -> 4 | K6: R | L6: =SUM(G6,B6) -> 9 | M6: =SUM(H6,C6) -> 1 | N6: =SUM(I6,D6) -> 8
A7: Accuracy | B7: =SUM(B4,C5,D6)/27*100 -> 33.333333 | F7: Accuracy | G7: =SUM(G4,H5,I6)/SUM(G4:I6) * 100 -> 40.740741 | K7: Accuracy | L7: =SUM(L4,M5,N6)/SUM(L4:N6) * 100 -> 37.037037
B9: Calibration
B10: Medium | C10: Not Resistant | D10: Resistant
A11: Medium | B11: 75 | C11: 12 | D11: 6 | F11: =SUM(B11,C12,D13)/SUM(B11:D13) -> 0.78819444
A12: Not Resistant | B12: 6 | C12: 78 | D12: 13
A13: Resistant | B13: 15 | C13: 9 | D13: 74
B14: Cross Val
B15: Medium | C15: Not Resistant | D15: Resistant
A16: Medium | B16: 68 | C16: 14 | D16: 18 | F16: =SUM(B16,C17,D18)/SUM(B16:D18) -> 0.70469799
A17: Not Resistant | B17: 11 | C17: 74 | D17: 17
A18: Resistant | B18: 17 | C18: 11 | D18: 68

Sheet 2C
A1: Calibration | F1: Validation | K1: Total
B2: Predicted | G2: Predicted | L2: Predicted
A3: Correct | B3: NR | C3: M | D3: R | F3: Correct | G3: NR | H3: M | I3: R | K3: Correct | L3: NR | M3: M | N3: R
A4: NR | B4: =COUNTIF('Data Collected'!$E2:$E11,"NR") -> 4 | C4: =COUNTIF('Data Collected'!$E2:$E11,"M") -> 0 | D4: =COUNTIF('Data Collected'!$E2:$E11,"R") -> 5 | F4: NR | G4: =COUNTIF('Data Collected'!$E22:$E31,"NR") -> 7 | H4: =COUNTIF('Data Collected'!$E22:$E31,"M") -> 0 | I4: =COUNTIF('Data Collected'!$E22:$E31,"R") -> 2 | K4: NR | L4: =SUM(B4,G4) -> 11 | M4: =SUM(C4,H4) -> 0 | N4: =SUM(D4,I4) -> 7
A5: M | B5: =COUNTIF('Data Collected'!$E42:$E51, "NR") -> 4 | C5: =COUNTIF('Data Collected'!$E42:$E51, "M") -> 0 | D5: =COUNTIF('Data Collected'!$E42:$E51, "R") -> 5 | F5: M | G5: =COUNTIF('Data Collected'!$E12:$E21,"NR") -> 5 | H5: =COUNTIF('Data Collected'!$E12:$E21,"M") -> 0 | I5: =COUNTIF('Data Collected'!$E12:$E21,"R") -> 4 | K5: M | L5: =SUM(B5,G5) -> 9 | M5: =SUM(C5,H5) -> 0 | N5: =SUM(D5,I5) -> 9
A6: R | B6: =COUNTIF('Data Collected'!$E52:$E61, "NR") -> 3 | C6: =COUNTIF('Data Collected'!$E52:$E61, "M") -> 0 | D6: =COUNTIF('Data Collected'!$E52:$E61, "R") -> 6 | F6: R | G6: =COUNTIF('Data Collected'!$E32:$E41,"NR") -> 4 | H6: =COUNTIF('Data Collected'!$E32:$E41,"M") -> 0 | I6: =COUNTIF('Data Collected'!$E32:$E41,"R") -> 5 | K6: R | L6: =SUM(B6,G6) -> 7 | M6: =SUM(C6,H6) -> 0 | N6: =SUM(D6,I6) -> 11
A7: Accuracy | B7: =SUM(B4,D6)/SUM(B4, B6, D4, D6)*100 -> 55.555556 | F7: Accuracy | G7: =SUM(G4,I6)/SUM(G4,G6,I4,I6) * 100 -> 66.666667 | K7: Accuracy | L7: =SUM(L4,N6)/SUM(L4,L6,N4,N6) * 100 -> 61.111111
B10: NR | C10: R
A11: NR | B11: 87 | C11: 16 | E11: =SUM(B11,C12)/SUM(B11:C12) -> 0.86138614
A12: R | B12: 12 | C12: 87
B14: NR | C14: R
A15: NR | B15: 86 | C15: 20 | E15: =SUM(B15,C16)/SUM(B15:C16) -> 0.83663366
A16: R | B16: 13 | C16: 83

Sheet A
A1: Calibration | F1: Validation | K1: Total
B2: Predicted | G2: Predicted | L2: Predicted
A3: Correct | B3: NR | C3: MR | F3: Correct | G3: NR | H3: M | K3: Correct | L3: NR | M3: M
A4: NR | B4: =COUNTIF('Data Collected'!$F2:$F11,"NR") -> 3 | C4: =COUNTIF('Data Collected'!$F2:$F11,"MR") -> 6 | F4: NR | G4: =COUNTIF('Data Collected'!$F22:$F31,"NR") -> 4 | H4: =COUNTIF('Data Collected'!$F22:$F31,"MR") -> 5 | K4: NR | L4: =SUM(B4,G4) -> 7 | M4: =SUM(C4,H4) -> 11
A5: MR | B5: =SUM(COUNTIF('Data Collected'!$F42:$F51,"NR"),COUNTIF('Data Collected'!$F52:$F61,"NR")) -> 4 | C5: =SUM(COUNTIF('Data Collected'!$F42:$F51,"MR"),COUNTIF('Data Collected'!$F52:$F61,"MR")) -> 14 | F5: MR | G5: =SUM(COUNTIF('Data Collected'!$F12:$F21,"NR"),COUNTIF('Data Collected'!$F32:$F41,"NR")) -> 9 | H5: =SUM(COUNTIF('Data Collected'!$F12:$F21,"MR"),COUNTIF('Data Collected'!$F32:$F41,"MR")) -> 9 | K5: M | L5: =SUM(B5,G5) -> 13 | M5: =SUM(C5,H5) -> 23
A6: Accuracy | B6: =SUM(B4,C5)/SUM(B4:C5)*100 -> 62.962963 | F6: Accuracy | G6: =SUM(G4,H5)/SUM(G4:H5) * 100 -> 48.148148 | K6: Accuracy | L6: =SUM(L4,M5)/SUM(L4:M5) * 100 -> 55.555556
A9: Calibration | F9: Validation | K9: Total
B10: Predicted | G10: Predicted | L10: Predicted
A11: Correct | B11: NR | C11: MR | F11: Correct | G11: NR | H11: MR | K11: Correct | L11: NR | M11: MR
A12: NR | B12: 3 | C12: 6 | F12: NR | G12: 4 | H12: 5 | K12: NR | L12: 7 | M12: 11
A13: M | B13: =COUNTIF('Data Collected'!$F42:$F51, "NR") -> 2 | C13: =COUNTIF('Data Collected'!$F42:$F51, "MR") -> 7 | F13: M | G13: =COUNTIF('Data Collected'!$F12:$F21, "NR") -> 5 | H13: =COUNTIF('Data Collected'!$F12:$F21, "MR") -> 4 | K13: M | L13: =SUM(B13,G13) -> 7 | M13: =SUM(C13,H13) -> 11
A14: R | B14: =COUNTIF('Data Collected'!$F52:$F61, "NR") -> 2 | C14: =COUNTIF('Data Collected'!$F52:$F61, "MR") -> 7 | F14: R | G14: =COUNTIF('Data Collected'!$F32:$F41, "NR") -> 4 | H14: =COUNTIF('Data Collected'!$F32:$F41, "MR") -> 5 | K14: R | L14: =SUM(B14,G14) -> 6 | M14: =SUM(C14,H14) -> 12
A15: Accuracy | B15: =SUM(B12,C13,C14)/SUM(B12:C14) * 100 -> 62.962963 | F15: Accuracy | G15: =SUM(G12,H13,H14)/SUM(G12:H14) * 100 -> 48.148148 | K15: Accuracy | L15: =SUM(L12,M13,M14)/SUM(L12:M14) * 100 -> 55.555556
B18: MR | C18: NR
A19: MR | B19: 170 | C19: 20 | E19: =SUM(B19,C20)/SUM(B19:C20) -> 0.83557047
A20: NR | B20: 29 | C20: 79
B21: MR | C21: NR
A22: MR | B22: 166 | C22: 19 | E22: =SUM(B22,C23)/SUM(B22:C23) -> 0.82550336
A23: NR | B23: 33 | C23: 80

Sheet B
A1: Calibration | F1: Validation | K1: Total
B2: Predicted | G2: Predicted | L2: Predicted
A3: Correct | B3: M | C3: R | F3: Correct | G3: M | H3: R | K3: Correct | L3: M | M3: R
A4: M | B4: =COUNTIF('Data Collected'!$H42:$H51,"M") -> 9 | C4: =COUNTIF('Data Collected'!$H42:$H51,"R") -> 0 | F4: M | G4: =COUNTIF('Data Collected'!$H12:$H21,"M") -> 9 | H4: =COUNTIF('Data Collected'!$H12:$H21,"R") -> 0 | K4: M | L4: =SUM(B4,G4) -> 18 | M4: =SUM(C4,H4) -> 0
A5: R | B5: =COUNTIF('Data Collected'!$H52:$H61,"M") -> 9 | C5: =COUNTIF('Data Collected'!$H52:$H61,"R") -> 0 | F5: R | G5: =COUNTIF('Data Collected'!$H32:$H41,"M") -> 9 | H5: =COUNTIF('Data Collected'!$H32:$H41,"R") -> 0 | K5: R | L5: =SUM(B5,G5) -> 18 | M5: =SUM(C5,H5) -> 0
A6: Accuracy | B6: =SUM(B4,C5)/SUM(B4:C5)*100 -> 50 | F6: Accuracy | G6: =SUM(G4,H5)/SUM(G4:H5) * 100 -> 50 | K6: Accuracy | L6: =SUM(L4,M5)/SUM(L4:M5) * 100 -> 50
B9: M | C9: R
A10: M | B10: 61 | C10: 28 | E10: =SUM(B10,C11)/SUM(B10:C11) -> 0.68341709
A11: R | B11: 35 | C11: 75
B13: M | C13: R
A14: M | B14: 60 | C14: 33 | E14: =SUM(B14,C15)/SUM(B14:C15) -> 0.65326633
A15: R | B15: 36 | C15: 70

Sheet C
A1: Calibration | F1: Validation | K1: Total
B2: Predicted | G2: Predicted | L2: Predicted
A3: Correct | B3: M | C3: NR | F3: Correct | G3: M | H3: NR | K3: Correct | L3: M | M3: NR
A4: M | B4: =COUNTIF('Data Collected'!$G42:$G51,"M") -> 6 | C4: =COUNTIF('Data Collected'!$G42:$G51,"NR") -> 3 | F4: M | G4: =COUNTIF('Data Collected'!$G12:$G21,"M") -> 4 | H4: =COUNTIF('Data Collected'!$G12:$G21,"NR") -> 5 | K4: M | L4: =SUM(B4,G4) -> 10 | M4: =SUM(C4,H4) -> 8
A5: NR | B5: =COUNTIF('Data Collected'!$G2:$G11,"M") -> 5 | C5: =COUNTIF('Data Collected'!$G2:$G11,"NR") -> 4 | F5: NR | G5: =COUNTIF('Data Collected'!$G22:$G31,"M") -> 6 | H5: =COUNTIF('Data Collected'!$G22:$G31,"NR") -> 3 | K5: NR | L5: =SUM(B5,G5) -> 11 | M5: =SUM(C5,H5) -> 7
A6: Accuracy | B6: =SUM(B4,C5)/SUM(B4:C5)*100 -> 55.555556 | F6: Accuracy | G6: =SUM(G4,H5)/SUM(G4:H5) * 100 -> 38.888889 | K6: Accuracy | L6: =SUM(L4,M5)/SUM(L4:M5) * 100 -> 47.222222
B9: M | C9: NR
A10: M | B10: 89 | C10: 14 | E10: =SUM(B10,C11)/SUM(B10:C11) -> 0.89230769
A11: NR | B11: 7 | C11: 85
B13: M | C13: NR
A14: M | B14: 80 | C14: 21 | E14: =SUM(B14,C15)/SUM(B14:C15) -> 0.81025641
A15: NR | B15: 16 | C15: 78

Sheet HM
A1: Calibration | F1: Validation | K1: Total
B2: Predicted | G2: Predicted | L2: Predicted
A3: Correct | B3: NR | C3: M | D3: R | F3: Correct | G3: NR | H3: M | I3: R | K3: Correct | L3: NR | M3: M | N3: R
A4: NR | B4: =COUNTIF('Data Collected'!$Q2:$Q11,"NR") -> 3 | C4: =COUNTIF('Data Collected'!$Q2:$Q11,"M") -> 6 | D4: =COUNTIF('Data Collected'!$Q2:$Q11,"R") -> 0 | F4: NR | G4: =COUNTIF('Data Collected'!$Q22:$Q31,"NR") -> 3 | H4: =COUNTIF('Data Collected'!$Q22:$Q31,"M") -> 6 | I4: =COUNTIF('Data Collected'!$Q22:$Q31,"R") -> 0 | K4: NR | L4: =SUM(G4,B4) -> 6 | M4: =SUM(H4,C4) -> 12 | N4: =SUM(I4,D4) -> 0
A5: M | B5: =COUNTIF('Data Collected'!$Q42:$Q51, "NR") -> 2 | C5: =COUNTIF('Data Collected'!$Q42:$Q51, "M") -> 7 | D5: =COUNTIF('Data Collected'!$Q42:$Q51, "R") -> 0 | F5: M | G5: =COUNTIF('Data Collected'!$Q12:$Q21,"NR") -> 5 | H5: =COUNTIF('Data Collected'!$Q12:$Q21,"M") -> 4 | I5: =COUNTIF('Data Collected'!$Q12:$Q21,"R") -> 0 | K5: M | L5: =SUM(G5,B5) -> 7 | M5: =SUM(H5,C5) -> 11 | N5: =SUM(I5,D5) -> 0
A6: R | B6: =COUNTIF('Data Collected'!$Q52:$Q61, "NR") -> 2 | C6: =COUNTIF('Data Collected'!$Q52:$Q61, "M") -> 7 | D6: =COUNTIF('Data Collected'!$Q52:$Q61, "R") -> 0 | F6: R | G6: =COUNTIF('Data Collected'!$Q32:$Q41,"NR") -> 4 | H6: =COUNTIF('Data Collected'!$Q32:$Q41,"M") -> 5 | I6: =COUNTIF('Data Collected'!$Q32:$Q41,"R") -> 0 | K6: R | L6: =SUM(G6,B6) -> 6 | M6: =SUM(H6,C6) -> 12 | N6: =SUM(I6,D6) -> 0
A7: Accuracy | B7: =SUM(B4,C5,D6)/27*100 -> 37.037037 | F7: Accuracy | G7: =SUM(G4,H5,I6)/SUM(G4:I6) * 100 -> 25.925926 | K7: Accuracy | L7: =SUM(L4,M5,N6)/SUM(L4:N6) * 100 -> 31.481481
